Workbook

Sheet DADOS DE VENDA
B1: SEGUNDA | H1: TERÇA | N1: QUARTA | T1: QUINTA | Z1: SEXTA | AF1: SABADO | AL1: DOMINGO | AQ1: MEDIA DO PERIODO 03/11 A 10/11
A2: Produto | B2: Descrição | C2: Código de Barras | D2: Quantidade | E2: DATA | G2: Produto | H2: Descrição | I2: Código de Barras | J2: Quantidade | K2: DATA | M2: Produto | N2: Descrição | O2: Código de Barras | P2: Quantidade | Q2: DATA | S2: Produto | T2: Descrição | U2: Código de Barras | V2: Quantidade | W2: DATA | Y2: Produto | Z2: Descrição | AA2: Código de Barras | AB2: Quantidade | AC2: DATA | AE2: Produto | AF2: Descrição | AG2: Código de Barras | AH2: Quantidade | AI2: DATA | AK2: Produto | AL2: Descrição | AM2: Código de Barras | AN2: Quantidade | AO2: DATA | AQ2: Produto | AR2: Descrição | AS2: Código de Barras | AT2: Quantidade | AU2: Venda Líquida | AV2: MEDIA QTD | AW2: MEDIA VALOR | AZ2: =SUMIF(AR:AR,AY2,AT:AT) -> 0
A3: 8966 | B3: REFEICAO ISCA DE FRANGO A MILANESA BENDITO | C3: 8966 | D3: 12 | E3: 19/01 a20/01 | G3: 7930 | H3: REF COPA LOMBO ACEBOLADA BENDITO | I3: 7930 | J3: 10 | K3: 20/01 a 21/01 | M3: 9350 | N3: COMBO SUSHI KANI/HOTHOLL/CALIFORNIA BENDITO UN | O3: 9350 | P3: 1 | Q3: 21/01 a 22/01 | S3: 7574 | T3: PATE DE AZEITONA PRETA BENDITO KG | U3: 7574 | V3: 0.18 | W3: 15/01 a 016/01 | Y3: 2893 | Z3: ASS.FRANGO METADE BENDITO UNIDADE | AA3: 2893 | AB3: 10 | AC3: 16/01 a 17/01 | AE3: 93583 | AF3: ASS.FRANGO BENDITO INTEIRO | AG3: 93583 | AH3: 6 | AI3: 17/01 a 18/01 | AK3: 7041 | AL3: BOLO BANANA BENDITO KG | AM3: 7041 | AN3: 0.95 | AO3: 20/10 A 23/10 | AQ3: 7068 | AR3: BOLO CENOURA COBERTURA CHOCOLATE BENDITO KG | AS3: 7068 | AT3: 20.51 | AU3: 1023.49 | AV3: =(AT3/7) -> 2.93 | AW3: =(AU3/7) -> 146.21286
A4: 7768 | B4: REFEICAO LAGARTO M.MADEIRA + BATATA ASSADA BENDITO | C4: 7768 | D4: 10 | E4: =(E3) -> 19/01 a20/01 | G4: 7673 | H4: REFEICAO FILE FRANGO PARMEGIANA BENDITO UN | I4: 7673 | J4: 14 | K4: =(K3) -> 20/01 a 21/01 | M4: 7930 | N4: REF COPA LOMBO ACEBOLADA BENDITO | O4: 7930 | P4: 10 | Q4: =(Q3) -> 21/01 a 22/01 | S4: 7625 | T4: REFEICAO CARNE PANELA BENDITO UN | U4: 7625 | V4: 8 | W4: =(W3) -> 15/01 a 016/01 | Y4: 7574 | Z4: PATE DE AZEITONA PRETA BENDITO KG | AA4: 7574 | AB4: 0.18 | AC4: =(AC3) -> 16/01 a 17/01 | AE4: 2893 | AF4: ASS.FRANGO METADE BENDITO UNIDADE | AG4: 2893 | AH4: 27 | AI4: =(AI3) -> 17/01 a 18/01 | AK4: 7068 | AL4: BOLO CENOURA COBERTURA CHOCOLATE BENDITO KG | AM4: 7068 | AN4: 10.31 | AO4: =(AO3) -> 20/10 A 23/10 | AQ4: 7569 | AR4: PAO CASEIRAO BENDITO 250GR | AS4: 7569 | AT4: 69 | AU4: 959.1 | AV4: =(AT4/7) -> 9.8571429 | AW4: =(AU4/7) -> 137.01429
A5: 7875 | B5: REFEICAO STROGONOFF FRANGO BENDITO UN | C5: 7875 | D5: 7 | E5: =(E4) -> 19/01 a20/01 | G5: 7875 | H5: REFEICAO STROGONOFF FRANGO BENDITO UN | I5: 7875 | J5: 7 | K5: =(K4) -> 20/01 a 21/01 | M5: 7625 | N5: REFEICAO CARNE PANELA BENDITO UN | O5: 7625 | P5: 7 | Q5: =(Q4) -> 21/01 a 22/01 | S5: 9362 | T5: REFEICAO ISCA DE FRANGO A ACEBOLADA BENDITO UN | U5: 9362 | V5: 10 | W5: =(W4) -> 15/01 a 016/01 | Y5: 7660 | Z5: REFEICAO FEIJOADA BENDITO UN | AA5: 7660 | AB5: 12 | AC5: =(AC4) -> 16/01 a 17/01 | AE5: 7660 | AF5: REFEICAO FEIJOADA BENDITO UN | AG5: 7660 | AH5: 12 | AI5: =(AI4) -> 17/01 a 18/01 | AK5: 6856 | AL5: BOLO COCO BENDITO KG | AM5: 6856 | AN5: 0.55 | AO5: =(AO4) -> 20/10 A 23/10 | AQ5: 6856 | AR5: BOLO COCO BENDITO KG | AS5: 6856 | AT5: 17.21 | AU5: 674.56 | AV5: =(AT5/7) -> 2.4585714 | AW5: =(AU5/7) -> 96.365714
A6: 7877 | B6: REFEICAO TIRINHA CARNE CHINESA BENDITO UN | C6: 7877 | D6: 14 | E6: =(E5) -> 19/01 a20/01 | G6: 7877 | H6: REFEICAO TIRINHA CARNE CHINESA BENDITO UN | I6: 7877 | J6: 14 | K6: =(K5) -> 20/01 a 21/01 | M6: 7673 | N6: REFEICAO FILE FRANGO PARMEGIANA BENDITO UN | O6: 7673 | P6: 14 | Q6: =(Q5) -> 21/01 a 22/01 | S6: 7796 | T6: REFEICAO MEDALHAO FRANGO BENDITO UN | U6: 7796 | V6: 13 | W6: =(W5) -> 15/01 a 016/01 | Y6: 7673 | Z6: REFEICAO FILE FRANGO PARMEGIANA BENDITO UN | AA6: 7673 | AB6: 15 | AC6: =(AC5) -> 16/01 a 17/01 | AE6: 7673 | AF6: REFEICAO FILE FRANGO PARMEGIANA BENDITO UN | AG6: 7673 | AH6: 15 | AI6: =(AI5) -> 17/01 a 18/01 | AK6: 6856 | AL6: BOLO COCO BENDITO KG | AM6: 6856 | AN6: 5.04 | AO6: =(AO5) -> 20/10 A 23/10 | AQ6: 6966 | AR6: PAO HAMBURGUER BENDITO KG | AS6: 6966 | AT6: 14.64 | AU6: 476.25 | AV6: =(AT6/7) -> 2.0914286 | AW6: =(AU6/7) -> 68.035714
A7: 8945 | B7: ROT.ISCA DE FRANGO A MILANESA BENDITO KG | C7: 8945 | D7: 0.87 | E7: =(E6) -> 19/01 a20/01 | G7: 8028 | H7: ROTISSERIA ARROZ BRANCO BENDITO KG | I7: 8028 | J7: 1.28 | K7: =(K6) -> 20/01 a 21/01 | M7: 7796 | N7: REFEICAO MEDALHAO FRANGO BENDITO UN | O7: 7796 | P7: 12 | Q7: =(Q6) -> 21/01 a 22/01 | S7: 7874 | T7: REFEICAO STROGONOFF CARNE BENDITO UN | U7: 7874 | V7: 8 | W7: =(W6) -> 15/01 a 016/01 | Y7: 9362 | Z7: REFEICAO ISCA DE FRANGO A ACEBOLADA BENDITO UN | AA7: 9362 | AB7: 10 | AC7: =(AC6) -> 16/01 a 17/01 | AE7: 8321 | AF7: ROT.ESPAGUETE A BOLONHESA + POLPETONE RECHEADO BENDITO | AG7: 8321 | AH7: 7 | AI7: =(AI6) -> 17/01 a 18/01 | AK7: 7120 | AL7: BOLO FUBA C/MILHO BENDITO KG | AM7: 7120 | AN7: 0.43 | AO7: =(AO6) -> 20/10 A 23/10 | AQ7: 104254 | AR7: F.PROPRIA LANCHE SALAME COM QUEIJO PRATO KG | AS7: 104254 | AT7: 5.18 | AU7: 414.18 | AV7: =(AT7/7) -> 0.74 | AW7: =(AU7/7) -> 59.168571
A8: 8028 | B8: ROTISSERIA ARROZ BRANCO BENDITO KG | C8: 8028 | D8: 2.71 | E8: =(E7) -> 19/01 a20/01 | G8: 8048 | H8: ROTISSERIA ARROZ TEMPERADO BENDITO KG | I8: 8048 | J8: 0.79 | K8: =(K7) -> 20/01 a 21/01 | M8: 8321 | N8: ROT.ESPAGUETE A BOLONHESA + POLPETONE RECHEADO BENDITO | O8: 8321 | P8: 4 | Q8: =(Q7) -> 21/01 a 22/01 | S8: 8321 | T8: ROT.ESPAGUETE A BOLONHESA + POLPETONE RECHEADO BENDITO | U8: 8321 | V8: 7 | W8: =(W7) -> 15/01 a 016/01 | Y8: 7874 | Z8: REFEICAO STROGONOFF CARNE BENDITO UN | AA8: 7874 | AB8: 8 | AC8: =(AC7) -> 16/01 a 17/01 | AE8: 8023 | AF8: ROTISSERIA ARROZ A GREGA BENDITO KG | AG8: 8023 | AH8: 1.6 | AI8: =(AI7) -> 17/01 a 18/01 | AK8: 7267 | AL8: BOLO LEITE NINHO VALSA BENDITO KG | AM8: 7267 | AN8: 0.44 | AO8: =(AO7) -> 20/10 A 23/10 | AQ8: 6965 | AR8: PAO FOFINHO BENDITO KG | AS8: 6965 | AT8: 12.53 | AU8: 367.8 | AV8: =(AT8/7) -> 1.79 | AW8: =(AU8/7) -> 52.542857
A9: 8080 | B9: ROTISSERIA BANANA BENDITO KG | C9: 8080 | D9: 0.72 | E9: =(E8) -> 19/01 a20/01 | G9: 8080 | H9: ROTISSERIA BANANA BENDITO KG | I9: 8080 | J9: 0.48 | K9: =(K8) -> 20/01 a 21/01 | M9: 8028 | N9: ROTISSERIA ARROZ BRANCO BENDITO KG | O9: 8028 | P9: 1.52 | Q9: =(Q8) -> 21/01 a 22/01 | S9: 8028 | T9: ROTISSERIA ARROZ BRANCO BENDITO KG | U9: 8028 | V9: 1.56 | W9: =(W8) -> 15/01 a 016/01 | Y9: 8321 | Z9: ROT.ESPAGUETE A BOLONHESA + POLPETONE RECHEADO BENDITO | AA9: 8321 | AB9: 11 | AC9: =(AC8) -> 16/01 a 17/01 | AE9: 8028 | AF9: ROTISSERIA ARROZ BRANCO BENDITO KG | AG9: 8028 | AH9: 1.35 | AI9: =(AI8) -> 17/01 a 18/01 | AK9: 7141 | AL9: BOLO LIMAO C COBERTURA BENDITO KG | AM9: 7141 | AN9: 1.82 | AO9: =(AO8) -> 20/10 A 23/10 | AQ9: 7499 | AR9: SONHO CREME BENDITO KG | AS9: 7499 | AT9: 8.82 | AU9: 325.29 | AV9: =(AT9/7) -> 1.26 | AW9: =(AU9/7) -> 46.47
A10: 8089 | B10: ROTISSERIA BATATA ASSADA BENDITO KG | C10: 8089 | D10: 1.36 | E10: =(E9) -> 19/01 a20/01 | G10: 8089 | H10: ROTISSERIA BATATA ASSADA BENDITO KG | I10: 8089 | J10: 0.81 | K10: =(K9) -> 20/01 a 21/01 | M10: 8048 | N10: ROTISSERIA ARROZ TEMPERADO BENDITO KG | O10: 8048 | P10: 1.32 | Q10: =(Q9) -> 21/01 a 22/01 | S10: 8080 | T10: ROTISSERIA BANANA BENDITO KG | U10: 8080 | V10: 0.43 | W10: =(W9) -> 15/01 a 016/01 | Y10: 8028 | Z10: ROTISSERIA ARROZ BRANCO BENDITO KG | AA10: 8028 | AB10: 1.8 | AC10: =(AC9) -> 16/01 a 17/01 | AE10: 8037 | AF10: ROTISSERIA ARROZ CARRETEIRO BENDITO KG | AG10: 8037 | AH10: 1.74 | AI10: =(AI9) -> 17/01 a 18/01 | AK10: 7567 | AL10: BOLO MACA BENDITO KG | AM10: 7567 | AN10: 0.23 | AO10: =(AO9) -> 20/10 A 23/10 | AQ10: 6982 | AR10: ROSCA CASEIRA COCO BENDITO KG | AS10: 6982 | AT10: 6.79 | AU10: 298.23 | AV10: =(AT10/7) -> 0.97 | AW10: =(AU10/7) -> 42.604286
A11: 8093 | B11: ROTISSERIA BATATA DOCE ASSADA BENDITO KG | C11: 8093 | D11: 0.79 | E11: =(E10) -> 19/01 a20/01 | G11: 8093 | H11: ROTISSERIA BATATA DOCE ASSADA BENDITO KG | I11: 8093 | J11: 0.79 | K11: =(K10) -> 20/01 a 21/01 | M11: 8089 | N11: ROTISSERIA BATATA ASSADA BENDITO KG | O11: 8089 | P11: 0.55 | Q11: =(Q10) -> 21/01 a 22/01 | S11: 8153 | T11: ROTISSERIA BERINJELA PIZZAOLA BENDITO KG | U11: 8153 | V11: 0.65 | W11: =(W10) -> 15/01 a 016/01 | Y11: 8048 | Z11: ROTISSERIA ARROZ TEMPERADO BENDITO KG | AA11: 8048 | AB11: 1.53 | AC11: =(AC10) -> 16/01 a 17/01 | AE11: 8048 | AF11: ROTISSERIA ARROZ TEMPERADO BENDITO KG | AG11: 8048 | AH11: 1.53 | AI11: =(AI10) -> 17/01 a 18/01 | AK11: 7197 | AL11: BOLO NOZES BENDITO KG | AM11: 7197 | AN11: 0.41 | AO11: =(AO10) -> 20/10 A 23/10 | AQ11: 104256 | AR11: F.PROPRIA LANCHE PRESUNTO E QUEIJO KG | AS11: 104256 | AT11: 4.67 | AU11: 280 | AV11: =(AT11/7) -> 0.66714286 | AW11: =(AU11/7) -> 40
A12: 8166 | B12: ROTISSERIA BOLINHO DE ARROZ BENDITO KG | C12: 8166 | D12: 1.51 | E12: =(E11) -> 19/01 a20/01 | G12: 8166 | H12: ROTISSERIA BOLINHO DE ARROZ BENDITO KG | I12: 8166 | J12: 3.01 | K12: =(K11) -> 20/01 a 21/01 | M12: 8166 | N12: ROTISSERIA BOLINHO DE ARROZ BENDITO KG | O12: 8166 | P12: 1.49 | Q12: =(Q11) -> 21/01 a 22/01 | S12: 8172 | T12: ROTISSERIA CABOTIA REFOGADA BENDITO KG | U12: 8172 | V12: 0.44 | W12: =(W11) -> 15/01 a 016/01 | Y12: 8080 | Z12: ROTISSERIA BANANA BENDITO KG | AA12: 8080 | AB12: 0.16 | AC12: =(AC11) -> 16/01 a 17/01 | AE12: 8089 | AF12: ROTISSERIA BATATA ASSADA BENDITO KG | AG12: 8089 | AH12: 0.5 | AI12: =(AI11) -> 17/01 a 18/01 | AK12: 7200 | AL12: BOLO PISCINA CENOURA BENDITO KG | AM12: 7200 | AN12: 1.11 | AO12: =(AO11) -> 20/10 A 23/10 | AQ12: 6944 | AR12: PANETTONE FRUTA BENDITO KG | AS12: 6944 | AT12: 6.68 | AU12: 266.48 | AV12: =(AT12/7) -> 0.95428571 | AW12: =(AU12/7) -> 38.068571
A13: 8176 | B13: ROTISSERIA CALDO DE MANDIOCA BENDITO KG | C13: 8176 | D13: 0.7 | E13: =(E12) -> 19/01 a20/01 | G13: 8172 | H13: ROTISSERIA CABOTIA REFOGADA BENDITO KG | I13: 8172 | J13: 1.18 | K13: =(K12) -> 20/01 a 21/01 | M13: 8172 | N13: ROTISSERIA CABOTIA REFOGADA BENDITO KG | O13: 8172 | P13: 1.56 | Q13: =(Q12) -> 21/01 a 22/01 | S13: 8201 | T13: ROTISSERIA CANELONE FRANGO COM REQUEIJAO BENDITO KG | U13: 8201 | V13: 0.93 | W13: =(W12) -> 15/01 a 016/01 | Y13: 8089 | Z13: ROTISSERIA BATATA ASSADA BENDITO KG | AA13: 8089 | AB13: 0.5 | AC13: =(AC12) -> 16/01 a 17/01 | AE13: 8153 | AF13: ROTISSERIA BERINJELA PIZZAOLA BENDITO KG | AG13: 8153 | AH13: 1.04 | AI13: =(AI12) -> 17/01 a 18/01 | AK13: 7213 | AL13: BOLO RECH.BRIGADEIRO C/LEITE NINHO BENDITO KG | AM13: 7213 | AN13: 0.76 | AO13: =(AO12) -> 20/10 A 23/10 | AQ13: 6975 | AR13: PAO HOT DOG BENDITO KG | AS13: 6975 | AT13: 8.31 | AU13: 248.37 | AV13: =(AT13/7) -> 1.1871429 | AW13: =(AU13/7) -> 35.481429
A14: 8221 | B14: ROTISSERIA CAPONATA BERINJELA BENDITO KG | C14: 8221 | D14: 0.27 | E14: =(E13) -> 19/01 a20/01 | G14: 8176 | H14: ROTISSERIA CALDO DE MANDIOCA BENDITO KG | I14: 8176 | J14: 1.39 | K14: =(K13) -> 20/01 a 21/01 | M14: 8176 | N14: ROTISSERIA CALDO DE MANDIOCA BENDITO KG | O14: 8176 | P14: 1.01 | Q14: =(Q13) -> 21/01 a 22/01 | S14: 8204 | T14: ROTISSERIA CANELONE PRE/QUEIJO E M.BRANCO BENDITO KG | U14: 8204 | V14: 0.85 | W14: =(W13) -> 15/01 a 016/01 | Y14: 8153 | Z14: ROTISSERIA BERINJELA PIZZAOLA BENDITO KG | AA14: 8153 | AB14: 1.69 | AC14: =(AC13) -> 16/01 a 17/01 | AE14: 8221 | AF14: ROTISSERIA CAPONATA BERINJELA BENDITO KG | AG14: 8221 | AH14: 0.35 | AI14: =(AI13) -> 17/01 a 18/01 | AK14: 7241 | AL14: BOLO RECHEADO BRIGADEIRO BENDITO KG | AM14: 7241 | AN14: 0.96 | AO14: =(AO13) -> 20/10 A 23/10 | AQ14: 6951 | AR14: PAO CASEIRINHO BENDITO KG | AS14: 6951 | AT14: 7.35 | AU14: 241.98 | AV14: =(AT14/7) -> 1.05 | AW14: =(AU14/7) -> 34.568571
A15: 8292 | B15: ROTISSERIA CREME DE MILHO BENDITO KG | C15: 8292 | D15: 0.98 | E15: =(E14) -> 19/01 a20/01 | G15: 8221 | H15: ROTISSERIA CAPONATA BERINJELA BENDITO KG | I15: 8221 | J15: 0.75 | K15: =(K14) -> 20/01 a 21/01 | M15: 8204 | N15: ROTISSERIA CANELONE PRE/QUEIJO E M.BRANCO BENDITO KG | O15: 8204 | P15: 0.33 | Q15: =(Q14) -> 21/01 a 22/01 | S15: 8221 | T15: ROTISSERIA CAPONATA BERINJELA BENDITO KG | U15: 8221 | V15: 0.35 | W15: =(W14) -> 15/01 a 016/01 | Y15: 8221 | Z15: ROTISSERIA CAPONATA BERINJELA BENDITO KG | AA15: 8221 | AB15: 0.7 | AC15: =(AC14) -> 16/01 a 17/01 | AE15: 8281 | AF15: ROTISSERIA COUVE REFOGADA BENDITO KG | AG15: 8281 | AH15: 0.16 | AI15: =(AI14) -> 17/01 a 18/01 | AK15: 7245 | AL15: BOLO RECHEADO DOCE LEITE C/AMEIXA BENDITO KG | AM15: 7245 | AN15: 0.15 | AO15: =(AO14) -> 20/10 A 23/10 | AQ15: 95804 | AR15: PAO GRATINADO KG | AS15: 95804 | AT15: 7.07 | AU15: 232.63 | AV15: =(AT15/7) -> 1.01 | AW15: =(AU15/7) -> 33.232857
... A34: 8571 | B34: ROTISSERIA POLENTA AO MOLHO CARNE MOIDA BENDITO KG | C34: 8571 | D34: 4.09 | E34: =(E33) -> 19/01 a20/01 | G34: 8497 | H34: ROTISSERIA MIX LEGUMES ASSADO BENDITO KG | I34: 8497 | J34: 0.61 | K34: =(K33) -> 20/01 a 21/01 | M34: 8491 | N34: ROTISSERIA MEDALHAO FRANGO BENDITO KG | O34: 8491 | P34: 1.16 | Q34: =(Q33) -> 21/01 a 22/01 | S34: 8633 | T34: ROTISSERIA REPOLHO REFOGADO BENDITO KG | U34: 8633 | V34: 0.69 | W34: =(W33) -> 15/01 a 016/01 | Y34: 8497 | Z34: ROTISSERIA MIX LEGUMES ASSADO BENDITO KG | AA34: 8497 | AB34: 0.84 | AC34: =(AC33) -> 16/01 a 17/01 | AE34: 8482 | AF34: ROTISSERIA MAIONESE DE LEGUMES COM FRANGO BENDITO KG | AG34: 8482 | AH34: 2.15 | AI34: =(AI33) -> 17/01 a 18/01 | AK34: 508 | AL34: F.PROPRIA FORROZINHO GOTAS CHOCOLATE KG | AM34: 508 | AN34: 0.75 | AO34: =(AO33) -> 20/10 A 23/10 | AQ34: 7411 | AR34: HOT DOG BENDITO KG | AS34: 7411 | AT34: 2.38 | AU34: 90.13 | AV34: =(AT34/7) -> 0.34 | AW34: =(AU34/7) -> 12.875714
A35: 8963 | B35: ROTISSERIA SALADA CEASER C/FRANGO BENDITO | C35: 8963 | D35: 5 | E35: =(E34) -> 19/01 a20/01 | G35: 8502 | H35: ROTISSERIA NHOQUE DE BATATA C/ CARNE BENDITO KG | I35: 8502 | J35: 0.82 | K35: =(K34) -> 20/01 a 21/01 | M35: 8497 | N35: ROTISSERIA MIX LEGUMES ASSADO BENDITO KG | O35: 8497 | P35: 1 | Q35: =(Q34) -> 21/01 a 22/01 | S35: 8671 | T35: ROTISSERIA SALADA BATATONESE BENDITO KG | U35: 8671 | V35: 0.74 | Y35: 6960 | Z35: ROTISSERIA NHOQUE AO MOLHO SUGO BENDITO KG | AA35: 6960 | AB35: 1.14 | AC35: =(AC34) -> 16/01 a 17/01 | AE35: 8484 | AF35: ROTISSERIA MAMINHA ASSADA BENDITO KG | AG35: 8484 | AH35: 0.5 | AI35: =(AI34) -> 17/01 a 18/01 | AK35: 104255 | AL35: F.PROPRIA LANCHE PEITO PERU C/MUSSARELA KG | AM35: 104255 | AN35: 0.51 | AO35: =(AO34) -> 20/10 A 23/10 | AQ35: 7004 | AR35: ROSQUINHA DE LEITE NINHO BENDITO KG | AS35: 7004 | AT35: 2.23 | AU35: 88.98 | AV35: =(AT35/7) -> 0.31857143 | AW35: =(AU35/7) -> 12.711429
A36: 8695 | B36: ROTISSERIA SALADA DE BETERRABA BENDITO KG | C36: 8695 | D36: 1.28 | E36: =(E35) -> 19/01 a20/01 | G36: 8551 | H36: ROTISSERIA PATE ALHO BENDITO KG | I36: 8551 | J36: 0.12 | K36: =(K35) -> 20/01 a 21/01 | M36: 8498 | N36: ROTISSERIA MOLHO PIMENTA ARTESANAL BENDITO KG | O36: 8498 | P36: 0.33 | Q36: =(Q35) -> 21/01 a 22/01 | S36: 8963 | T36: ROTISSERIA SALADA CEASER C/FRANGO BENDITO | U36: 8963 | V36: 4 | Y36: 8529 | Z36: ROTISSERIA PANQUECA DE CARNE AO POMODORO BENDITO KG | AA36: 8529 | AB36: 0.62 | AC36: =(AC35) -> 16/01 a 17/01 | AE36: 8497 | AF36: ROTISSERIA MIX LEGUMES ASSADO BENDITO KG | AG36: 8497 | AH36: 0.34 | AI36: =(AI35) -> 17/01 a 18/01 | AK36: 104256 | AL36: F.PROPRIA LANCHE PRESUNTO E QUEIJO KG | AM36: 104256 | AN36: 0.58 | AO36: =(AO35) -> 20/10 A 23/10 | AQ36: 7003 | AR36: ROSQUINHA COCO BENDITO KG | AS36: 7003 | AT36: 2.19 | AU36: 87.28 | AV36: =(AT36/7) -> 0.31285714 | AW36: =(AU36/7) -> 12.468571
A37: 8789 | B37: ROTISSERIA SALADA SUNOMONO BENDITOKG | C37: 8789 | D37: 0.42 | E37: =(E36) -> 19/01 a20/01 | G37: 8563 | H37: ROTISSERIA PERNIL ACEBOLADO BENDITO KG | I37: 8563 | J37: 0.65 | K37: =(K36) -> 20/01 a 21/01 | M37: 8502 | N37: ROTISSERIA NHOQUE DE BATATA C/ CARNE BENDITO KG | O37: 8502 | P37: 0.82 | Q37: =(Q36) -> 21/01 a 22/01 | S37: 8690 | T37: ROTISSERIA SALADA DE BATATA CURTINHA BENDITO KG | U37: 8690 | V37: 1.19 | Y37: 8532 | Z37: ROTISSERIA PANQUECA DE FRANGO BENDITO KG | AA37: 8532 | AB37: 1.7 | AC37: =(AC36) -> 16/01 a 17/01 | AE37: 8498 | AF37: ROTISSERIA MOLHO PIMENTA ARTESANAL BENDITO KG | AG37: 8498 | AH37: 0.31 | AI37: =(AI36) -> 17/01 a 18/01 | AK37: 104254 | AL37: F.PROPRIA LANCHE SALAME COM QUEIJO PRATO KG | AM37: 104254 | AN37: 0.57 | AO37: =(AO36) -> 20/10 A 23/10 | AQ37: 7481 | AR37: PUDIM LEITE COND.TRIANGULO BENDITO KG | AS37: 7481 | AT37: 2.02 | AU37: 86.58 | AV37: =(AT37/7) -> 0.28857143 | AW37: =(AU37/7) -> 12.368571
A38: 8837 | B38: ROTISSERIA STROGONOFF DE FRANGO BENDITO KG | C38: 8837 | D38: 1.19 | E38: =(E37) -> 19/01 a20/01 | G38: 8571 | H38: ROTISSERIA POLENTA AO MOLHO CARNE MOIDA BENDITO KG | I38: 8571 | J38: 1.21 | K38: =(K37) -> 20/01 a 21/01 | M38: 8551 | N38: ROTISSERIA PATE ALHO BENDITO KG | O38: 8551 | P38: 0.12 | Q38: =(Q37) -> 21/01 a 22/01 | S38: 8695 | T38: ROTISSERIA SALADA DE BETERRABA BENDITO KG | U38: 8695 | V38: 0.75 | Y38: 8551 | Z38: ROTISSERIA PATE ALHO BENDITO KG | AA38: 8551 | AB38: 0.75 | AC38: =(AC37) -> 16/01 a 17/01 | AE38: 6960 | AF38: ROTISSERIA NHOQUE AO MOLHO SUGO BENDITO KG | AG38: 6960 | AH38: 1.53 | AI38: =(AI37) -> 17/01 a 18/01 | AK38: 1589 | AL38: F.PROPRIA LUA DE MEL DOCE LEITE POLVILHADA COM NINHO KG | AM38: 1589 | AN38: 0.18 | AO38: =(AO37) -> 20/10 A 23/10 | AQ38: 6955 | AR38: PAO DE FRIOS BENDITO KG | AS38: 6955 | AT38: 1.91 | AU38: 85.57 | AV38: =(AT38/7) -> 0.27285714 | AW38: =(AU38/7) -> 12.224286
A39: 9123 | B39: ROTISSERIA SUSHI KANI C/CREAM CHEESE BENDITO UN | C39: 9123 | D39: 5 | E39: =(E38) -> 19/01 a20/01 | G39: 8671 | H39: ROTISSERIA SALADA BATATONESE BENDITO KG | I39: 8671 | J39: 0.4 | K39: =(K38) -> 20/01 a 21/01 | M39: 8598 | N39: ROTISSERIA PURE DE BATATA BENDITO KG | O39: 8598 | P39: 0.37 | Q39: =(Q38) -> 21/01 a 22/01 | S39: 9391 | T39: ROTISSERIA SALADA FRESH HONEY PERU BENDITO | U39: 9391 | V39: 2 | Y39: 8598 | Z39: ROTISSERIA PURE DE BATATA BENDITO KG | AA39: 8598 | AB39: 0.83 | AC39: =(AC38) -> 16/01 a 17/01 | AE39: 8532 | AF39: ROTISSERIA PANQUECA DE FRANGO BENDITO KG | AG39: 8532 | AH39: 1.09 | AI39: =(AI38) -> 17/01 a 18/01 | AK39: 1589 | AL39: F.PROPRIA LUA DE MEL DOCE LEITE POLVILHADA COM NINHO KG | AM39: 1589 | AN39: 0.66 | AO39: =(AO38) -> 20/10 A 23/10 | AQ39: 6963 | AR39: PAO DONUTS CHOCOLATE BENDITO KG | AS39: 6963 | AT39: 1.85 | AU39: 83.23 | AV39: =(AT39/7) -> 0.26428571 | AW39: =(AU39/7) -> 11.89
A40: 8847 | B40: ROTISSERIA TIRINHA DE CARNE BENDITO KG | C40: 8847 | D40: 0.99 | E40: =(E39) -> 19/01 a20/01 | G40: 8963 | H40: ROTISSERIA SALADA CEASER C/FRANGO BENDITO | I40: 8963 | J40: 4 | K40: =(K39) -> 20/01 a 21/01 | M40: 8671 | N40: ROTISSERIA SALADA BATATONESE BENDITO KG | O40: 8671 | P40: 1.35 | Q40: =(Q39) -> 21/01 a 22/01 | S40: 8789 | T40: ROTISSERIA SALADA SUNOMONO BENDITOKG | U40: 8789 | V40: 0.61 | Y40: 8633 | Z40: ROTISSERIA REPOLHO REFOGADO BENDITO KG | AA40: 8633 | AB40: 0.43 | AC40: =(AC39) -> 16/01 a 17/01 | AE40: 8551 | AF40: ROTISSERIA PATE ALHO BENDITO KG | AG40: 8551 | AH40: 0.38 | AI40: =(AI39) -> 17/01 a 18/01 | AK40: 515 | AL40: F.PROPRIA PAO BISNAGUINHA FP KG | AM40: 515 | AN40: 1.21 | AO40: =(AO39) -> 20/10 A 23/10 | AQ40: 7141 | AR40: BOLO LIMAO C COBERTURA BENDITO KG | AS40: 7141 | AT40: 1.65 | AU40: 82.34 | AV40: =(AT40/7) -> 0.23571429 | AW40: =(AU40/7) -> 11.762857
A41: 7075 | B41: SUI PROD.TORRESMO FRITO KG | C41: 7075 | D41: 4.5 | E41: =(E40) -> 19/01 a20/01 | G41: 8690 | H41: ROTISSERIA SALADA DE BATATA CURTINHA BENDITO KG | I41: 8690 | J41: 0.44 | K41: =(K40) -> 20/01 a 21/01 | M41: 8963 | N41: ROTISSERIA SALADA CEASER C/FRANGO BENDITO | O41: 8963 | P41: 5 | Q41: =(Q40) -> 21/01 a 22/01 | S41: 8834 | T41: ROTISSERIA STROGONOFF DE CARNE BENDITO KG | U41: 8834 | V41: 0.6 | Y41: 8671 | Z41: ROTISSERIA SALADA BATATONESE BENDITO KG | AA41: 8671 | AB41: 0.39 | AC41: =(AC40) -> 16/01 a 17/01 | AE41: 8598 | AF41: ROTISSERIA PURE DE BATATA BENDITO KG | AG41: 8598 | AH41: 1.22 | AI41: =(AI40) -> 17/01 a 18/01 | AK41: 544 | AL41: F.PROPRIA PAO CASEIRINHO KG | AM41: 544 | AN41: 0.74 | AO41: =(AO40) -> 20/10 A 23/10 | AQ41: 7399 | AR41: HOT DOG COM MOSTARDA BENDITO KG | AS41: 7399 | AT41: 1.96 | AU41: 74.28 | AV41: =(AT41/7) -> 0.28 | AW41: =(AU41/7) -> 10.611429
A42: 8695 | B42: ROTISSERIA SALADA DE BETERRABA BENDITO KG | C42: 8695 | D42: 1.57 | E42: =(E41) -> 19/01 a20/01 | G42: 8695 | H42: ROTISSERIA SALADA DE BETERRABA BENDITO KG | I42: 8695 | J42: 2.7 | K42: =(K41) -> 20/01 a 21/01 | M42: 8690 | N42: ROTISSERIA SALADA DE BATATA CURTINHA BENDITO KG | O42: 8690 | P42: 1.62 | Q42: =(Q41) -> 21/01 a 22/01 | S42: 8847 | T42: ROTISSERIA TIRINHA DE CARNE BENDITO KG | U42: 8847 | V42: 0.63 | Y42: 8963 | Z42: ROTISSERIA SALADA CEASER C/FRANGO BENDITO | AA42: 8963 | AB42: 3 | AC42: =(AC41) -> 16/01 a 17/01 | AE42: 8963 | AF42: ROTISSERIA SALADA CEASER C/FRANGO BENDITO | AG42: 8963 | AH42: 3 | AI42: =(AI41) -> 17/01 a 18/01 | AK42: 759 | AL42: F.PROPRIA PAO DE CALABREZA KG | AM42: 759 | AN42: 1.29 | AO42: =(AO41) -> 20/10 A 23/10 | AQ42: 7475 | AR42: PAVE DE PESSEGO BENDITO KG | AS42: 7475 | AT42: 1.18 | AU42: 73.97 | AV42: =(AT42/7) -> 0.16857143 | AW42: =(AU42/7) -> 10.567143
A43: 8702 | B43: ROTISSERIA SALADA DE BROCOLIS C/COUVE FLOR BENDITO KG | C43: 8702 | D43: 0.22 | E43: =(E42) -> 19/01 a20/01 | G43: 9391 | H43: ROTISSERIA SALADA FRESH HONEY PERU BENDITO | I43: 9391 | J43: 1 | K43: =(K42) -> 20/01 a 21/01 | M43: 8695 | N43: ROTISSERIA SALADA DE BETERRABA BENDITO KG | O43: 8695 | P43: 2.23 | Q43: =(Q42) -> 21/01 a 22/01 | S43: 8874 | T43: ROTISSERIA TUTU DE FEIJAO BENDITO KG | U43: 8874 | V43: 0.25 | Y43: 8690 | Z43: ROTISSERIA SALADA DE BATATA CURTINHA BENDITO KG | AA43: 8690 | AB43: 0.4 | AC43: =(AC42) -> 16/01 a 17/01 | AE43: 8702 | AF43: ROTISSERIA SALADA DE BROCOLIS C/COUVE FLOR BENDITO KG | AG43: 8702 | AH43: 0.37 | AI43: =(AI42) -> 17/01 a 18/01 | AK43: 1663 | AL43: F.PROPRIA PAO DE MILHO KG | AM43: 1663 | AN43: 0.16 | AO43: =(AO42) -> 20/10 A 23/10 | AQ43: 6915 | AR43: F.PROPRIA ESFIRRA BRCOLIS QJO E BACON KG | AS43: 6915 | AT43: 1.22 | AU43: 73.09 | AV43: =(AT43/7) -> 0.17428571 | AW43: =(AU43/7) -> 10.441429
A44: 9391 | B44: ROTISSERIA SALADA FRESH HONEY PERU BENDITO | C44: 9391 | D44: 6 | E44: =(E43) -> 19/01 a20/01 | G44: 8789 | H44: ROTISSERIA SALADA SUNOMONO BENDITOKG | I44: 8789 | J44: 0.42 | K44: =(K43) -> 20/01 a 21/01 | M44: 9391 | N44: ROTISSERIA SALADA FRESH HONEY PERU BENDITO | O44: 9391 | P44: 2 | Q44: =(Q43) -> 21/01 a 22/01 | S44: 7065 | T44: SUI PROD.BANHA KG | U44: 7065 | V44: 5.74 | Y44: 8695 | Z44: ROTISSERIA SALADA DE BETERRABA BENDITO KG | AA44: 8695 | AB44: 0.25 | AC44: =(AC43) -> 16/01 a 17/01 | AE44: 8834 | AF44: ROTISSERIA STROGONOFF DE CARNE BENDITO KG | AG44: 8834 | AH44: 0.39 | AI44: =(AI43) -> 17/01 a 18/01 | AK44: 523 | AL44: F.PROPRIA PAO HAMBURGUER KG | AM44: 523 | AN44: 0.51 | AO44: =(AO43) -> 20/10 A 23/10 | AQ44: 7260 | AR44: BOLO RECHEADO LEITE NINHO C/MORANGO BENDITO KG | AS44: 7260 | AT44: 0.96 | AU44: 71.77 | AV44: =(AT44/7) -> 0.13714286 | AW44: =(AU44/7) -> 10.252857
A45: 8789 | B45: ROTISSERIA SALADA SUNOMONO BENDITOKG | C45: 8789 | D45: 0.88 | E45: =(E44) -> 19/01 a20/01 | G45: 8837 | H45: ROTISSERIA STROGONOFF DE FRANGO BENDITO KG | I45: 8837 | J45: 1.59 | K45: =(K44) -> 20/01 a 21/01 | M45: 8789 | N45: ROTISSERIA SALADA SUNOMONO BENDITOKG | O45: 8789 | P45: 0.22 | Q45: =(Q44) -> 21/01 a 22/01 | S45: 7075 | T45: SUI PROD.TORRESMO FRITO KG | U45: 7075 | V45: 0.65 | Y45: 8702 | Z45: ROTISSERIA SALADA DE BROCOLIS C/COUVE FLOR BENDITO KG | AA45: 8702 | AB45: 0.37 | AC45: =(AC44) -> 16/01 a 17/01 | AE45: 9123 | AF45: ROTISSERIA SUSHI KANI C/CREAM CHEESE BENDITO UN | AG45: 9123 | AH45: 1 | AI45: =(AI44) -> 17/01 a 18/01 | AK45: 2079 | AL45: F.PROPRIA ROCAMBOLE DOCE LEITE KG | AM45: 2079 | AN45: 0.47 | AO45: =(AO44) -> 20/10 A 23/10 | AQ45: 7474 | AR45: PAVE CHOCOLATE BENDITO KG | AS45: 7474 | AT45: 1.01 | AU45: 70.76 | AV45: =(AT45/7) -> 0.14428571 | AW45: =(AU45/7) -> 10.108571
A46: 8837 | B46: ROTISSERIA STROGONOFF DE FRANGO BENDITO KG | C46: 8837 | D46: 0.35 | E46: =(E45) -> 19/01 a20/01 | G46: 9123 | H46: ROTISSERIA SUSHI KANI C/CREAM CHEESE BENDITO UN | I46: 9123 | J46: 10 | K46: =(K45) -> 20/01 a 21/01 | M46: 8837 | N46: ROTISSERIA STROGONOFF DE FRANGO BENDITO KG | O46: 8837 | P46: 0.63 | Q46: =(Q45) -> 21/01 a 22/01 | Y46: 8789 | Z46: ROTISSERIA SALADA SUNOMONO BENDITOKG | AA46: 8789 | AB46: 0.19 | AC46: =(AC45) -> 16/01 a 17/01 | AE46: 8839 | AF46: ROTISSERIA TABULE BENDITO KG | AG46: 8839 | AH46: 1.92 | AI46: =(AI45) -> 17/01 a 18/01 | AK46: 2072 | AL46: F.PROPRIA ROCAMBOLE GOIABADA KG | AM46: 2072 | AN46: 0.37 | AO46: =(AO45) -> 20/10 A 23/10 | AQ46: 7398 | AR46: GELATINA COLORIDA BENDITO KG | AS46: 7398 | AT46: 1.75 | AU46: 69.74 | AV46: =(AT46/7) -> 0.25 | AW46: =(AU46/7) -> 9.9628571
A47: 9123 | B47: ROTISSERIA SUSHI KANI C/CREAM CHEESE BENDITO UN | C47: 9123 | D47: 5 | E47: =(E46) -> 19/01 a20/01 | G47: 8847 | H47: ROTISSERIA TIRINHA DE CARNE BENDITO KG | I47: 8847 | J47: 1.58 | K47: =(K46) -> 20/01 a 21/01 | M47: 9123 | N47: ROTISSERIA SUSHI KANI C/CREAM CHEESE BENDITO UN | O47: 9123 | P47: 6 | Q47: =(Q46) -> 21/01 a 22/01 | V47: 108.702 | Y47: 8834 | Z47: ROTISSERIA STROGONOFF DE CARNE BENDITO KG | AA47: 8834 | AB47: 0.99 | AC47: =(AC46) -> 16/01 a 17/01 | AE47: 8523 | AF47: ROTISSERIA TULIPA BUFALO WINGS KG | AG47: 8523 | AH47: 0.64 | AI47: =(AI46) -> 17/01 a 18/01 | AK47: 2923 | AL47: F.PROPRIA ROCAMBOLE LEITE NINHO KG | AM47: 2923 | AN47: 0.19 | AO47: =(AO46) -> 20/10 A 23/10 | AQ47: 6993 | AR47: ROSCA RECHEADA COCO BENDITO KG | AS47: 6993 | AT47: 1.41 | AU47: 67.44 | AV47: =(AT47/7) -> 0.20142857 | AW47: =(AU47/7) -> 9.6342857
A48: 8839 | B48: ROTISSERIA TABULE BENDITO KG | C48: 8839 | D48: 1.3 | E48: =(E47) -> 19/01 a20/01 | G48: 8874 | H48: ROTISSERIA TUTU DE FEIJAO BENDITO KG | I48: 8874 | J48: 0.4 | K48: =(K47) -> 20/01 a 21/01 | M48: 8839 | N48: ROTISSERIA TABULE BENDITO KG | O48: 8839 | P48: 0.54 | Q48: =(Q47) -> 21/01 a 22/01 | S48: 8874 | T48: ROTISSERIA TUTU DE FEIJAO BENDITO KG | U48: 8874 | V48: 1.09 | Y48: 9123 | Z48: ROTISSERIA SUSHI KANI C/CREAM CHEESE BENDITO UN | AA48: 9123 | AB48: 1 | AC48: =(AC47) -> 16/01 a 17/01 | AE48: 8874 | AF48: ROTISSERIA TUTU DE FEIJAO BENDITO KG | AG48: 8874 | AH48: 0.23 | AI48: =(AI47) -> 17/01 a 18/01 | AK48: 643 | AL48: F.PROPRIA ROSCA CASEIRA COCO KG | AM48: 643 | AN48: 0.33 | AO48: =(AO47) -> 20/10 A 23/10 | AQ48: 7529 | AR48: COOKIES CHOCOLATE BENDITO KG | AS48: 7529 | AT48: 1.33 | AU48: 66.14 | AV48: =(AT48/7) -> 0.19 | AW48: =(AU48/7) -> 9.4485714
A49: 8847 | B49: ROTISSERIA TIRINHA DE CARNE BENDITO KG | C49: 8847 | D49: 0.88 | E49: =(E48) -> 19/01 a20/01 | G49: 7065 | H49: SUI PROD.BANHA KG | I49: 7065 | J49: 0.85 | K49: =(K48) -> 20/01 a 21/01 | M49: 8847 | N49: ROTISSERIA TIRINHA DE CARNE BENDITO KG | O49: 8847 | P49: 0.6 | Q49: =(Q48) -> 21/01 a 22/01 | S49: 7065 | T49: SUI PROD.BANHA KG | U49: 7065 | V49: 0.77 | Y49: 8839 | Z49: ROTISSERIA TABULE BENDITO KG | AA49: 8839 | AB49: 1.92 | AC49: =(AC48) -> 16/01 a 17/01 | AE49: 8900 | AF49: ROTISSERIA YAKISSOBA BENDITO KG | AG49: 8900 | AH49: 2.04 | AI49: =(AI48) -> 17/01 a 18/01 | AK49: 6231 | AL49: F.PROPRIA ROSCA CASEIRA NINHO KG | AM49: 6231 | AN49: 0.27 | AO49: =(AO48) -> 20/10 A 23/10 | AQ49: 7348 | AR49: ESFIRRA CARNE, BROCOLIS E QUEIJO BENDITO KG | AS49: 7348 | AT49: 1.09 | AU49: 65.06 | AV49: =(AT49/7) -> 0.15571429 | AW49: =(AU49/7) -> 9.2942857
A50: 7065 | B50: SUI PROD.BANHA KG | C50: 7065 | D50: 0.94 | E50: =(E49) -> 19/01 a20/01 | G50: 7075 | H50: SUI PROD.TORRESMO FRITO KG | I50: 7075 | J50: 7.17 | K50: =(K49) -> 20/01 a 21/01 | M50: 8874 | N50: ROTISSERIA TUTU DE FEIJAO BENDITO KG | O50: 8874 | P50: 1 | Q50: =(Q49) -> 21/01 a 22/01 | S50: 7065 | T50: SUI PROD.BANHA KG | U50: 7065 | V50: 4.77 | Y50: 8874 | Z50: ROTISSERIA TUTU DE FEIJAO BENDITO KG | AA50: 8874 | AB50: 0.48 | AC50: =(AC49) -> 16/01 a 17/01 | AE50: 7065 | AF50: SUI PROD.BANHA KG | AG50: 7065 | AH50: 2.39 | AI50: =(AI49) -> 17/01 a 18/01 | AK50: 235 | AL50: F.PROPRIA ROSCA CREME C/ GOIABADA | AM50: 235 | AN50: 0.28 | AO50: =(AO49) -> 20/10 A 23/10 | AQ50: 7120 | AR50: BOLO FUBA C/MILHO BENDITO KG | AS50: 7120 | AT50: 1.59 | AU50: 63.45 | AV50: =(AT50/7) -> 0.22714286 | AW50: =(AU50/7) -> 9.0642857
A51: 7075 | B51: SUI PROD.TORRESMO FRITO KG | C51: 7075 | D51: 4.15 | E51: =(E50) -> 19/01 a20/01 | K51: =(K50) -> 20/01 a 21/01 | M51: 7065 | N51: SUI PROD.BANHA KG | O51: 7065 | P51: 5.9 | Q51: =(Q50) -> 21/01 a 22/01 | S51: 7075 | T51: SUI PROD.TORRESMO FRITO KG | U51: 7075 | V51: 6.54 | Y51: 8900 | Z51: ROTISSERIA YAKISSOBA BENDITO KG | AA51: 8900 | AB51: 2.04 | AC51: =(AC50) -> 16/01 a 17/01 | AI51: =(AI50) -> 17/01 a 18/01 | AK51: 164 | AL51: F.PROPRIA ROSCA RECHEADA COCO KG | AM51: 164 | AN51: 0.29 | AO51: =(AO50) -> 20/10 A 23/10 | AQ51: 7200 | AR51: BOLO PISCINA CENOURA BENDITO KG | AS51: 7200 | AT51: 1.23 | AU51: 61.58 | AV51: =(AT51/7) -> 0.17571429 | AW51: =(AU51/7) -> 8.7971429
E52: =(E51) -> 19/01 a20/01 | J52: 110.166 | K52: =(K51) -> 20/01 a 21/01 | M52: 7075 | N52: SUI PROD.TORRESMO FRITO KG | O52: 7075 | P52: 7.41 | Q52: =(Q51) -> 21/01 a 22/01 | S52: 7075 | T52: SUI PROD.TORRESMO FRITO KG | U52: 7075 | V52: 0.15 | Y52: 7065 | Z52: SUI PROD.BANHA KG | AA52: 7065 | AB52: 4.85 | AC52: =(AC51) -> 16/01 a 17/01 | AI52: =(AI51) -> 17/01 a 18/01 | AK52: 6228 | AL52: F.PROPRIA ROSQUINHA COCO KG | AM52: 6228 | AN52: 0.69 | AO52: =(AO51) -> 20/10 A 23/10 | AQ52: 7488 | AR52: QUICHE FRANGO C/REQUEIJAO BENDITO 400GR | AS52: 7488 | AT52: 2 | AU52: 57.8 | AV52: =(AT52/7) -> 0.28571429 | AW52: =(AU52/7) -> 8.2571429
E53: =(E52) -> 19/01 a20/01 | K53: =(K52) -> 20/01 a 21/01 | AC53: =(AC52) -> 16/01 a 17/01 | AI53: =(AI52) -> 17/01 a 18/01 | AK53: 511 | AL53: F.PROPRIA ROSQUINHA DE LEITE NINHO KG | AM53: 511 | AN53: 0.14 | AO53: =(AO52) -> 20/10 A 23/10 | AQ53: 6954 | AR53: PAO BRIOCHE CALABRESA BENDITO KG | AS53: 6954 | AT53: 1.19 | AU53: 55.73 | AV53: =(AT53/7) -> 0.17 | AW53: =(AU53/7) -> 7.9614286
E54: =(E53) -> 19/01 a20/01 | K54: =(K53) -> 20/01 a 21/01 | P54: 114.803 | V54: 153.942 | AB54: 133.1 | AC54: =(AC53) -> 16/01 a 17/01 | AI54: =(AI53) -> 17/01 a 18/01 | AK54: 511 | AL54: F.PROPRIA ROSQUINHA DE LEITE NINHO KG | AM54: 511 | AN54: 0.15 | AO54: =(AO53) -> 20/10 A 23/10 | AQ54: 7265 | AR54: BOLO NINHO C/OURO BRC BENDITO KG | AS54: 7265 | AT54: 0.69 | AU54: 51.53 | AV54: =(AT54/7) -> 0.098571429 | AW54: =(AU54/7) -> 7.3614286
E55: =(E54) -> 19/01 a20/01 | K55: =(K54) -> 20/01 a 21/01 | AB55: 177.205 | AC55: =(AC54) -> 16/01 a 17/01 | AI55: =(AI54) -> 17/01 a 18/01 | AK55: 7327 | AL55: F. PROPRIA SEQUILHOS KG | AM55: 7327 | AN55: 0.22 | AO55: =(AO54) -> 20/10 A 23/10 | AQ55: 6950 | AR55: PAO BRIOCHE BENDITO KG | AS55: 6950 | AT55: 1.02 | AU55: 50.7 | AV55: =(AT55/7) -> 0.14571429 | AW55: =(AU55/7) -> 7.2428571
E56: =(E55) -> 19/01 a20/01 | K56: =(K55) -> 20/01 a 21/01 | AC56: =(AC55) -> 16/01 a 17/01 | AI56: =(AI55) -> 17/01 a 18/01 | AK56: 7327 | AL56: F. PROPRIA SEQUILHOS KG | AM56: 7327 | AN56: 0.34 | AO56: =(AO55) -> 20/10 A 23/10 | AQ56: 7195 | AR56: F.PROPRIA SALGADO DE CALABRESA ASSADO KG | AS56: 7195 | AT56: 1.27 | AU56: 50.61 | AV56: =(AT56/7) -> 0.18142857 | AW56: =(AU56/7) -> 7.23
E57: =(E56) -> 19/01 a20/01 | K57: =(K56) -> 20/01 a 21/01 | AC57: =(AC56) -> 16/01 a 17/01 | AI57: =(AI56) -> 17/01 a 18/01 | AK57: 4052 | AL57: F.PROPRIA SONHO CREME KG | AM57: 4052 | AN57: 0.5 | AO57: =(AO56) -> 20/10 A 23/10 | AQ57: 7473 | AR57: PAO DE CALABREZA BENDITO KG | AS57: 7473 | AT57: 1.34 | AU57: 48.12 | AV57: =(AT57/7) -> 0.19142857 | AW57: =(AU57/7) -> 6.8742857
E58: =(E57) -> 19/01 a20/01 | K58: =(K57) -> 20/01 a 21/01 | AC58: =(AC57) -> 16/01 a 17/01 | AI58: =(AI57) -> 17/01 a 18/01 | AK58: 93445 | AL58: F.PROPRIA TORTA DE FRANGO KG | AM58: 93445 | AN58: 0.38 | AO58: =(AO57) -> 20/10 A 23/10 | AQ58: 7496 | AR58: ROCAMBOLE PRESTIGIO BENDITO KG | AS58: 7496 | AT58: 0.97 | AU58: 46.28 | AV58: =(AT58/7) -> 0.13857143 | AW58: =(AU58/7) -> 6.6114286
...

Sheet SEGUNDA
A1: SEGUNDA (LOJA 1 DESCONTÃO-ROTISSERIA) | I1: SUJESTÃO DE PEDIDO | R1: DATA | S1: 46048
A2: ALMOÇO | C2: INFORMAÇÕES DO PEDIDO | D2: INFORMAÇÕES DO PEDIDO | I2: INFORMAÇÕES SUGESTÃO DE PEDIDO | P2: ALMOÇO | R2: INFORMAÇÕES DO PEDIDO
A3: COD | B3: MARMITA 3 DIVISORIAS | C3: QTD | D3: KG/UN | E3: P.PADRÃO | F3: Q.PCT | G3: PREÇO | H3: TOTAL | I3: VENDA QTD | J3: EM PCT | K3: EM VALORES | L3: PERIODO BASE | M3: STATUS | P3: COD | Q3: MARMITA 3 DIVISORIAS | R3: QTD | S3: Q.PCT
A4: =('[1]ESCALA DE PRODUÇÃO'!B3) -> 7768 | B4: =_xlfn.XLOOKUP(A4,'[1]ESCALA DE PRODUÇÃO'!$AL$1:$AL$1048566,'[1]ESCALA DE PRODUÇÃO'!$AJ$1:$AJ$1048566,"NÃO ENCOTRADO") -> 007768 - REFEICAO LAGARTO M.MADEIRA + BATATA ASSADA BENDITO | C4: 10 | D4: =_xlfn.XLOOKUP(A4,'[1]ESCALA DE PRODUÇÃO'!$AL$1:$AL$1048566,'[1]ESCALA DE PRODUÇÃO'!$AK$1:$AK$1048566,"0") -> UN/0001 | E4: ='[2]ESCALA DE PRODUÇÃO'!D3 -> 1 | F4: =IFERROR(C4/E4,"0") -> 10 | G4: =_xlfn.XLOOKUP(A4,'[1]ESCALA DE PRODUÇÃO'!$AL$1:$AL$1048566,'[1]ESCALA DE PRODUÇÃO'!$AM$1:$AM$1048566,"SEM PREÇO") -> 24.9 | H4: =IFERROR(C4*G4,"0") -> 249 | I4: =_xlfn.XLOOKUP(A4,'DADOS DE VENDA'!A:A,'DADOS DE VENDA'!D:D,"SEM VENDA") -> 10 | J4: =IFERROR(I4/E4,"0") -> 10 | K4: =IFERROR(I4*G4,"0") -> 249 | L4: =_xlfn.XLOOKUP(A4,'DADOS DE VENDA'!A:A,'DADOS DE VENDA'!E:E,"RUPTURA NO PERIODO") -> 19/01 a20/01 | M4: {=_xlfn.IFS(C4<I4,"ABAIXO",C4>I4,"ACIMA",C4=I4,"OK")} -> OK | P4: =A4 -> 7768 | Q4: =_xlfn.XLOOKUP(P4,'[1]ESCALA DE PRODUÇÃO'!$AL$1:$AL$1048566,'[1]ESCALA DE PRODUÇÃO'!$AJ$1:$AJ$1048566,"NÃO ENCOTRADO") -> 007768 - REFEICAO LAGARTO M.MADEIRA + BATATA ASSADA BENDITO | R4: =C4 -> 10 | S4: =(F4) -> 10
A5: =('[1]ESCALA DE PRODUÇÃO'!B4) -> 8966 | B5: =_xlfn.XLOOKUP(A5,'[1]ESCALA DE PRODUÇÃO'!$AL$1:$AL$1048566,'[1]ESCALA DE PRODUÇÃO'!$AJ$1:$AJ$1048566,"NÃO ENCOTRADO") -> 08966 - REFEICAO ISCA DE FRANGO A MILANESA | C5: 12 | D5: =_xlfn.XLOOKUP(A5,'[1]ESCALA DE PRODUÇÃO'!$AL$1:$AL$1048566,'[1]ESCALA DE PRODUÇÃO'!$AK$1:$AK$1048566,"0") -> UN/0001 | E5: ='[2]ESCALA DE PRODUÇÃO'!D4 -> 1 | F5: =IFERROR(C5/E5,"0") -> 12 | G5: =_xlfn.XLOOKUP(A5,'[1]ESCALA DE PRODUÇÃO'!$AL$1:$AL$1048566,'[1]ESCALA DE PRODUÇÃO'!$AM$1:$AM$1048566,"SEM PREÇO") -> 23.9 | H5: =IFERROR(C5*G5,"0") -> 286.8 | I5: =_xlfn.XLOOKUP(A5,'DADOS DE VENDA'!A:A,'DADOS DE VENDA'!D:D,"SEM VENDA") -> 12 | J5: =IFERROR(I5/E5,"0") -> 12 | K5: =IFERROR(I5*G5,"0") -> 286.8 | L5: =_xlfn.XLOOKUP(A5,'DADOS DE VENDA'!A:A,'DADOS DE VENDA'!E:E,"RUPTURA NO PERIODO") -> 19/01 a20/01 | M5: {=_xlfn.IFS(C5<I5,"ABAIXO",C5>I5,"ACIMA",C5=I5,"OK")} -> OK | P5: =A5 -> 8966 | Q5: =_xlfn.XLOOKUP(P5,'[1]ESCALA DE PRODUÇÃO'!$AL$1:$AL$1048566,'[1]ESCALA DE PRODUÇÃO'!$AJ$1:$AJ$1048566,"NÃO ENCOTRADO") -> 08966 - REFEICAO ISCA DE FRANGO A MILANESA | R5: =C5 -> 12 | S5: =(F5) -> 12
A6: =('[1]ESCALA DE PRODUÇÃO'!B5) -> 0 | B6: =_xlfn.XLOOKUP(A6,'[1]ESCALA DE PRODUÇÃO'!$AL$1:$AL$1048566,'[1]ESCALA DE PRODUÇÃO'!$AJ$1:$AJ$1048566,"NÃO ENCOTRADO") -> NÃO ENCOTRADO | C6: 0 | D6: =_xlfn.XLOOKUP(A6,'[1]ESCALA DE PRODUÇÃO'!$AL$1:$AL$1048566,'[1]ESCALA DE PRODUÇÃO'!$AK$1:$AK$1048566,"0") -> 0 | E6: ='[2]ESCALA DE PRODUÇÃO'!D5 -> 0 | F6: =IFERROR(C6/E6,"0") -> 0 | G6: =_xlfn.XLOOKUP(A6,'[1]ESCALA DE PRODUÇÃO'!$AL$1:$AL$1048566,'[1]ESCALA DE PRODUÇÃO'!$AM$1:$AM$1048566,"SEM PREÇO") -> SEM PREÇO | H6: =IFERROR(C6*G6,"0") -> 0 | I6: =_xlfn.XLOOKUP(A6,'DADOS DE VENDA'!A:A,'DADOS DE VENDA'!D:D,"SEM VENDA") -> SEM VENDA | J6: =IFERROR(I6/E6,"0") -> 0 | K6: =IFERROR(I6*G6,"0") -> 0 | L6: =_xlfn.XLOOKUP(A6,'DADOS DE VENDA'!A:A,'DADOS DE VENDA'!E:E,"RUPTURA NO PERIODO") -> RUPTURA NO PERIODO | M6: {=_xlfn.IFS(C6<I6,"ABAIXO",C6>I6,"ACIMA",C6=I6,"OK")} -> ABAIXO | P6: =A6 -> 0 | Q6: =_xlfn.XLOOKUP(P6,'[1]ESCALA DE PRODUÇÃO'!$AL$1:$AL$1048566,'[1]ESCALA DE PRODUÇÃO'!$AJ$1:$AJ$1048566,"NÃO ENCOTRADO") -> NÃO ENCOTRADO | R6: =C6 -> 0 | S6: =(F6) -> 0
A7: COD | B7: MACARRÃO | C7: QTD | D7: KG/UN | E7: P.PADRÃO | F7: Q.PCT | G7: PREÇO | H7: TOTAL | I7: VENDA QTD | J7: EM PCT | K7: EM VALORES | L7: PERIODO BASE | M7: STATUS | P7: COD | Q7: MACARRÃO | R7: QTD | S7: Q.PCT
A8: =('[1]ESCALA DE PRODUÇÃO'!B7) -> 8480 | B8: =_xlfn.XLOOKUP(A8,'[1]ESCALA DE PRODUÇÃO'!$AL$1:$AL$1048566,'[1]ESCALA DE PRODUÇÃO'!$AJ$1:$AJ$1048566,"NÃO ENCOTRADO") -> 008480 - ROTISSERIA MACARRONADA A BOLONHESA BENDITO KG | C8: 3 | D8: =_xlfn.XLOOKUP(A8,'[1]ESCALA DE PRODUÇÃO'!$AL$1:$AL$1048566,'[1]ESCALA DE PRODUÇÃO'!$AK$1:$AK$1048566,"0") -> KG/0001 | E8: ='[2]ESCALA DE PRODUÇÃO'!D7 -> 0.35 | F8: =IFERROR(C8/E8,"0") -> 8.5714286 | G8: =_xlfn.XLOOKUP(A8,'[1]ESCALA DE PRODUÇÃO'!$AL$1:$AL$1048566,'[1]ESCALA DE PRODUÇÃO'!$AM$1:$AM$1048566,"SEM PREÇO") -> 39.9 | H8: =IFERROR(C8*G8,"0") -> 119.7 | I8: =_xlfn.XLOOKUP(A8,'DADOS DE VENDA'!A:A,'DADOS DE VENDA'!D:D,"SEM VENDA") -> SEM VENDA | J8: =IFERROR(I8/E8,"0") -> 0 | K8: =IFERROR(I8*G8,"0") -> 0 | L8: =_xlfn.XLOOKUP(A8,'DADOS DE VENDA'!A:A,'DADOS DE VENDA'!E:E,"RUPTURA NO PERIODO") -> RUPTURA NO PERIODO | M8: {=_xlfn.IFS(C8<I8,"ABAIXO",C8>I8,"ACIMA",C8=I8,"OK")} -> ABAIXO | P8: =A8 -> 8480 | Q8: =_xlfn.XLOOKUP(P8,'[1]ESCALA DE PRODUÇÃO'!$AL$1:$AL$1048566,'[1]ESCALA DE PRODUÇÃO'!$AJ$1:$AJ$1048566,"NÃO ENCOTRADO") -> 008480 - ROTISSERIA MACARRONADA A BOLONHESA BENDITO KG | R8: =C8 -> 3 | S8: =(F8) -> 8.5714286
A9: =('[1]ESCALA DE PRODUÇÃO'!B8) -> 93626 | B9: =_xlfn.XLOOKUP(A9,'[1]ESCALA DE PRODUÇÃO'!$AL$1:$AL$1048566,'[1]ESCALA DE PRODUÇÃO'!$AJ$1:$AJ$1048566,"NÃO ENCOTRADO") -> 093626 - ROTISSERIA MACARRAO C/BROCOLIS E BACON KG | C9: 2 | D9: =_xlfn.XLOOKUP(A9,'[1]ESCALA DE PRODUÇÃO'!$AL$1:$AL$1048566,'[1]ESCALA DE PRODUÇÃO'!$AK$1:$AK$1048566,"0") -> KG/0001 | E9: ='[2]ESCALA DE PRODUÇÃO'!D8 -> 0.35 | F9: =IFERROR(C9/E9,"0") -> 5.7142857 | G9: =_xlfn.XLOOKUP(A9,'[1]ESCALA DE PRODUÇÃO'!$AL$1:$AL$1048566,'[1]ESCALA DE PRODUÇÃO'!$AM$1:$AM$1048566,"SEM PREÇO") -> 39.9 | H9: =IFERROR(C9*G9,"0") -> 79.8 | I9: =_xlfn.XLOOKUP(A9,'DADOS DE VENDA'!A:A,'DADOS DE VENDA'!D:D,"SEM VENDA") -> 1.17 | J9: =IFERROR(I9/E9,"0") -> 3.3428571 | K9: =IFERROR(I9*G9,"0") -> 46.683 | L9: =_xlfn.XLOOKUP(A9,'DADOS DE VENDA'!A:A,'DADOS DE VENDA'!E:E,"RUPTURA NO PERIODO") -> 19/01 a20/01 | M9: {=_xlfn.IFS(C9<I9,"ABAIXO",C9>I9,"ACIMA",C9=I9,"OK")} -> ACIMA | P9: =A9 -> 93626 | Q9: =_xlfn.XLOOKUP(P9,'[1]ESCALA DE PRODUÇÃO'!$AL$1:$AL$1048566,'[1]ESCALA DE PRODUÇÃO'!$AJ$1:$AJ$1048566,"NÃO ENCOTRADO") -> 093626 - ROTISSERIA MACARRAO C/BROCOLIS E BACON KG | R9: =C9 -> 2 | S9: =(F9) -> 5.7142857
A10: =('[1]ESCALA DE PRODUÇÃO'!B9) -> 0 | B10: =_xlfn.XLOOKUP(A10,'[1]ESCALA DE PRODUÇÃO'!$AL$1:$AL$1048566,'[1]ESCALA DE PRODUÇÃO'!$AJ$1:$AJ$1048566,"NÃO ENCOTRADO") -> NÃO ENCOTRADO | C10: 0 | D10: =_xlfn.XLOOKUP(A10,'[1]ESCALA DE PRODUÇÃO'!$AL$1:$AL$1048566,'[1]ESCALA DE PRODUÇÃO'!$AK$1:$AK$1048566,"0") -> 0 | E10: ='[2]ESCALA DE PRODUÇÃO'!D9 -> 0 | F10: =IFERROR(C10/E10,"0") -> 0 | G10: =_xlfn.XLOOKUP(A10,'[1]ESCALA DE PRODUÇÃO'!$AL$1:$AL$1048566,'[1]ESCALA DE PRODUÇÃO'!$AM$1:$AM$1048566,"SEM PREÇO") -> SEM PREÇO | H10: =IFERROR(C10*G10,"0") -> 0 | I10: =_xlfn.XLOOKUP(A10,'DADOS DE VENDA'!A:A,'DADOS DE VENDA'!D:D,"SEM VENDA") -> SEM VENDA | J10: =IFERROR(I10/E10,"0") -> 0 | K10: =IFERROR(I10*G10,"0") -> 0 | L10: =_xlfn.XLOOKUP(A10,'DADOS DE VENDA'!A:A,'DADOS DE VENDA'!E:E,"RUPTURA NO PERIODO") -> RUPTURA NO PERIODO | M10: {=_xlfn.IFS(C10<I10,"ABAIXO",C10>I10,"ACIMA",C10=I10,"OK")} -> ABAIXO | P10: =A10 -> 0 | Q10: =_xlfn.XLOOKUP(P10,'[1]ESCALA DE PRODUÇÃO'!$AL$1:$AL$1048566,'[1]ESCALA DE PRODUÇÃO'!$AJ$1:$AJ$1048566,"NÃO ENCOTRADO") -> NÃO ENCOTRADO | R10: =C10 -> 0 | S10: =(F10) -> 0
A11: COD | B11: MONO ARROZ | C11: QTD | D11: KG/UN | E11: P.PADRÃO | F11: Q.PCT | G11: PREÇO | H11: TOTAL | I11: VENDA QTD | J11: EM PCT | K11: EM VALORES | L11: PERIODO BASE | M11: STATUS | P11: COD | Q11: MONO ARROZ | R11: QTD | S11: Q.PCT
A12: =('[1]ESCALA DE PRODUÇÃO'!B11) -> 8028 | B12: =_xlfn.XLOOKUP(A12,'[1]ESCALA DE PRODUÇÃO'!$AL$1:$AL$1048566,'[1]ESCALA DE PRODUÇÃO'!$AJ$1:$AJ$1048566,"NÃO ENCOTRADO") -> 008028 - ROTISSERIA ARROZ BRANCO BENDITO KG | C12: 1.2 | D12: =_xlfn.XLOOKUP(A12,'[1]ESCALA DE PRODUÇÃO'!$AL$1:$AL$1048566,'[1]ESCALA DE PRODUÇÃO'!$AK$1:$AK$1048566,"0") -> KG/0001 | E12: ='[2]ESCALA DE PRODUÇÃO'!D11 -> 0.12 | F12: =IFERROR(C12/E12,"0") -> 10 | G12: =_xlfn.XLOOKUP(A12,'[1]ESCALA DE PRODUÇÃO'!$AL$1:$AL$1048566,'[1]ESCALA DE PRODUÇÃO'!$AM$1:$AM$1048566,"SEM PREÇO") -> 28.9 | H12: =IFERROR(C12*G12,"0") -> 34.68 | I12: =_xlfn.XLOOKUP(A12,'DADOS DE VENDA'!A:A,'DADOS DE VENDA'!D:D,"SEM VENDA") -> 2.71 | J12: =IFERROR(I12/E12,"0") -> 22.583333 | K12: =IFERROR(I12*G12,"0") -> 78.319 | L12: =_xlfn.XLOOKUP(A12,'DADOS DE VENDA'!A:A,'DADOS DE VENDA'!E:E,"RUPTURA NO PERIODO") -> 19/01 a20/01 | M12: {=_xlfn.IFS(C12<I12,"ABAIXO",C12>I12,"ACIMA",C12=I12,"OK")} -> ABAIXO | P12: =A12 -> 8028 | Q12: =_xlfn.XLOOKUP(P12,'[1]ESCALA DE PRODUÇÃO'!$AL$1:$AL$1048566,'[1]ESCALA DE PRODUÇÃO'!$AJ$1:$AJ$1048566,"NÃO ENCOTRADO") -> 008028 - ROTISSERIA ARROZ BRANCO BENDITO KG | R12: =C12 -> 1.2 | S12: =(F12) -> 10
A13: =('[1]ESCALA DE PRODUÇÃO'!B12) -> 0 | B13: =_xlfn.XLOOKUP(A13,'[1]ESCALA DE PRODUÇÃO'!$AL$1:$AL$1048566,'[1]ESCALA DE PRODUÇÃO'!$AJ$1:$AJ$1048566,"NÃO ENCOTRADO") -> NÃO ENCOTRADO | C13: 0 | D13: =_xlfn.XLOOKUP(A13,'[1]ESCALA DE PRODUÇÃO'!$AL$1:$AL$1048566,'[1]ESCALA DE PRODUÇÃO'!$AK$1:$AK$1048566,"0") -> 0 | E13: ='[2]ESCALA DE PRODUÇÃO'!D12 -> 0 | F13: =IFERROR(C13/E13,"0") -> 0 | G13: =_xlfn.XLOOKUP(A13,'[1]ESCALA DE PRODUÇÃO'!$AL$1:$AL$1048566,'[1]ESCALA DE PRODUÇÃO'!$AM$1:$AM$1048566,"SEM PREÇO") -> SEM PREÇO | H13: =IFERROR(C13*G13,"0") -> 0 | I13: =_xlfn.XLOOKUP(A13,'DADOS DE VENDA'!A:A,'DADOS DE VENDA'!D:D,"SEM VENDA") -> SEM VENDA | J13: =IFERROR(I13/E13,"0") -> 0 | K13: =IFERROR(I13*G13,"0") -> 0 | L13: =_xlfn.XLOOKUP(A13,'DADOS DE VENDA'!A:A,'DADOS DE VENDA'!E:E,"RUPTURA NO PERIODO") -> RUPTURA NO PERIODO | M13: {=_xlfn.IFS(C13<I13,"ABAIXO",C13>I13,"ACIMA",C13=I13,"OK")} -> ABAIXO | P13: =A13 -> 0 | Q13: =_xlfn.XLOOKUP(P13,'[1]ESCALA DE PRODUÇÃO'!$AL$1:$AL$1048566,'[1]ESCALA DE PRODUÇÃO'!$AJ$1:$AJ$1048566,"NÃO ENCOTRADO") -> NÃO ENCOTRADO | R13: =C13 -> 0 | S13: =(F13) -> 0
A14: COD | B14: MONO FEIJÃO | C14: QTD | D14: KG/UN | E14: P.PADRÃO | F14: Q.PCT | G14: PREÇO | H14: TOTAL | I14: VENDA QTD | J14: EM PCT | K14: EM VALORES | L14: PERIODO BASE | M14: STATUS | P14: COD | Q14: MONO FEIJÃO | R14: QTD | S14: Q.PCT
A15: =('[1]ESCALA DE PRODUÇÃO'!B14) -> 8328 | B15: =_xlfn.XLOOKUP(A15,'[1]ESCALA DE PRODUÇÃO'!$AL$1:$AL$1048566,'[1]ESCALA DE PRODUÇÃO'!$AJ$1:$AJ$1048566,"NÃO ENCOTRADO") -> 008328 - ROTISSERIA FEIJAO BENDITO KG | C15: 1 | D15: =_xlfn.XLOOKUP(A15,'[1]ESCALA DE PRODUÇÃO'!$AL$1:$AL$1048566,'[1]ESCALA DE PRODUÇÃO'!$AK$1:$AK$1048566,"0") -> KG/0001 | E15: ='[2]ESCALA DE PRODUÇÃO'!D14 -> 0.18 | F15: =IFERROR(C15/E15,"0") -> 5.5555556 | G15: =_xlfn.XLOOKUP(A15,'[1]ESCALA DE PRODUÇÃO'!$AL$1:$AL$1048566,'[1]ESCALA DE PRODUÇÃO'!$AM$1:$AM$1048566,"SEM PREÇO") -> 34.9 | H15: =IFERROR(C15*G15,"0") -> 34.9 | I15: =_xlfn.XLOOKUP(A15,'DADOS DE VENDA'!A:A,'DADOS DE VENDA'!D:D,"SEM VENDA") -> 0.75 | J15: =IFERROR(I15/E15,"0") -> 4.1666667 | K15: =IFERROR(I15*G15,"0") -> 26.175 | L15: =_xlfn.XLOOKUP(A15,'DADOS DE VENDA'!A:A,'DADOS DE VENDA'!E:E,"RUPTURA NO PERIODO") -> 19/01 a20/01 | M15: {=_xlfn.IFS(C15<I15,"ABAIXO",C15>I15,"ACIMA",C15=I15,"OK")} -> ACIMA | P15: =A15 -> 8328 | Q15: =_xlfn.XLOOKUP(P15,'[1]ESCALA DE PRODUÇÃO'!$AL$1:$AL$1048566,'[1]ESCALA DE PRODUÇÃO'!$AJ$1:$AJ$1048566,"NÃO ENCOTRADO") -> 008328 - ROTISSERIA FEIJAO BENDITO KG | R15: =C15 -> 1 | S15: =(F15) -> 5.5555556
A16: =('[1]ESCALA DE PRODUÇÃO'!B15) -> 10 | B16: =_xlfn.XLOOKUP(A16,'[1]ESCALA DE PRODUÇÃO'!$AL$1:$AL$1048566,'[1]ESCALA DE PRODUÇÃO'!$AJ$1:$AJ$1048566,"NÃO ENCOTRADO") -> NÃO ENCOTRADO | C16: 0 | D16: =_xlfn.XLOOKUP(A16,'[1]ESCALA DE PRODUÇÃO'!$AL$1:$AL$1048566,'[1]ESCALA DE PRODUÇÃO'!$AK$1:$AK$1048566,"0") -> 0 | E16: ='[2]ESCALA DE PRODUÇÃO'!D15 -> 0 | F16: =IFERROR(C16/E16,"0") -> 0 | G16: =_xlfn.XLOOKUP(A16,'[1]ESCALA DE PRODUÇÃO'!$AL$1:$AL$1048566,'[1]ESCALA DE PRODUÇÃO'!$AM$1:$AM$1048566,"SEM PREÇO") -> SEM PREÇO | H16: =IFERROR(C16*G16,"0") -> 0 | I16: =_xlfn.XLOOKUP(A16,'DADOS DE VENDA'!A:A,'DADOS DE VENDA'!D:D,"SEM VENDA") -> SEM VENDA | J16: =IFERROR(I16/E16,"0") -> 0 | K16: =IFERROR(I16*G16,"0") -> 0 | L16: =_xlfn.XLOOKUP(A16,'DADOS DE VENDA'!A:A,'DADOS DE VENDA'!E:E,"RUPTURA NO PERIODO") -> RUPTURA NO PERIODO | M16: {=_xlfn.IFS(C16<I16,"ABAIXO",C16>I16,"ACIMA",C16=I16,"OK")} -> ABAIXO | P16: =A16 -> 10 | Q16: =_xlfn.XLOOKUP(P16,'[1]ESCALA DE PRODUÇÃO'!$AL$1:$AL$1048566,'[1]ESCALA DE PRODUÇÃO'!$AJ$1:$AJ$1048566,"NÃO ENCOTRADO") -> NÃO ENCOTRADO | R16: =C16 -> 0 | S16: =(F16) -> 0
A17: COD | B17: MONO GUARNIÇÃO | C17: QTD | D17: KG/UN | E17: P.PADRÃO | F17: Q.PCT | G17: PREÇO | H17: TOTAL | I17: VENDA QTD | J17: EM PCT | K17: EM VALORES | L17: PERIODO BASE | M17: STATUS | P17: COD | Q17: MONO GUARNIÇÃO | R17: QTD | S17: Q.PCT
A18: =('[1]ESCALA DE PRODUÇÃO'!B17) -> 8089 | B18: =_xlfn.XLOOKUP(A18,'[1]ESCALA DE PRODUÇÃO'!$AL$1:$AL$1048566,'[1]ESCALA DE PRODUÇÃO'!$AJ$1:$AJ$1048566,"NÃO ENCOTRADO") -> 008089 - ROTISSERIA BATATA ASSADA BENDITO KG | C18: 1 | D18: =_xlfn.XLOOKUP(A18,'[1]ESCALA DE PRODUÇÃO'!$AL$1:$AL$1048566,'[1]ESCALA DE PRODUÇÃO'!$AK$1:$AK$1048566,"0") -> KG/0001 | E18: ='[2]ESCALA DE PRODUÇÃO'!D17 -> 0.12 | F18: =IFERROR(C18/E18,"0") -> 8.3333333 | G18: =_xlfn.XLOOKUP(A18,'[1]ESCALA DE PRODUÇÃO'!$AL$1:$AL$1048566,'[1]ESCALA DE PRODUÇÃO'!$AM$1:$AM$1048566,"SEM PREÇO") -> 49.9 | H18: =IFERROR(C18*G18,"0") -> 49.9 | I18: =_xlfn.XLOOKUP(A18,'DADOS DE VENDA'!A:A,'DADOS DE VENDA'!D:D,"SEM VENDA") -> 1.36 | J18: =IFERROR(I18/E18,"0") -> 11.333333 | K18: =IFERROR(I18*G18,"0") -> 67.864 | L18: =_xlfn.XLOOKUP(A18,'DADOS DE VENDA'!A:A,'DADOS DE VENDA'!E:E,"RUPTURA NO PERIODO") -> 19/01 a20/01 | M18: {=_xlfn.IFS(C18<I18,"ABAIXO",C18>I18,"ACIMA",C18=I18,"OK")} -> ABAIXO | P18: =A18 -> 8089 | Q18: =_xlfn.XLOOKUP(P18,'[1]ESCALA DE PRODUÇÃO'!$AL$1:$AL$1048566,'[1]ESCALA DE PRODUÇÃO'!$AJ$1:$AJ$1048566,"NÃO ENCOTRADO") -> 008089 - ROTISSERIA BATATA ASSADA BENDITO KG | R18: =C18 -> 1 | S18: =(F18) -> 8.3333333
A19: =('[1]ESCALA DE PRODUÇÃO'!B18) -> 8598 | B19: =_xlfn.XLOOKUP(A19,'[1]ESCALA DE PRODUÇÃO'!$AL$1:$AL$1048566,'[1]ESCALA DE PRODUÇÃO'!$AJ$1:$AJ$1048566,"NÃO ENCOTRADO") -> 008598 - ROTISSERIA PURE DE BATATA BENDITO KG | C19: 1 | D19: =_xlfn.XLOOKUP(A19,'[1]ESCALA DE PRODUÇÃO'!$AL$1:$AL$1048566,'[1]ESCALA DE PRODUÇÃO'!$AK$1:$AK$1048566,"0") -> KG/0001 | E19: ='[2]ESCALA DE PRODUÇÃO'!D18 -> 0.15 | F19: =IFERROR(C19/E19,"0") -> 6.6666667 | G19: =_xlfn.XLOOKUP(A19,'[1]ESCALA DE PRODUÇÃO'!$AL$1:$AL$1048566,'[1]ESCALA DE PRODUÇÃO'!$AM$1:$AM$1048566,"SEM PREÇO") -> 48.9 | H19: =IFERROR(C19*G19,"0") -> 48.9 | I19: =_xlfn.XLOOKUP(A19,'DADOS DE VENDA'!A:A,'DADOS DE VENDA'!D:D,"SEM VENDA") -> SEM VENDA | J19: =IFERROR(I19/E19,"0") -> 0 | K19: =IFERROR(I19*G19,"0") -> 0 | L19: =_xlfn.XLOOKUP(A19,'DADOS DE VENDA'!A:A,'DADOS DE VENDA'!E:E,"RUPTURA NO PERIODO") -> RUPTURA NO PERIODO | M19: {=_xlfn.IFS(C19<I19,"ABAIXO",C19>I19,"ACIMA",C19=I19,"OK")} -> ABAIXO | P19: =A19 -> 8598 | Q19: =_xlfn.XLOOKUP(P19,'[1]ESCALA DE PRODUÇÃO'!$AL$1:$AL$1048566,'[1]ESCALA DE PRODUÇÃO'!$AJ$1:$AJ$1048566,"NÃO ENCOTRADO") -> 008598 - ROTISSERIA PURE DE BATATA BENDITO KG | R19: =C19 -> 1 | S19: =(F19) -> 6.6666667
A20: =('[1]ESCALA DE PRODUÇÃO'!B19) -> 8403 | B20: =_xlfn.XLOOKUP(A20,'[1]ESCALA DE PRODUÇÃO'!$AL$1:$AL$1048566,'[1]ESCALA DE PRODUÇÃO'!$AJ$1:$AJ$1048566,"NÃO ENCOTRADO") -> 008403 - ROTISSERIA LEGUMES BENDITO KG | C20: 1 | D20: =_xlfn.XLOOKUP(A20,'[1]ESCALA DE PRODUÇÃO'!$AL$1:$AL$1048566,'[1]ESCALA DE PRODUÇÃO'!$AK$1:$AK$1048566,"0") -> KG/0001 | E20: ='[2]ESCALA DE PRODUÇÃO'!D19 -> 0.12 | F20: =IFERROR(C20/E20,"0") -> 8.3333333 | G20: =_xlfn.XLOOKUP(A20,'[1]ESCALA DE PRODUÇÃO'!$AL$1:$AL$1048566,'[1]ESCALA DE PRODUÇÃO'!$AM$1:$AM$1048566,"SEM PREÇO") -> 14.9 | H20: =IFERROR(C20*G20,"0") -> 14.9 | I20: =_xlfn.XLOOKUP(A20,'DADOS DE VENDA'!A:A,'DADOS DE VENDA'!D:D,"SEM VENDA") -> 0.25 | J20: =IFERROR(I20/E20,"0") -> 2.0833333 | K20: =IFERROR(I20*G20,"0") -> 3.725 | L20: =_xlfn.XLOOKUP(A20,'DADOS DE VENDA'!A:A,'DADOS DE VENDA'!E:E,"RUPTURA NO PERIODO") -> 19/01 a20/01 | M20: {=_xlfn.IFS(C20<I20,"ABAIXO",C20>I20,"ACIMA",C20=I20,"OK")} -> ACIMA | P20: =A20 -> 8403 | Q20: =_xlfn.XLOOKUP(P20,'[1]ESCALA DE PRODUÇÃO'!$AL$1:$AL$1048566,'[1]ESCALA DE PRODUÇÃO'!$AJ$1:$AJ$1048566,"NÃO ENCOTRADO") -> 008403 - ROTISSERIA LEGUMES BENDITO KG | R20: =C20 -> 1 | S20: =(F20) -> 8.3333333
A21: COD | B21: MONO PROTEINAS | C21: QTD | D21: KG/UN | E21: P.PADRÃO | F21: Q.PCT | G21: PREÇO | H21: TOTAL | I21: VENDA QTD | J21: EM PCT | K21: EM VALORES | L21: PERIODO BASE | M21: STATUS | P21: COD | Q21: MONO PROTEINAS | R21: QTD | S21: Q.PCT
A22: =('[1]ESCALA DE PRODUÇÃO'!B21) -> 8409 | B22: =_xlfn.XLOOKUP(A22,'[1]ESCALA DE PRODUÇÃO'!$AL$1:$AL$1048566,'[1]ESCALA DE PRODUÇÃO'!$AJ$1:$AJ$1048566,"NÃO ENCOTRADO") -> 008409 - ROTISSERIA LINGUICA ASSADA BENDITO KG | C22: 1 | D22: =_xlfn.XLOOKUP(A22,'[1]ESCALA DE PRODUÇÃO'!$AL$1:$AL$1048566,'[1]ESCALA DE PRODUÇÃO'!$AK$1:$AK$1048566,"0") -> KG/0001 | E22: ='[2]ESCALA DE PRODUÇÃO'!D21 -> 0.15 | F22: =IFERROR(C22/E22,"0") -> 6.6666667 | G22: =_xlfn.XLOOKUP(A22,'[1]ESCALA DE PRODUÇÃO'!$AL$1:$AL$1048566,'[1]ESCALA DE PRODUÇÃO'!$AM$1:$AM$1048566,"SEM PREÇO") -> 59.9 | H22: =IFERROR(C22*G22,"0") -> 59.9 | I22: =_xlfn.XLOOKUP(A22,'DADOS DE VENDA'!A:A,'DADOS DE VENDA'!D:D,"SEM VENDA") -> 0.42 | J22: =IFERROR(I22/E22,"0") -> 2.8 | K22: =IFERROR(I22*G22,"0") -> 25.158 | L22: =_xlfn.XLOOKUP(A22,'DADOS DE VENDA'!A:A,'DADOS DE VENDA'!E:E,"RUPTURA NO PERIODO") -> 19/01 a20/01 | M22: {=_xlfn.IFS(C22<I22,"ABAIXO",C22>I22,"ACIMA",C22=I22,"OK")} -> ACIMA | P22: =A22 -> 8409 | Q22: =_xlfn.XLOOKUP(P22,'[1]ESCALA DE PRODUÇÃO'!$AL$1:$AL$1048566,'[1]ESCALA DE PRODUÇÃO'!$AJ$1:$AJ$1048566,"NÃO ENCOTRADO") -> 008409 - ROTISSERIA LINGUICA ASSADA BENDITO KG | R22: =C22 -> 1 | S22: =(F22) -> 6.6666667
A23: =('[1]ESCALA DE PRODUÇÃO'!B22) -> 8945 | B23: =_xlfn.XLOOKUP(A23,'[1]ESCALA DE PRODUÇÃO'!$AL$1:$AL$1048566,'[1]ESCALA DE PRODUÇÃO'!$AJ$1:$AJ$1048566,"NÃO ENCOTRADO") -> 008945 - ROT.ISCA DE FRANGO A MILANESA BENDITO KG | C23: 1 | D23: =_xlfn.XLOOKUP(A23,'[1]ESCALA DE PRODUÇÃO'!$AL$1:$AL$1048566,'[1]ESCALA DE PRODUÇÃO'!$AK$1:$AK$1048566,"0") -> KG/0001 | E23: ='[2]ESCALA DE PRODUÇÃO'!D22 -> 0.18 | F23: =IFERROR(C23/E23,"0") -> 5.5555556 | G23: =_xlfn.XLOOKUP(A23,'[1]ESCALA DE PRODUÇÃO'!$AL$1:$AL$1048566,'[1]ESCALA DE PRODUÇÃO'!$AM$1:$AM$1048566,"SEM PREÇO") -> 64.9 | H23: =IFERROR(C23*G23,"0") -> 64.9 | I23: =_xlfn.XLOOKUP(A23,'DADOS DE VENDA'!A:A,'DADOS DE VENDA'!D:D,"SEM VENDA") -> 0.87 | J23: =IFERROR(I23/E23,"0") -> 4.8333333 | K23: =IFERROR(I23*G23,"0") -> 56.463 | L23: =_xlfn.XLOOKUP(A23,'DADOS DE VENDA'!A:A,'DADOS DE VENDA'!E:E,"RUPTURA NO PERIODO") -> 19/01 a20/01 | M23: {=_xlfn.IFS(C23<I23,"ABAIXO",C23>I23,"ACIMA",C23=I23,"OK")} -> ACIMA | P23: =A23 -> 8945 | Q23: =_xlfn.XLOOKUP(P23,'[1]ESCALA DE PRODUÇÃO'!$AL$1:$AL$1048566,'[1]ESCALA DE PRODUÇÃO'!$AJ$1:$AJ$1048566,"NÃO ENCOTRADO") -> 008945 - ROT.ISCA DE FRANGO A MILANESA BENDITO KG | R23: =C23 -> 1 | S23: =(F23) -> 5.5555556
A24: =('[1]ESCALA DE PRODUÇÃO'!B23) -> 8396 | B24: =_xlfn.XLOOKUP(A24,'[1]ESCALA DE PRODUÇÃO'!$AL$1:$AL$1048566,'[1]ESCALA DE PRODUÇÃO'!$AJ$1:$AJ$1048566,"NÃO ENCOTRADO") -> 008396 - ROTISSERIA LAGARTO AO MOLHO MADEIRA BENDITO KG | C24: 0 | D24: =_xlfn.XLOOKUP(A24,'[1]ESCALA DE PRODUÇÃO'!$AL$1:$AL$1048566,'[1]ESCALA DE PRODUÇÃO'!$AK$1:$AK$1048566,"0") -> KG/0001 | E24: ='[2]ESCALA DE PRODUÇÃO'!D23 -> 0 | F24: =IFERROR(C24/E24,"0") -> 0 | G24: =_xlfn.XLOOKUP(A24,'[1]ESCALA DE PRODUÇÃO'!$AL$1:$AL$1048566,'[1]ESCALA DE PRODUÇÃO'!$AM$1:$AM$1048566,"SEM PREÇO") -> 94.9 | H24: =IFERROR(C24*G24,"0") -> 0 | I24: =_xlfn.XLOOKUP(A24,'DADOS DE VENDA'!A:A,'DADOS DE VENDA'!D:D,"SEM VENDA") -> SEM VENDA | J24: =IFERROR(I24/E24,"0") -> 0 | K24: =IFERROR(I24*G24,"0") -> 0 | L24: =_xlfn.XLOOKUP(A24,'DADOS DE VENDA'!A:A,'DADOS DE VENDA'!E:E,"RUPTURA NO PERIODO") -> RUPTURA NO PERIODO | M24: {=_xlfn.IFS(C24<I24,"ABAIXO",C24>I24,"ACIMA",C24=I24,"OK")} -> ABAIXO | P24: =A24 -> 8396 | Q24: =_xlfn.XLOOKUP(P24,'[1]ESCALA DE PRODUÇÃO'!$AL$1:$AL$1048566,'[1]ESCALA DE PRODUÇÃO'!$AJ$1:$AJ$1048566,"NÃO ENCOTRADO") -> 008396 - ROTISSERIA LAGARTO AO MOLHO MADEIRA BENDITO KG | R24: =C24 -> 0 | S24: =(F24) -> 0
A25: COD | B25: SALADAS COZIDAS | C25: QTD | D25: KG/UN | E25: P.PADRÃO | F25: Q.PCT | G25: PREÇO | H25: TOTAL | I25: VENDA QTD | J25: EM PCT | K25: EM VALORES | L25: PERIODO BASE | M25: STATUS | P25: COD | Q25: SALADAS COZIDAS | R25: QTD | S25: Q.PCT
A26: =('[1]ESCALA DE PRODUÇÃO'!B25) -> 0 | B26: =_xlfn.XLOOKUP(A26,'[1]ESCALA DE PRODUÇÃO'!$AL$1:$AL$1048566,'[1]ESCALA DE PRODUÇÃO'!$AJ$1:$AJ$1048566,"NÃO ENCOTRADO") -> NÃO ENCOTRADO | C26: 3.5 | D26: =_xlfn.XLOOKUP(A26,'[1]ESCALA DE PRODUÇÃO'!$AL$1:$AL$1048566,'[1]ESCALA DE PRODUÇÃO'!$AK$1:$AK$1048566,"0") -> 0 | E26: ='[2]ESCALA DE PRODUÇÃO'!D25 -> 0.35 | F26: =IFERROR(C26/E26,"0") -> 10 | G26: =_xlfn.XLOOKUP(A26,'[1]ESCALA DE PRODUÇÃO'!$AL$1:$AL$1048566,'[1]ESCALA DE PRODUÇÃO'!$AM$1:$AM$1048566,"SEM PREÇO") -> SEM PREÇO | H26: =IFERROR(C26*G26,"0") -> 0 | I26: =_xlfn.XLOOKUP(A26,'DADOS DE VENDA'!A:A,'DADOS DE VENDA'!D:D,"SEM VENDA") -> SEM VENDA | J26: =IFERROR(I26/E26,"0") -> 0 | K26: =IFERROR(I26*G26,"0") -> 0 | L26: =_xlfn.XLOOKUP(A26,'DADOS DE VENDA'!A:A,'DADOS DE VENDA'!E:E,"RUPTURA NO PERIODO") -> RUPTURA NO PERIODO | M26: {=_xlfn.IFS(C26<I26,"ABAIXO",C26>I26,"ACIMA",C26=I26,"OK")} -> ABAIXO | P26: =A26 -> 0 | Q26: =_xlfn.XLOOKUP(P26,'[1]ESCALA DE PRODUÇÃO'!$AL$1:$AL$1048566,'[1]ESCALA DE PRODUÇÃO'!$AJ$1:$AJ$1048566,"NÃO ENCOTRADO") -> NÃO ENCOTRADO | R26: =C26 -> 3.5 | S26: =(F26) -> 10
A27: =('[1]ESCALA DE PRODUÇÃO'!B26) -> 8221 | B27: =_xlfn.XLOOKUP(A27,'[1]ESCALA DE PRODUÇÃO'!$AL$1:$AL$1048566,'[1]ESCALA DE PRODUÇÃO'!$AJ$1:$AJ$1048566,"NÃO ENCOTRADO") -> 008221 - ROTISSERIA CAPONATA BERINJELA BENDITO KG | C27: 2 | D27: =_xlfn.XLOOKUP(A27,'[1]ESCALA DE PRODUÇÃO'!$AL$1:$AL$1048566,'[1]ESCALA DE PRODUÇÃO'!$AK$1:$AK$1048566,"0") -> KG/0001 | E27: ='[2]ESCALA DE PRODUÇÃO'!D26 -> 0.25 | F27: =IFERROR(C27/E27,"0") -> 8 | G27: =_xlfn.XLOOKUP(A27,'[1]ESCALA DE PRODUÇÃO'!$AL$1:$AL$1048566,'[1]ESCALA DE PRODUÇÃO'!$AM$1:$AM$1048566,"SEM PREÇO") -> 39.9 | H27: =IFERROR(C27*G27,"0") -> 79.8 | I27: =_xlfn.XLOOKUP(A27,'DADOS DE VENDA'!A:A,'DADOS DE VENDA'!D:D,"SEM VENDA") -> 0.27 | J27: =IFERROR(I27/E27,"0") -> 1.08 | K27: =IFERROR(I27*G27,"0") -> 10.773 | L27: =_xlfn.XLOOKUP(A27,'DADOS DE VENDA'!A:A,'DADOS DE VENDA'!E:E,"RUPTURA NO PERIODO") -> 19/01 a20/01 | M27: {=_xlfn.IFS(C27<I27,"ABAIXO",C27>I27,"ACIMA",C27=I27,"OK")} -> ACIMA | P27: =A27 -> 8221 | Q27: =_xlfn.XLOOKUP(P27,'[1]ESCALA DE PRODUÇÃO'!$AL$1:$AL$1048566,'[1]ESCALA DE PRODUÇÃO'!$AJ$1:$AJ$1048566,"NÃO ENCOTRADO") -> 008221 - ROTISSERIA CAPONATA BERINJELA BENDITO KG | R27: =C27 -> 2 | S27: =(F27) -> 8
B28: VALORES | C28: META | F28: PEDIDO | G28: =SUM(H4+H5+H6+H8+H9+H10+H12+H13+H15+H16+H18+H19+H20+H22+H24+H26+H27) -> 1058.28 | I28: ULT.VENDA | J28: =SUM(K4+K5+K6+K8+K9+K10+K12+K13+K15+K16+K18+K19+K20+K22+K24+K26+K27) -> 794.497 | P28: TOTAL | R28: =G28 -> 1058.28
A31: SEGUNDA (LOJA 1 DESCONTÃO-ROTISSERIA) | I31: SUJESTÃO DE PEDIDO | P31: =P1 | R31: DATA | S31: =S1 -> 46048
A32: SALADAS C/PROTEINAS | C32: pedido | D32: INFORMAÇÕES DO PEDIDO | I32: INFORMAÇÕES SUGESTÃO DE PEDIDO | P32: SALADAS C/PROTEINAS | R32: INFORMAÇÕES DO PEDIDO
A33: COD | B33: SALADAS PROTEICAS | C33: QTD | D33: KG/UN | E33: P.PADRÃO | F33: Q.PCT | G33: PREÇO | H33: TOTAL | I33: VENDA QTD | J33: EM PCT | K33: EM VALORES | L33: PERIODO BASE | M33: STATUS | P33: COD | Q33: SALADAS PROTEICAS | R33: QTD | S33: Q.PCT
A34: ='[2]ESCALA DE PRODUÇÃO'!B28 -> 8963 | B34: =_xlfn.XLOOKUP(A34,'[1]ESCALA DE PRODUÇÃO'!$AL$1:$AL$1048566,'[1]ESCALA DE PRODUÇÃO'!$AJ$1:$AJ$1048566,"NÃO ENCOTRADO") -> 008963 - ROTISSERIA SALADA CEASER C/FRANGO BENDITO | C34: 4 | D34: =_xlfn.XLOOKUP(A34,'[1]ESCALA DE PRODUÇÃO'!$AL$1:$AL$1048566,'[1]ESCALA DE PRODUÇÃO'!$AK$1:$AK$1048566,"0") -> UN/0001 | E34: =('[2]ESCALA DE PRODUÇÃO'!D28) -> 1 | F34: =IFERROR(C34/E34,"0") -> 4 | G34: =_xlfn.XLOOKUP(A34,'[1]ESCALA DE PRODUÇÃO'!$AL$1:$AL$1048566,'[1]ESCALA DE PRODUÇÃO'!$AM$1:$AM$1048566,"SEM PREÇO") -> 24.9 | H34: =IFERROR(C34*G34,"0") -> 99.6 | I34: =_xlfn.XLOOKUP(A34,'DADOS DE VENDA'!A:A,'DADOS DE VENDA'!D:D,"SEM VENDA") -> 5 | J34: =IFERROR(I34/E34,"0") -> 5 | K34: =IFERROR(I34*G34,"0") -> 124.5 | L34: =_xlfn.XLOOKUP(A34,'DADOS DE VENDA'!A:A,'DADOS DE VENDA'!E:E,"RUPTURA NO PERIODO") -> 19/01 a20/01 | M34: {=_xlfn.IFS(C34<I34,"ABAIXO",C34>I34,"ACIMA",C34=I34,"OK")} -> ABAIXO | P34: =A34 -> 8963 | Q34: =_xlfn.XLOOKUP(P34,'[1]ESCALA DE PRODUÇÃO'!$AL$1:$AL$1048566,'[1]ESCALA DE PRODUÇÃO'!$AJ$1:$AJ$1048566,"NÃO ENCOTRADO") -> 008963 - ROTISSERIA SALADA CEASER C/FRANGO BENDITO | R34: =C34 -> 4 | S34: =F34 -> 4
A35: ='[2]ESCALA DE PRODUÇÃO'!B29 -> 8962 | B35: =_xlfn.XLOOKUP(A35,'[1]ESCALA DE PRODUÇÃO'!$AL$1:$AL$1048566,'[1]ESCALA DE PRODUÇÃO'!$AJ$1:$AJ$1048566,"NÃO ENCOTRADO") -> 008962 - ROTISSERIA SALADA MIX DE FOLHA E LEGUMES C/PROTEINAS BENDITO | C35: 0 | D35: =_xlfn.XLOOKUP(A35,'[1]ESCALA DE PRODUÇÃO'!$AL$1:$AL$1048566,'[1]ESCALA DE PRODUÇÃO'!$AK$1:$AK$1048566,"0") -> UN/0001 | E35: =('[2]ESCALA DE PRODUÇÃO'!D29) -> 1 | F35: =IFERROR(C35/E35,"0") -> 0 | G35: =_xlfn.XLOOKUP(A35,'[1]ESCALA DE PRODUÇÃO'!$AL$1:$AL$1048566,'[1]ESCALA DE PRODUÇÃO'!$AM$1:$AM$1048566,"SEM PREÇO") -> 21.9 | H35: =IFERROR(C35*G35,"0") -> 0 | I35: =_xlfn.XLOOKUP(A35,'DADOS DE VENDA'!A:A,'DADOS DE VENDA'!D:D,"SEM VENDA") -> SEM VENDA | J35: =IFERROR(I35/E35,"0") -> 0 | K35: =IFERROR(I35*G35,"0") -> 0 | L35: =_xlfn.XLOOKUP(A35,'DADOS DE VENDA'!A:A,'DADOS DE VENDA'!E:E,"RUPTURA NO PERIODO") -> RUPTURA NO PERIODO | M35: {=_xlfn.IFS(C35<I35,"ABAIXO",C35>I35,"ACIMA",C35=I35,"OK")} -> ABAIXO | P35: =A35 -> 8962 | Q35: =_xlfn.XLOOKUP(P35,'[1]ESCALA DE PRODUÇÃO'!$AL$1:$AL$1048566,'[1]ESCALA DE PRODUÇÃO'!$AJ$1:$AJ$1048566,"NÃO ENCOTRADO") -> 008962 - ROTISSERIA SALADA MIX DE FOLHA E LEGUMES C/PROTEINAS BENDITO | R35: =C35 -> 0 | S35: =F35 -> 0
A36: ='[2]ESCALA DE PRODUÇÃO'!B30 -> 30 | B36: =_xlfn.XLOOKUP(A36,'[1]ESCALA DE PRODUÇÃO'!$AL$1:$AL$1048566,'[1]ESCALA DE PRODUÇÃO'!$AJ$1:$AJ$1048566,"NÃO ENCOTRADO") -> NÃO ENCOTRADO | C36: 0 | D36: =_xlfn.XLOOKUP(A36,'[1]ESCALA DE PRODUÇÃO'!$AL$1:$AL$1048566,'[1]ESCALA DE PRODUÇÃO'!$AK$1:$AK$1048566,"0") -> 0 | E36: =('[2]ESCALA DE PRODUÇÃO'!D30) -> 0 | F36: =IFERROR(C36/E36,"0") -> 0 | G36: =_xlfn.XLOOKUP(A36,'[1]ESCALA DE PRODUÇÃO'!$AL$1:$AL$1048566,'[1]ESCALA DE PRODUÇÃO'!$AM$1:$AM$1048566,"SEM PREÇO") -> SEM PREÇO | H36: =IFERROR(C36*G36,"0") -> 0 | I36: =_xlfn.XLOOKUP(A36,'DADOS DE VENDA'!A:A,'DADOS DE VENDA'!D:D,"SEM VENDA") -> SEM VENDA | J36: =IFERROR(I36/E36,"0") -> 0 | K36: =IFERROR(I36*G36,"0") -> 0 | L36: =_xlfn.XLOOKUP(A36,'DADOS DE VENDA'!A:A,'DADOS DE VENDA'!E:E,"RUPTURA NO PERIODO") -> RUPTURA NO PERIODO | M36: {=_xlfn.IFS(C36<I36,"ABAIXO",C36>I36,"ACIMA",C36=I36,"OK")} -> ABAIXO | P36: =A36 -> 30 | Q36: =_xlfn.XLOOKUP(P36,'[1]ESCALA DE PRODUÇÃO'!$AL$1:$AL$1048566,'[1]ESCALA DE PRODUÇÃO'!$AJ$1:$AJ$1048566,"NÃO ENCOTRADO") -> NÃO ENCOTRADO | R36: =C36 -> 0 | S36: =F36 -> 0
A37: COD | B37: SUSHI | C37: QTD | D37: KG/UN | E37: P.PADRÃO | F37: Q.PCT | G37: PREÇO | H37: TOTAL | I37: VENDA QTD | J37: EM PCT | K37: EM VALORES | L37: PERIODO BASE | M37: STATUS | P37: COD | Q37: SUSHI | R37: QTD | S37: Q.PCT
