Workbook

Sheet DADOS DE VENDA
B1: SEGUNDA | H1: TERÇA | N1: QUARTA | T1: QUINTA | Z1: SEXTA | AF1: SABADO | AL1: DOMINGO | AQ1: MEDIA DO PERIODO 03/11 A 10/11
A2: Produto | B2: Descrição | C2: Código de Barras | D2: Quantidade | E2: DATA | G2: Produto | H2: Descrição | I2: Código de Barras | J2: Quantidade | K2: DATA | M2: Produto | N2: Descrição | O2: Código de Barras | P2: Quantidade | Q2: DATA | S2: Produto | T2: Descrição | U2: Código de Barras | V2: Quantidade | W2: DATA | Y2: Produto | Z2: Descrição | AA2: Código de Barras | AB2: Quantidade | AC2: DATA | AE2: Produto | AF2: Descrição | AG2: Código de Barras | AH2: Quantidade | AI2: DATA | AK2: Produto | AL2: Descrição | AM2: Código de Barras | AN2: Quantidade | AO2: DATA | AQ2: Produto | AR2: Descrição | AS2: Código de Barras | AT2: Quantidade | AU2: Venda Líquida | AV2: MEDIA QTD | AW2: MEDIA VALOR | AZ2: =SUMIF(AR:AR,AY2,AT:AT) -> 0
A3: 8966 | B3: REFEICAO ISCA DE FRANGO A MILANESA BENDITO | C3: 8966 | D3: 12 | E3: 19/01 a20/01 | G3: 7574 | H3: PATE DE AZEITONA PRETA BENDITO KG | I3: 7574 | J3: 0.19 | K3: 20/01 a 21/01 | M3: 9350 | N3: COMBO SUSHI KANI/HOTHOLL/CALIFORNIA BENDITO UN | O3: 9350 | P3: 1 | Q3: 21/01 a 22/01 | S3: 102365 | T3: PADARIA TABUA DE FRIOS KG | U3: 102365 | V3: 0.29 | W3: 15/01 a16/01 | Y3: 2893 | Z3: ASS.FRANGO METADE BENDITO UNIDADE | AA3: 2893 | AB3: 10 | AC3: 16/01 a 17/01 | AE3: 93583 | AF3: ASS.FRANGO BENDITO INTEIRO | AG3: 93583 | AH3: 8 | AI3: 17/01 a 18/01 | AK3: 7041 | AL3: BOLO BANANA BENDITO KG | AM3: 7041 | AN3: 0.95 | AO3: 20/10 A 23/10 | AQ3: 7068 | AR3: BOLO CENOURA COBERTURA CHOCOLATE BENDITO KG | AS3: 7068 | AT3: 20.51 | AU3: 1023.49 | AV3: =(AT3/7) -> 2.93 | AW3: =(AU3/7) -> 146.21286
A4: 7768 | B4: REFEICAO LAGARTO M.MADEIRA + BATATA ASSADA BENDITO | C4: 7768 | D4: 10 | E4: =(E3) -> 19/01 a20/01 | G4: 7575 | H4: PATE DE AZEITONA VERDE BENDITO KG | I4: 7575 | J4: 0.2 | K4: =(K3) -> 20/01 a 21/01 | M4: 7930 | N4: REF COPA LOMBO ACEBOLADA BENDITO | O4: 7930 | P4: 10 | Q4: =(Q3) -> 21/01 a 22/01 | S4: 7574 | T4: PATE DE AZEITONA PRETA BENDITO KG | U4: 7574 | V4: 0.19 | W4: =(W3) -> 15/01 a16/01 | Y4: 7574 | Z4: PATE DE AZEITONA PRETA BENDITO KG | AA4: 7574 | AB4: 0.35 | AC4: =(AC3) -> 16/01 a 17/01 | AE4: 2893 | AF4: ASS.FRANGO METADE BENDITO UNIDADE | AG4: 2893 | AH4: 27 | AI4: =(AI3) -> 17/01 a 18/01 | AK4: 7068 | AL4: BOLO CENOURA COBERTURA CHOCOLATE BENDITO KG | AM4: 7068 | AN4: 10.31 | AO4: =(AO3) -> 20/10 A 23/10 | AQ4: 7569 | AR4: PAO CASEIRAO BENDITO 250GR | AS4: 7569 | AT4: 69 | AU4: 959.1 | AV4: =(AT4/7) -> 9.8571429 | AW4: =(AU4/7) -> 137.01429
A5: 7875 | B5: REFEICAO STROGONOFF FRANGO BENDITO UN | C5: 7875 | D5: 7 | E5: =(E4) -> 19/01 a20/01 | G5: 7930 | H5: REF COPA LOMBO ACEBOLADA BENDITO | I5: 7930 | J5: 11 | K5: =(K4) -> 20/01 a 21/01 | M5: 7625 | N5: REFEICAO CARNE PANELA BENDITO UN | O5: 7625 | P5: 7 | Q5: =(Q4) -> 21/01 a 22/01 | S5: 7575 | T5: PATE DE AZEITONA VERDE BENDITO KG | U5: 7575 | V5: 0.22 | W5: =(W4) -> 15/01 a16/01 | Y5: 7575 | Z5: PATE DE AZEITONA VERDE BENDITO KG | AA5: 7575 | AB5: 0.22 | AC5: =(AC4) -> 16/01 a 17/01 | AE5: 7574 | AF5: PATE DE AZEITONA PRETA BENDITO KG | AG5: 7574 | AH5: 0.16 | AI5: =(AI4) -> 17/01 a 18/01 | AK5: 6856 | AL5: BOLO COCO BENDITO KG | AM5: 6856 | AN5: 0.55 | AO5: =(AO4) -> 20/10 A 23/10 | AQ5: 6856 | AR5: BOLO COCO BENDITO KG | AS5: 6856 | AT5: 17.21 | AU5: 674.56 | AV5: =(AT5/7) -> 2.4585714 | AW5: =(AU5/7) -> 96.365714
A6: 7877 | B6: REFEICAO TIRINHA CARNE CHINESA BENDITO UN | C6: 7877 | D6: 14 | E6: =(E5) -> 19/01 a20/01 | G6: 7673 | H6: REFEICAO FILE FRANGO PARMEGIANA BENDITO UN | I6: 7673 | J6: 17 | K6: =(K5) -> 20/01 a 21/01 | M6: 7673 | N6: REFEICAO FILE FRANGO PARMEGIANA BENDITO UN | O6: 7673 | P6: 14 | Q6: =(Q5) -> 21/01 a 22/01 | S6: 7625 | T6: REFEICAO CARNE PANELA BENDITO UN | U6: 7625 | V6: 15 | W6: =(W5) -> 15/01 a16/01 | Y6: 7660 | Z6: REFEICAO FEIJOADA BENDITO UN | AA6: 7660 | AB6: 12 | AC6: =(AC5) -> 16/01 a 17/01 | AE6: 7660 | AF6: REFEICAO FEIJOADA BENDITO UN | AG6: 7660 | AH6: 12 | AI6: =(AI5) -> 17/01 a 18/01 | AK6: 6856 | AL6: BOLO COCO BENDITO KG | AM6: 6856 | AN6: 5.04 | AO6: =(AO5) -> 20/10 A 23/10 | AQ6: 6966 | AR6: PAO HAMBURGUER BENDITO KG | AS6: 6966 | AT6: 14.64 | AU6: 476.25 | AV6: =(AT6/7) -> 2.0914286 | AW6: =(AU6/7) -> 68.035714
A7: 8945 | B7: ROT.ISCA DE FRANGO A MILANESA BENDITO KG | C7: 8945 | D7: 0.87 | E7: =(E6) -> 19/01 a20/01 | G7: 7875 | H7: REFEICAO STROGONOFF FRANGO BENDITO UN | I7: 7875 | J7: 10 | K7: =(K6) -> 20/01 a 21/01 | M7: 7796 | N7: REFEICAO MEDALHAO FRANGO BENDITO UN | O7: 7796 | P7: 12 | Q7: =(Q6) -> 21/01 a 22/01 | S7: 9362 | T7: REFEICAO ISCA DE FRANGO A ACEBOLADA BENDITO UN | U7: 9362 | V7: 15 | W7: =(W6) -> 15/01 a16/01 | Y7: 7673 | Z7: REFEICAO FILE FRANGO PARMEGIANA BENDITO UN | AA7: 7673 | AB7: 21 | AC7: =(AC6) -> 16/01 a 17/01 | AE7: 7673 | AF7: REFEICAO FILE FRANGO PARMEGIANA BENDITO UN | AG7: 7673 | AH7: 21 | AI7: =(AI6) -> 17/01 a 18/01 | AK7: 7120 | AL7: BOLO FUBA C/MILHO BENDITO KG | AM7: 7120 | AN7: 0.43 | AO7: =(AO6) -> 20/10 A 23/10 | AQ7: 104254 | AR7: F.PROPRIA LANCHE SALAME COM QUEIJO PRATO KG | AS7: 104254 | AT7: 5.18 | AU7: 414.18 | AV7: =(AT7/7) -> 0.74 | AW7: =(AU7/7) -> 59.168571
A8: 8028 | B8: ROTISSERIA ARROZ BRANCO BENDITO KG | C8: 8028 | D8: 2.71 | E8: =(E7) -> 19/01 a20/01 | G8: 7877 | H8: REFEICAO TIRINHA CARNE CHINESA BENDITO UN | I8: 7877 | J8: 14 | K8: =(K7) -> 20/01 a 21/01 | M8: 8321 | N8: ROT.ESPAGUETE A BOLONHESA + POLPETONE RECHEADO BENDITO | O8: 8321 | P8: 4 | Q8: =(Q7) -> 21/01 a 22/01 | S8: 7796 | T8: REFEICAO MEDALHAO FRANGO BENDITO UN | U8: 7796 | V8: 15 | W8: =(W7) -> 15/01 a16/01 | Y8: 9362 | Z8: REFEICAO ISCA DE FRANGO A ACEBOLADA BENDITO UN | AA8: 9362 | AB8: 15 | AC8: =(AC7) -> 16/01 a 17/01 | AE8: 8321 | AF8: ROT.ESPAGUETE A BOLONHESA + POLPETONE RECHEADO BENDITO | AG8: 8321 | AH8: 7 | AI8: =(AI7) -> 17/01 a 18/01 | AK8: 7267 | AL8: BOLO LEITE NINHO VALSA BENDITO KG | AM8: 7267 | AN8: 0.44 | AO8: =(AO7) -> 20/10 A 23/10 | AQ8: 6965 | AR8: PAO FOFINHO BENDITO KG | AS8: 6965 | AT8: 12.53 | AU8: 367.8 | AV8: =(AT8/7) -> 1.79 | AW8: =(AU8/7) -> 52.542857
A9: 8080 | B9: ROTISSERIA BANANA BENDITO KG | C9: 8080 | D9: 0.72 | E9: =(E8) -> 19/01 a20/01 | G9: 7877 | H9: REFEICAO TIRINHA CARNE CHINESA BENDITO UN | I9: 7877 | J9: 1 | K9: =(K8) -> 20/01 a 21/01 | M9: 8028 | N9: ROTISSERIA ARROZ BRANCO BENDITO KG | O9: 8028 | P9: 1.52 | Q9: =(Q8) -> 21/01 a 22/01 | S9: 7874 | T9: REFEICAO STROGONOFF CARNE BENDITO UN | U9: 7874 | V9: 15 | W9: =(W8) -> 15/01 a16/01 | Y9: 7874 | Z9: REFEICAO STROGONOFF CARNE BENDITO UN | AA9: 7874 | AB9: 15 | AC9: =(AC8) -> 16/01 a 17/01 | AE9: 8023 | AF9: ROTISSERIA ARROZ A GREGA BENDITO KG | AG9: 8023 | AH9: 3.22 | AI9: =(AI8) -> 17/01 a 18/01 | AK9: 7141 | AL9: BOLO LIMAO C COBERTURA BENDITO KG | AM9: 7141 | AN9: 1.82 | AO9: =(AO8) -> 20/10 A 23/10 | AQ9: 7499 | AR9: SONHO CREME BENDITO KG | AS9: 7499 | AT9: 8.82 | AU9: 325.29 | AV9: =(AT9/7) -> 1.26 | AW9: =(AU9/7) -> 46.47
A10: 8089 | B10: ROTISSERIA BATATA ASSADA BENDITO KG | C10: 8089 | D10: 1.36 | E10: =(E9) -> 19/01 a20/01 | G10: 8028 | H10: ROTISSERIA ARROZ BRANCO BENDITO KG | I10: 8028 | J10: 2.56 | K10: =(K9) -> 20/01 a 21/01 | M10: 8048 | N10: ROTISSERIA ARROZ TEMPERADO BENDITO KG | O10: 8048 | P10: 1.32 | Q10: =(Q9) -> 21/01 a 22/01 | S10: 8321 | T10: ROT.ESPAGUETE A BOLONHESA + POLPETONE RECHEADO BENDITO | U10: 8321 | V10: 8 | W10: =(W9) -> 15/01 a16/01 | Y10: 8321 | Z10: ROT.ESPAGUETE A BOLONHESA + POLPETONE RECHEADO BENDITO | AA10: 8321 | AB10: 11 | AC10: =(AC9) -> 16/01 a 17/01 | AE10: 8028 | AF10: ROTISSERIA ARROZ BRANCO BENDITO KG | AG10: 8028 | AH10: 3.07 | AI10: =(AI9) -> 17/01 a 18/01 | AK10: 7567 | AL10: BOLO MACA BENDITO KG | AM10: 7567 | AN10: 0.23 | AO10: =(AO9) -> 20/10 A 23/10 | AQ10: 6982 | AR10: ROSCA CASEIRA COCO BENDITO KG | AS10: 6982 | AT10: 6.79 | AU10: 298.23 | AV10: =(AT10/7) -> 0.97 | AW10: =(AU10/7) -> 42.604286
A11: 8093 | B11: ROTISSERIA BATATA DOCE ASSADA BENDITO KG | C11: 8093 | D11: 0.79 | E11: =(E10) -> 19/01 a20/01 | G11: 8048 | H11: ROTISSERIA ARROZ TEMPERADO BENDITO KG | I11: 8048 | J11: 1.15 | K11: =(K10) -> 20/01 a 21/01 | M11: 8089 | N11: ROTISSERIA BATATA ASSADA BENDITO KG | O11: 8089 | P11: 0.55 | Q11: =(Q10) -> 21/01 a 22/01 | S11: 8028 | T11: ROTISSERIA ARROZ BRANCO BENDITO KG | U11: 8028 | V11: 3.61 | W11: =(W10) -> 15/01 a16/01 | Y11: 8028 | Z11: ROTISSERIA ARROZ BRANCO BENDITO KG | AA11: 8028 | AB11: 3.1 | AC11: =(AC10) -> 16/01 a 17/01 | AE11: 8037 | AF11: ROTISSERIA ARROZ CARRETEIRO BENDITO KG | AG11: 8037 | AH11: 1.34 | AI11: =(AI10) -> 17/01 a 18/01 | AK11: 7197 | AL11: BOLO NOZES BENDITO KG | AM11: 7197 | AN11: 0.41 | AO11: =(AO10) -> 20/10 A 23/10 | AQ11: 104256 | AR11: F.PROPRIA LANCHE PRESUNTO E QUEIJO KG | AS11: 104256 | AT11: 4.67 | AU11: 280 | AV11: =(AT11/7) -> 0.66714286 | AW11: =(AU11/7) -> 40
A12: 8166 | B12: ROTISSERIA BOLINHO DE ARROZ BENDITO KG | C12: 8166 | D12: 1.51 | E12: =(E11) -> 19/01 a20/01 | G12: 8080 | H12: ROTISSERIA BANANA BENDITO KG | I12: 8080 | J12: 0.36 | K12: =(K11) -> 20/01 a 21/01 | M12: 8166 | N12: ROTISSERIA BOLINHO DE ARROZ BENDITO KG | O12: 8166 | P12: 1.49 | Q12: =(Q11) -> 21/01 a 22/01 | S12: 8080 | T12: ROTISSERIA BANANA BENDITO KG | U12: 8080 | V12: 0.86 | W12: =(W11) -> 15/01 a16/01 | Y12: 8048 | Z12: ROTISSERIA ARROZ TEMPERADO BENDITO KG | AA12: 8048 | AB12: 2.72 | AC12: =(AC11) -> 16/01 a 17/01 | AE12: 8048 | AF12: ROTISSERIA ARROZ TEMPERADO BENDITO KG | AG12: 8048 | AH12: 2.72 | AI12: =(AI11) -> 17/01 a 18/01 | AK12: 7200 | AL12: BOLO PISCINA CENOURA BENDITO KG | AM12: 7200 | AN12: 1.11 | AO12: =(AO11) -> 20/10 A 23/10 | AQ12: 6944 | AR12: PANETTONE FRUTA BENDITO KG | AS12: 6944 | AT12: 6.68 | AU12: 266.48 | AV12: =(AT12/7) -> 0.95428571 | AW12: =(AU12/7) -> 38.068571
A13: 8176 | B13: ROTISSERIA CALDO DE MANDIOCA BENDITO KG | C13: 8176 | D13: 0.7 | E13: =(E12) -> 19/01 a20/01 | G13: 8089 | H13: ROTISSERIA BATATA ASSADA BENDITO KG | I13: 8089 | J13: 0.4 | K13: =(K12) -> 20/01 a 21/01 | M13: 8172 | N13: ROTISSERIA CABOTIA REFOGADA BENDITO KG | O13: 8172 | P13: 1.56 | Q13: =(Q12) -> 21/01 a 22/01 | S13: 8089 | T13: ROTISSERIA BATATA ASSADA BENDITO KG | U13: 8089 | V13: 0.32 | W13: =(W12) -> 15/01 a16/01 | Y13: 8089 | Z13: ROTISSERIA BATATA ASSADA BENDITO KG | AA13: 8089 | AB13: 0.15 | AC13: =(AC12) -> 16/01 a 17/01 | AE13: 8089 | AF13: ROTISSERIA BATATA ASSADA BENDITO KG | AG13: 8089 | AH13: 0.41 | AI13: =(AI12) -> 17/01 a 18/01 | AK13: 7213 | AL13: BOLO RECH.BRIGADEIRO C/LEITE NINHO BENDITO KG | AM13: 7213 | AN13: 0.76 | AO13: =(AO12) -> 20/10 A 23/10 | AQ13: 6975 | AR13: PAO HOT DOG BENDITO KG | AS13: 6975 | AT13: 8.31 | AU13: 248.37 | AV13: =(AT13/7) -> 1.1871429 | AW13: =(AU13/7) -> 35.481429
A14: 8221 | B14: ROTISSERIA CAPONATA BERINJELA BENDITO KG | C14: 8221 | D14: 0.27 | E14: =(E13) -> 19/01 a20/01 | G14: 8093 | H14: ROTISSERIA BATATA DOCE ASSADA BENDITO KG | I14: 8093 | J14: 0.83 | K14: =(K13) -> 20/01 a 21/01 | M14: 8176 | N14: ROTISSERIA CALDO DE MANDIOCA BENDITO KG | O14: 8176 | P14: 1.01 | Q14: =(Q13) -> 21/01 a 22/01 | S14: 8153 | T14: ROTISSERIA BERINJELA PIZZAOLA BENDITO KG | U14: 8153 | V14: 0.95 | W14: =(W13) -> 15/01 a16/01 | Y14: 8153 | Z14: ROTISSERIA BERINJELA PIZZAOLA BENDITO KG | AA14: 8153 | AB14: 1.9 | AC14: =(AC13) -> 16/01 a 17/01 | AE14: 8153 | AF14: ROTISSERIA BERINJELA PIZZAOLA BENDITO KG | AG14: 8153 | AH14: 1.09 | AI14: =(AI13) -> 17/01 a 18/01 | AK14: 7241 | AL14: BOLO RECHEADO BRIGADEIRO BENDITO KG | AM14: 7241 | AN14: 0.96 | AO14: =(AO13) -> 20/10 A 23/10 | AQ14: 6951 | AR14: PAO CASEIRINHO BENDITO KG | AS14: 6951 | AT14: 7.35 | AU14: 241.98 | AV14: =(AT14/7) -> 1.05 | AW14: =(AU14/7) -> 34.568571
A15: 8292 | B15: ROTISSERIA CREME DE MILHO BENDITO KG | C15: 8292 | D15: 0.98 | E15: =(E14) -> 19/01 a20/01 | G15: 8166 | H15: ROTISSERIA BOLINHO DE ARROZ BENDITO KG | I15: 8166 | J15: 2.71 | K15: =(K14) -> 20/01 a 21/01 | M15: 8204 | N15: ROTISSERIA CANELONE PRE/QUEIJO E M.BRANCO BENDITO KG | O15: 8204 | P15: 0.33 | Q15: =(Q14) -> 21/01 a 22/01 | S15: 8166 | T15: ROTISSERIA BOLINHO DE ARROZ BENDITO KG | U15: 8166 | V15: 1.12 | W15: =(W14) -> 15/01 a16/01 | Y15: 8204 | Z15: ROTISSERIA CANELONE PRE/QUEIJO E M.BRANCO BENDITO KG | AA15: 8204 | AB15: 0.26 | AC15: =(AC14) -> 16/01 a 17/01 | AE15: 8221 | AF15: ROTISSERIA CAPONATA BERINJELA BENDITO KG | AG15: 8221 | AH15: 0.66 | AI15: =(AI14) -> 17/01 a 18/01 | AK15: 7245 | AL15: BOLO RECHEADO DOCE LEITE C/AMEIXA BENDITO KG | AM15: 7245 | AN15: 0.15 | AO15: =(AO14) -> 20/10 A 23/10 | AQ15: 95804 | AR15: PAO GRATINADO KG | AS15: 95804 | AT15: 7.07 | AU15: 232.63 | AV15: =(AT15/7) -> 1.01 | AW15: =(AU15/7) -> 33.232857
... A41: 7075 | B41: SUI PROD.TORRESMO FRITO KG | C41: 7075 | D41: 4.5 | E41: =(E40) -> 19/01 a20/01 | G41: 8498 | H41: ROTISSERIA MOLHO PIMENTA ARTESANAL BENDITO KG | I41: 8498 | J41: 0.32 | K41: =(K40) -> 20/01 a 21/01 | M41: 8963 | N41: ROTISSERIA SALADA CEASER C/FRANGO BENDITO | O41: 8963 | P41: 5 | Q41: =(Q40) -> 21/01 a 22/01 | S41: 8545 | T41: ROTISSERIA PANQUECA S/MOLHO CARNE BENDITO KG | U41: 8545 | V41: 0.32 | W41: =(W40) -> 15/01 a16/01 | Y41: 6960 | Z41: ROTISSERIA NHOQUE AO MOLHO SUGO BENDITO KG | AA41: 6960 | AB41: 0.39 | AC41: =(AC40) -> 16/01 a 17/01 | AE41: 8484 | AF41: ROTISSERIA MAMINHA ASSADA BENDITO KG | AG41: 8484 | AH41: 2.24 | AI41: =(AI40) -> 17/01 a 18/01 | AK41: 544 | AL41: F.PROPRIA PAO CASEIRINHO KG | AM41: 544 | AN41: 0.74 | AO41: =(AO40) -> 20/10 A 23/10 | AQ41: 7399 | AR41: HOT DOG COM MOSTARDA BENDITO KG | AS41: 7399 | AT41: 1.96 | AU41: 74.28 | AV41: =(AT41/7) -> 0.28 | AW41: =(AU41/7) -> 10.611429
E42: =(E41) -> 19/01 a20/01 | G42: 8502 | H42: ROTISSERIA NHOQUE DE BATATA C/ CARNE BENDITO KG | I42: 8502 | J42: 0.41 | K42: =(K41) -> 20/01 a 21/01 | M42: 8690 | N42: ROTISSERIA SALADA DE BATATA CURTINHA BENDITO KG | O42: 8690 | P42: 1.62 | Q42: =(Q41) -> 21/01 a 22/01 | S42: 8551 | T42: ROTISSERIA PATE ALHO BENDITO KG | U42: 8551 | V42: 0.25 | W42: =(W41) -> 15/01 a16/01 | Y42: 8529 | Z42: ROTISSERIA PANQUECA DE CARNE AO POMODORO BENDITO KG | AA42: 8529 | AB42: 0.58 | AC42: =(AC41) -> 16/01 a 17/01 | AE42: 8497 | AF42: ROTISSERIA MIX LEGUMES ASSADO BENDITO KG | AG42: 8497 | AH42: 0.75 | AI42: =(AI41) -> 17/01 a 18/01 | AK42: 759 | AL42: F.PROPRIA PAO DE CALABREZA KG | AM42: 759 | AN42: 1.29 | AO42: =(AO41) -> 20/10 A 23/10 | AQ42: 7475 | AR42: PAVE DE PESSEGO BENDITO KG | AS42: 7475 | AT42: 1.18 | AU42: 73.97 | AV42: =(AT42/7) -> 0.16857143 | AW42: =(AU42/7) -> 10.567143
D43: 99.636 | E43: =(E42) -> 19/01 a20/01 | G43: 8563 | H43: ROTISSERIA PERNIL ACEBOLADO BENDITO KG | I43: 8563 | J43: 0.99 | K43: =(K42) -> 20/01 a 21/01 | M43: 8695 | N43: ROTISSERIA SALADA DE BETERRABA BENDITO KG | O43: 8695 | P43: 2.23 | Q43: =(Q42) -> 21/01 a 22/01 | S43: 6835 | T43: ROTISSERIA PATE GORGONZOLA KG | U43: 6835 | V43: 0.33 | W43: =(W42) -> 15/01 a16/01 | Y43: 8532 | Z43: ROTISSERIA PANQUECA DE FRANGO BENDITO KG | AA43: 8532 | AB43: 2.35 | AC43: =(AC42) -> 16/01 a 17/01 | AE43: 8498 | AF43: ROTISSERIA MOLHO PIMENTA ARTESANAL BENDITO KG | AG43: 8498 | AH43: 0.95 | AI43: =(AI42) -> 17/01 a 18/01 | AK43: 1663 | AL43: F.PROPRIA PAO DE MILHO KG | AM43: 1663 | AN43: 0.16 | AO43: =(AO42) -> 20/10 A 23/10 | AQ43: 6915 | AR43: F.PROPRIA ESFIRRA BRCOLIS QJO E BACON KG | AS43: 6915 | AT43: 1.22 | AU43: 73.09 | AV43: =(AT43/7) -> 0.17428571 | AW43: =(AU43/7) -> 10.441429
A44: 8837 | B44: ROTISSERIA STROGONOFF DE FRANGO BENDITO KG | C44: 8837 | D44: 1.03 | E44: =(E43) -> 19/01 a20/01 | G44: 8563 | H44: ROTISSERIA PERNIL ACEBOLADO BENDITO KG | I44: 8563 | J44: 0.82 | K44: =(K43) -> 20/01 a 21/01 | M44: 9391 | N44: ROTISSERIA SALADA FRESH HONEY PERU BENDITO | O44: 9391 | P44: 2 | Q44: =(Q43) -> 21/01 a 22/01 | S44: 8598 | T44: ROTISSERIA PURE DE BATATA BENDITO KG | U44: 8598 | V44: 0.42 | W44: =(W43) -> 15/01 a16/01 | Y44: 8541 | Z44: ROTISSERIA PANQUECA FRANGO C REQUEIJAO BENDITO KG | AA44: 8541 | AB44: 0.89 | AC44: =(AC43) -> 16/01 a 17/01 | AE44: 6960 | AF44: ROTISSERIA NHOQUE AO MOLHO SUGO BENDITO KG | AG44: 6960 | AH44: 4.27 | AI44: =(AI43) -> 17/01 a 18/01 | AK44: 523 | AL44: F.PROPRIA PAO HAMBURGUER KG | AM44: 523 | AN44: 0.51 | AO44: =(AO43) -> 20/10 A 23/10 | AQ44: 7260 | AR44: BOLO RECHEADO LEITE NINHO C/MORANGO BENDITO KG | AS44: 7260 | AT44: 0.96 | AU44: 71.77 | AV44: =(AT44/7) -> 0.13714286 | AW44: =(AU44/7) -> 10.252857
A45: 9123 | B45: ROTISSERIA SUSHI KANI C/CREAM CHEESE BENDITO UN | C45: 9123 | D45: 1 | E45: =(E44) -> 19/01 a20/01 | G45: 8571 | H45: ROTISSERIA POLENTA AO MOLHO CARNE MOIDA BENDITO KG | I45: 8571 | J45: 1.39 | K45: =(K44) -> 20/01 a 21/01 | M45: 8789 | N45: ROTISSERIA SALADA SUNOMONO BENDITOKG | O45: 8789 | P45: 0.22 | Q45: =(Q44) -> 21/01 a 22/01 | S45: 8633 | T45: ROTISSERIA REPOLHO REFOGADO BENDITO KG | U45: 8633 | V45: 0.77 | W45: =(W44) -> 15/01 a16/01 | Y45: 8544 | Z45: ROTISSERIA PANQUECA PRESUNTO E MUSSARELA BENDITO KG | AA45: 8544 | AB45: 0.92 | AC45: =(AC44) -> 16/01 a 17/01 | AE45: 6960 | AF45: ROTISSERIA NHOQUE AO MOLHO SUGO BENDITO KG | AG45: 6960 | AH45: 0.39 | AI45: =(AI44) -> 17/01 a 18/01 | AK45: 2079 | AL45: F.PROPRIA ROCAMBOLE DOCE LEITE KG | AM45: 2079 | AN45: 0.47 | AO45: =(AO44) -> 20/10 A 23/10 | AQ45: 7474 | AR45: PAVE CHOCOLATE BENDITO KG | AS45: 7474 | AT45: 1.01 | AU45: 70.76 | AV45: =(AT45/7) -> 0.14428571 | AW45: =(AU45/7) -> 10.108571
A46: 8839 | B46: ROTISSERIA TABULE BENDITO KG | C46: 8839 | D46: 2.18 | E46: =(E45) -> 19/01 a20/01 | G46: 8671 | H46: ROTISSERIA SALADA BATATONESE BENDITO KG | I46: 8671 | J46: 0.83 | K46: =(K45) -> 20/01 a 21/01 | M46: 8837 | N46: ROTISSERIA STROGONOFF DE FRANGO BENDITO KG | O46: 8837 | P46: 0.63 | Q46: =(Q45) -> 21/01 a 22/01 | S46: 8671 | T46: ROTISSERIA SALADA BATATONESE BENDITO KG | U46: 8671 | V46: 4.89 | W46: =(W45) -> 15/01 a16/01 | Y46: 8551 | Z46: ROTISSERIA PATE ALHO BENDITO KG | AA46: 8551 | AB46: 0.87 | AC46: =(AC45) -> 16/01 a 17/01 | AE46: 8529 | AF46: ROTISSERIA PANQUECA DE CARNE AO POMODORO BENDITO KG | AG46: 8529 | AH46: 0.58 | AI46: =(AI45) -> 17/01 a 18/01 | AK46: 2072 | AL46: F.PROPRIA ROCAMBOLE GOIABADA KG | AM46: 2072 | AN46: 0.37 | AO46: =(AO45) -> 20/10 A 23/10 | AQ46: 7398 | AR46: GELATINA COLORIDA BENDITO KG | AS46: 7398 | AT46: 1.75 | AU46: 69.74 | AV46: =(AT46/7) -> 0.25 | AW46: =(AU46/7) -> 9.9628571
A47: 8847 | B47: ROTISSERIA TIRINHA DE CARNE BENDITO KG | C47: 8847 | D47: 0.65 | E47: =(E46) -> 19/01 a20/01 | G47: 8963 | H47: ROTISSERIA SALADA CEASER C/FRANGO BENDITO | I47: 8963 | J47: 13 | K47: =(K46) -> 20/01 a 21/01 | M47: 9123 | N47: ROTISSERIA SUSHI KANI C/CREAM CHEESE BENDITO UN | O47: 9123 | P47: 6 | Q47: =(Q46) -> 21/01 a 22/01 | S47: 8963 | T47: ROTISSERIA SALADA CEASER C/FRANGO BENDITO | U47: 8963 | V47: 9 | W47: =(W46) -> 15/01 a16/01 | Y47: 6835 | Z47: ROTISSERIA PATE GORGONZOLA KG | AA47: 6835 | AB47: 0.21 | AC47: =(AC46) -> 16/01 a 17/01 | AE47: 8532 | AF47: ROTISSERIA PANQUECA DE FRANGO BENDITO KG | AG47: 8532 | AH47: 2.7 | AI47: =(AI46) -> 17/01 a 18/01 | AK47: 2923 | AL47: F.PROPRIA ROCAMBOLE LEITE NINHO KG | AM47: 2923 | AN47: 0.19 | AO47: =(AO46) -> 20/10 A 23/10 | AQ47: 6993 | AR47: ROSCA RECHEADA COCO BENDITO KG | AS47: 6993 | AT47: 1.41 | AU47: 67.44 | AV47: =(AT47/7) -> 0.20142857 | AW47: =(AU47/7) -> 9.6342857
A48: 7075 | B48: SUI PROD.TORRESMO FRITO KG | C48: 7075 | D48: 1.23 | E48: =(E47) -> 19/01 a20/01 | G48: 8690 | H48: ROTISSERIA SALADA DE BATATA CURTINHA BENDITO KG | I48: 8690 | J48: 2.37 | K48: =(K47) -> 20/01 a 21/01 | M48: 8839 | N48: ROTISSERIA TABULE BENDITO KG | O48: 8839 | P48: 0.54 | Q48: =(Q47) -> 21/01 a 22/01 | S48: 8690 | T48: ROTISSERIA SALADA DE BATATA CURTINHA BENDITO KG | U48: 8690 | V48: 2.64 | W48: =(W47) -> 15/01 a16/01 | Y48: 8598 | Z48: ROTISSERIA PURE DE BATATA BENDITO KG | AA48: 8598 | AB48: 0.62 | AC48: =(AC47) -> 16/01 a 17/01 | AE48: 8551 | AF48: ROTISSERIA PATE ALHO BENDITO KG | AG48: 8551 | AH48: 0.62 | AI48: =(AI47) -> 17/01 a 18/01 | AK48: 643 | AL48: F.PROPRIA ROSCA CASEIRA COCO KG | AM48: 643 | AN48: 0.33 | AO48: =(AO47) -> 20/10 A 23/10 | AQ48: 7529 | AR48: COOKIES CHOCOLATE BENDITO KG | AS48: 7529 | AT48: 1.33 | AU48: 66.14 | AV48: =(AT48/7) -> 0.19 | AW48: =(AU48/7) -> 9.4485714
E49: =(E48) -> 19/01 a20/01 | G49: 8695 | H49: ROTISSERIA SALADA DE BETERRABA BENDITO KG | I49: 8695 | J49: 2.14 | K49: =(K48) -> 20/01 a 21/01 | M49: 8847 | N49: ROTISSERIA TIRINHA DE CARNE BENDITO KG | O49: 8847 | P49: 0.6 | Q49: =(Q48) -> 21/01 a 22/01 | S49: 8695 | T49: ROTISSERIA SALADA DE BETERRABA BENDITO KG | U49: 8695 | V49: 0.25 | W49: =(W48) -> 15/01 a16/01 | Y49: 8671 | Z49: ROTISSERIA SALADA BATATONESE BENDITO KG | AA49: 8671 | AB49: 3.85 | AC49: =(AC48) -> 16/01 a 17/01 | AE49: 6835 | AF49: ROTISSERIA PATE GORGONZOLA KG | AG49: 6835 | AH49: 0.21 | AI49: =(AI48) -> 17/01 a 18/01 | AK49: 6231 | AL49: F.PROPRIA ROSCA CASEIRA NINHO KG | AM49: 6231 | AN49: 0.27 | AO49: =(AO48) -> 20/10 A 23/10 | AQ49: 7348 | AR49: ESFIRRA CARNE, BROCOLIS E QUEIJO BENDITO KG | AS49: 7348 | AT49: 1.09 | AU49: 65.06 | AV49: =(AT49/7) -> 0.15571429 | AW49: =(AU49/7) -> 9.2942857
E50: =(E49) -> 19/01 a20/01 | G50: 8702 | H50: ROTISSERIA SALADA DE BROCOLIS C/COUVE FLOR BENDITO KG | I50: 8702 | J50: 0.22 | K50: =(K49) -> 20/01 a 21/01 | M50: 8874 | N50: ROTISSERIA TUTU DE FEIJAO BENDITO KG | O50: 8874 | P50: 1 | Q50: =(Q49) -> 21/01 a 22/01 | S50: 8834 | T50: ROTISSERIA STROGONOFF DE CARNE BENDITO KG | U50: 8834 | V50: 0.84 | W50: =(W49) -> 15/01 a16/01 | Y50: 8963 | Z50: ROTISSERIA SALADA CEASER C/FRANGO BENDITO | AA50: 8963 | AB50: 16 | AC50: =(AC49) -> 16/01 a 17/01 | AE50: 8598 | AF50: ROTISSERIA PURE DE BATATA BENDITO KG | AG50: 8598 | AH50: 1.07 | AI50: =(AI49) -> 17/01 a 18/01 | AK50: 235 | AL50: F.PROPRIA ROSCA CREME C/ GOIABADA | AM50: 235 | AN50: 0.28 | AO50: =(AO49) -> 20/10 A 23/10 | AQ50: 7120 | AR50: BOLO FUBA C/MILHO BENDITO KG | AS50: 7120 | AT50: 1.59 | AU50: 63.45 | AV50: =(AT50/7) -> 0.22714286 | AW50: =(AU50/7) -> 9.0642857
E51: =(E50) -> 19/01 a20/01 | G51: 9391 | H51: ROTISSERIA SALADA FRESH HONEY PERU BENDITO | I51: 9391 | J51: 6 | K51: =(K50) -> 20/01 a 21/01 | M51: 7065 | N51: SUI PROD.BANHA KG | O51: 7065 | P51: 5.9 | Q51: =(Q50) -> 21/01 a 22/01 | S51: 8837 | T51: ROTISSERIA STROGONOFF DE FRANGO BENDITO KG | U51: 8837 | V51: 0.35 | W51: =(W50) -> 15/01 a16/01 | Y51: 8690 | Z51: ROTISSERIA SALADA DE BATATA CURTINHA BENDITO KG | AA51: 8690 | AB51: 1.92 | AC51: =(AC50) -> 16/01 a 17/01 | AE51: 8671 | AF51: ROTISSERIA SALADA BATATONESE BENDITO KG | AG51: 8671 | AH51: 0.71 | AI51: =(AI50) -> 17/01 a 18/01 | AK51: 164 | AL51: F.PROPRIA ROSCA RECHEADA COCO KG | AM51: 164 | AN51: 0.29 | AO51: =(AO50) -> 20/10 A 23/10 | AQ51: 7200 | AR51: BOLO PISCINA CENOURA BENDITO KG | AS51: 7200 | AT51: 1.23 | AU51: 61.58 | AV51: =(AT51/7) -> 0.17571429 | AW51: =(AU51/7) -> 8.7971429
E52: =(E51) -> 19/01 a20/01 | G52: 8789 | H52: ROTISSERIA SALADA SUNOMONO BENDITOKG | I52: 8789 | J52: 1.3 | K52: =(K51) -> 20/01 a 21/01 | M52: 7075 | N52: SUI PROD.TORRESMO FRITO KG | O52: 7075 | P52: 7.41 | Q52: =(Q51) -> 21/01 a 22/01 | S52: 9123 | T52: ROTISSERIA SUSHI KANI C/CREAM CHEESE BENDITO UN | U52: 9123 | V52: 10 | W52: =(W51) -> 15/01 a16/01 | Y52: 8702 | Z52: ROTISSERIA SALADA DE BROCOLIS C/COUVE FLOR BENDITO KG | AA52: 8702 | AB52: 0.32 | AC52: =(AC51) -> 16/01 a 17/01 | AE52: 8963 | AF52: ROTISSERIA SALADA CEASER C/FRANGO BENDITO | AG52: 8963 | AH52: 11 | AI52: =(AI51) -> 17/01 a 18/01 | AK52: 6228 | AL52: F.PROPRIA ROSQUINHA COCO KG | AM52: 6228 | AN52: 0.69 | AO52: =(AO51) -> 20/10 A 23/10 | AQ52: 7488 | AR52: QUICHE FRANGO C/REQUEIJAO BENDITO 400GR | AS52: 7488 | AT52: 2 | AU52: 57.8 | AV52: =(AT52/7) -> 0.28571429 | AW52: =(AU52/7) -> 8.2571429
E53: =(E52) -> 19/01 a20/01 | G53: 8837 | H53: ROTISSERIA STROGONOFF DE FRANGO BENDITO KG | I53: 8837 | J53: 1.77 | K53: =(K52) -> 20/01 a 21/01 | S53: 8847 | T53: ROTISSERIA TIRINHA DE CARNE BENDITO KG | U53: 8847 | V53: 0.72 | W53: =(W52) -> 15/01 a16/01 | Y53: 9391 | Z53: ROTISSERIA SALADA FRESH HONEY PERU BENDITO | AA53: 9391 | AB53: 3 | AC53: =(AC52) -> 16/01 a 17/01 | AE53: 8690 | AF53: ROTISSERIA SALADA DE BATATA CURTINHA BENDITO KG | AG53: 8690 | AH53: 0.8 | AI53: =(AI52) -> 17/01 a 18/01 | AK53: 511 | AL53: F.PROPRIA ROSQUINHA DE LEITE NINHO KG | AM53: 511 | AN53: 0.14 | AO53: =(AO52) -> 20/10 A 23/10 | AQ53: 6954 | AR53: PAO BRIOCHE CALABRESA BENDITO KG | AS53: 6954 | AT53: 1.19 | AU53: 55.73 | AV53: =(AT53/7) -> 0.17 | AW53: =(AU53/7) -> 7.9614286
E54: =(E53) -> 19/01 a20/01 | G54: 9123 | H54: ROTISSERIA SUSHI KANI C/CREAM CHEESE BENDITO UN | I54: 9123 | J54: 5 | K54: =(K53) -> 20/01 a 21/01 | P54: 114.803 | S54: 8862 | T54: ROTISSERIA TOMATE CONFIT BENDITO KG | U54: 8862 | V54: 0.19 | W54: =(W53) -> 15/01 a16/01 | Y54: 8834 | Z54: ROTISSERIA STROGONOFF DE CARNE BENDITO KG | AA54: 8834 | AB54: 1.39 | AC54: =(AC53) -> 16/01 a 17/01 | AE54: 8702 | AF54: ROTISSERIA SALADA DE BROCOLIS C/COUVE FLOR BENDITO KG | AG54: 8702 | AH54: 0.43 | AI54: =(AI53) -> 17/01 a 18/01 | AK54: 511 | AL54: F.PROPRIA ROSQUINHA DE LEITE NINHO KG | AM54: 511 | AN54: 0.15 | AO54: =(AO53) -> 20/10 A 23/10 | AQ54: 7265 | AR54: BOLO NINHO C/OURO BRC BENDITO KG | AS54: 7265 | AT54: 0.69 | AU54: 51.53 | AV54: =(AT54/7) -> 0.098571429 | AW54: =(AU54/7) -> 7.3614286
E55: =(E54) -> 19/01 a20/01 | G55: 8839 | H55: ROTISSERIA TABULE BENDITO KG | I55: 8839 | J55: 0.83 | K55: =(K54) -> 20/01 a 21/01 | S55: 8874 | T55: ROTISSERIA TUTU DE FEIJAO BENDITO KG | U55: 8874 | V55: 1.38 | W55: =(W54) -> 15/01 a16/01 | Y55: 9123 | Z55: ROTISSERIA SUSHI KANI C/CREAM CHEESE BENDITO UN | AA55: 9123 | AB55: 9 | AC55: =(AC54) -> 16/01 a 17/01 | AE55: 9391 | AF55: ROTISSERIA SALADA FRESH HONEY PERU BENDITO | AG55: 9391 | AH55: 4 | AI55: =(AI54) -> 17/01 a 18/01 | AK55: 7327 | AL55: F. PROPRIA SEQUILHOS KG | AM55: 7327 | AN55: 0.22 | AO55: =(AO54) -> 20/10 A 23/10 | AQ55: 6950 | AR55: PAO BRIOCHE BENDITO KG | AS55: 6950 | AT55: 1.02 | AU55: 50.7 | AV55: =(AT55/7) -> 0.14571429 | AW55: =(AU55/7) -> 7.2428571
E56: =(E55) -> 19/01 a20/01 | G56: 8847 | H56: ROTISSERIA TIRINHA DE CARNE BENDITO KG | I56: 8847 | J56: 1.26 | K56: =(K55) -> 20/01 a 21/01 | S56: 7075 | T56: SUI PROD.TORRESMO FRITO KG | U56: 7075 | V56: 0.4 | W56: =(W55) -> 15/01 a16/01 | Y56: 8839 | Z56: ROTISSERIA TABULE BENDITO KG | AA56: 8839 | AB56: 0.26 | AC56: =(AC55) -> 16/01 a 17/01 | AE56: 8834 | AF56: ROTISSERIA STROGONOFF DE CARNE BENDITO KG | AG56: 8834 | AH56: 0.56 | AI56: =(AI55) -> 17/01 a 18/01 | AK56: 7327 | AL56: F. PROPRIA SEQUILHOS KG | AM56: 7327 | AN56: 0.34 | AO56: =(AO55) -> 20/10 A 23/10 | AQ56: 7195 | AR56: F.PROPRIA SALGADO DE CALABRESA ASSADO KG | AS56: 7195 | AT56: 1.27 | AU56: 50.61 | AV56: =(AT56/7) -> 0.18142857 | AW56: =(AU56/7) -> 7.23
E57: =(E56) -> 19/01 a20/01 | G57: 8874 | H57: ROTISSERIA TUTU DE FEIJAO BENDITO KG | I57: 8874 | J57: 1.24 | K57: =(K56) -> 20/01 a 21/01 | Y57: 8862 | Z57: ROTISSERIA TOMATE CONFIT BENDITO KG | AA57: 8862 | AB57: 0.57 | AC57: =(AC56) -> 16/01 a 17/01 | AE57: 9123 | AF57: ROTISSERIA SUSHI KANI C/CREAM CHEESE BENDITO UN | AG57: 9123 | AH57: 2 | AI57: =(AI56) -> 17/01 a 18/01 | AK57: 4052 | AL57: F.PROPRIA SONHO CREME KG | AM57: 4052 | AN57: 0.5 | AO57: =(AO56) -> 20/10 A 23/10 | AQ57: 7473 | AR57: PAO DE CALABREZA BENDITO KG | AS57: 7473 | AT57: 1.34 | AU57: 48.12 | AV57: =(AT57/7) -> 0.19142857 | AW57: =(AU57/7) -> 6.8742857
E58: =(E57) -> 19/01 a20/01 | G58: 7065 | H58: SUI PROD.BANHA KG | I58: 7065 | J58: 0.94 | K58: =(K57) -> 20/01 a 21/01 | Y58: 8874 | Z58: ROTISSERIA TUTU DE FEIJAO BENDITO KG | AA58: 8874 | AB58: 1.6 | AC58: =(AC57) -> 16/01 a 17/01 | AE58: 8839 | AF58: ROTISSERIA TABULE BENDITO KG | AG58: 8839 | AH58: 0.26 | AI58: =(AI57) -> 17/01 a 18/01 | AK58: 93445 | AL58: F.PROPRIA TORTA DE FRANGO KG | AM58: 93445 | AN58: 0.38 | AO58: =(AO57) -> 20/10 A 23/10 | AQ58: 7496 | AR58: ROCAMBOLE PRESTIGIO BENDITO KG | AS58: 7496 | AT58: 0.97 | AU58: 46.28 | AV58: =(AT58/7) -> 0.13857143 | AW58: =(AU58/7) -> 6.6114286
E59: =(E58) -> 19/01 a20/01 | G59: 7075 | H59: SUI PROD.TORRESMO FRITO KG | I59: 7075 | J59: 4.86 | K59: =(K58) -> 20/01 a 21/01 | Y59: 8900 | Z59: ROTISSERIA YAKISSOBA BENDITO KG | AA59: 8900 | AB59: 3.28 | AC59: =(AC58) -> 16/01 a 17/01 | AE59: 8862 | AF59: ROTISSERIA TOMATE CONFIT BENDITO KG | AG59: 8862 | AH59: 0.39 | AI59: =(AI58) -> 17/01 a 18/01 | AK59: 7398 | AL59: GELATINA COLORIDA BENDITO KG | AM59: 7398 | AN59: 1.34 | AO59: =(AO58) -> 20/10 A 23/10 | AQ59: 7479 | AR59: PUDIM DE PADARIA BENDITO KG | AS59: 7479 | AT59: 1.3 | AU59: 45.31 | AV59: =(AT59/7) -> 0.18571429 | AW59: =(AU59/7) -> 6.4728571
E60: =(E59) -> 19/01 a20/01 | K60: =(K59) -> 20/01 a 21/01 | Y60: 7075 | Z60: SUI PROD.TORRESMO FRITO KG | AA60: 7075 | AB60: 0.21 | AC60: =(AC59) -> 16/01 a 17/01 | AE60: 8523 | AF60: ROTISSERIA TULIPA BUFALO WINGS KG | AG60: 8523 | AH60: 2.69 | AI60: =(AI59) -> 17/01 a 18/01 | AK60: 7421 | AL60: LANCHE PATE FRANGO RICOTA BENDITO KG | AM60: 7421 | AN60: 1.6 | AO60: =(AO59) -> 20/10 A 23/10 | AQ60: 7549 | AR60: QUEIJADINHA BENDITO KG | AS60: 7549 | AT60: 0.66 | AU60: 44.94 | AV60: =(AT60/7) -> 0.094285714 | AW60: =(AU60/7) -> 6.42
E61: =(E60) -> 19/01 a20/01 | J61: 153.344 | K61: =(K60) -> 20/01 a 21/01 | AC61: =(AC60) -> 16/01 a 17/01 | AE61: 8874 | AF61: ROTISSERIA TUTU DE FEIJAO BENDITO KG | AG61: 8874 | AH61: 0.22 | AI61: =(AI60) -> 17/01 a 18/01 | AK61: 7435 | AL61: LUA DE MEL LEITE CONDENSADO BENDITO KG | AM61: 7435 | AN61: 0.56 | AO61: =(AO60) -> 20/10 A 23/10 | AQ61: 7504 | AR61: TORTA DE FRIOS BENDITO KG | AS61: 7504 | AT61: 0.95 | AU61: 44.74 | AV61: =(AT61/7) -> 0.13571429 | AW61: =(AU61/7) -> 6.3914286
E62: =(E61) -> 19/01 a20/01 | K62: =(K61) -> 20/01 a 21/01 | AC62: =(AC61) -> 16/01 a 17/01 | AE62: 8900 | AF62: ROTISSERIA YAKISSOBA BENDITO KG | AG62: 8900 | AH62: 3.7 | AI62: =(AI61) -> 17/01 a 18/01 | AK62: 7436 | AL62: MANJAR BENDITO KG | AM62: 7436 | AN62: 1.13 | AO62: =(AO61) -> 20/10 A 23/10 | AQ62: 7119 | AR62: BOLO FUBA C/ GOIABADA BENDITO KG | AS62: 7119 | AT62: 1.09 | AU62: 43.48 | AV62: =(AT62/7) -> 0.15571429 | AW62: =(AU62/7) -> 6.2114286
E63: =(E62) -> 19/01 a20/01 | K63: =(K62) -> 20/01 a 21/01 | AC63: =(AC62) -> 16/01 a 17/01 | AI63: =(AI62) -> 17/01 a 18/01 | AK63: 7437 | AL63: MARIA MOLE BENDITO KG | AM63: 7437 | AN63: 0.91 | AO63: =(AO62) -> 20/10 A 23/10 | AQ63: 7041 | AR63: BOLO BANANA BENDITO KG | AS63: 7041 | AT63: 1.06 | AU63: 42.14 | AV63: =(AT63/7) -> 0.15142857 | AW63: =(AU63/7) -> 6.02
E64: =(E63) -> 19/01 a20/01 | K64: =(K63) -> 20/01 a 21/01 | AC64: =(AC63) -> 16/01 a 17/01 | AI64: =(AI63) -> 17/01 a 18/01 | AK64: 7455 | AL64: MINI PUDIM BENDITO 100G | AM64: 7455 | AN64: 12 | AO64: =(AO63) -> 20/10 A 23/10 | AQ64: 6990 | AR64: ROSCA RECHEADA CHOCOLATE BENDITO KG | AS64: 6990 | AT64: 1.14 | AU64: 42 | AV64: =(AT64/7) -> 0.16285714 | AW64: =(AU64/7) -> 6
E65: =(E64) -> 19/01 a20/01 | K65: =(K64) -> 20/01 a 21/01 | AC65: =(AC64) -> 16/01 a 17/01 | AI65: =(AI64) -> 17/01 a 18/01 | AK65: 7096 | AL65: PAO ABOBORA BENDITO KG | AM65: 7096 | AN65: 0.33 | AO65: =(AO64) -> 20/10 A 23/10 | AQ65: 7032 | AR65: PAO MANDIOQUINHA BENDITO KG | AS65: 7032 | AT65: 1.01 | AU65: 40.12 | AV65: =(AT65/7) -> 0.14428571 | AW65: =(AU65/7) -> 5.7314286
...

Sheet PESOS
A1: SEGUNDA-FEIRA | F1: TERÇA FEIRA | K1: QUARTA FEIRA | P1: QUINTA FEIRA | U1: SEXT A FEIRA | Z1: SABADO | AE1: DOMINGO | AJ1: Produto | AK1: Embalagem | AL1: Código de Barras | AM1: Preço Venda
A2: ALMOÇO | B2: COD | C2: PRODUTO | D2: PESO P/PCT | F2: ALMOÇO | G2: COD | H2: PRODUTO | I2: PESO P/PCT | K2: ALMOÇO | L2: COD | M2: PRODUTO | N2: PESO P/PCT | P2: ALMOÇO | Q2: COD | R2: PRODUTO | S2: PESO P/PCT | U2: ALMOÇO | V2: COD | W2: PRODUTO | X2: PESO P/PCT | Z2: ALMOÇO | AA2: COD | AB2: PRODUTO | AC2: PESO P/PCT | AE2: ALMOÇO | AF2: COD | AG2: PRODUTO | AH2: PESO P/PCT | AJ2: 093583 - ASS.FRANGO BENDITO INTEIRO | AK2: UN/0001 | AL2: 93583 | AM2: 45.9
A3: MARMITA 3 DIVISORIAS | B3: 7768 | C3: 007768 - REFEICAO LAGARTO M.MADEIRA + BATATA ASSADA BENDITO | D3: 1 | F3: MARMITA 3 DIVISORIAS | G3: 7875 | H3: 007875 - REFEICAO STROGONOFF FRANGO BENDITO UN | I3: 1 | K3: MARMITA 3 DIVISORIAS | L3: 7673 | M3: 007673 - REFEICAO FILE FRANGO PARMEGIANA BENDITO UN | N3: 1 | P3: MARMITA 3 DIVISORIAS | Q3: 7625 | R3: 007625 - REFEICAO CARNE PANELA BENDITO UN | S3: 1 | U3: MARMITA 3 DIVISORIAS | V3: 9362 | W3: 009362 - REFEICAO ISCA DE FRANGO A ACEBOLADA BENDITO UN | X3: 1 | Z3: MARMITA 3 DIVISORIAS | AA3: 7673 | AB3: 007673 - REFEICAO FILE FRANGO PARMEGIANA BENDITO UN | AC3: 1 | AJ3: 002893 - ASS.FRANGO METADE BENDITO UNIDADE | AK3: UN/0001 | AL3: 2893 | AM3: 26.9
B4: 8966 | C4: 08966 - REFEICAO ISCA DE FRANGO A MILANESA | D4: 1 | G4: 7877 | H4: 007877 - REFEICAO TIRINHA CARNE CHINESA BENDITO UN | I4: 1 | L4: 8948 | M4: 008948 - REF COPA LOMBO SUINA MILANESA BENDITO | N4: 1 | Q4: 8491 | R4: 008491 - ROTISSERIA MEDALHAO FRANGO BENDITO KG | S4: 1 | V4: 7874 | W4: 007874 - REFEICAO STROGONOFF CARNE BENDITO UN | X4: 1 | AA4: 7660 | AB4: 007660 - REFEICAO FEIJOADA BENDITO UN | AC4: 1 | AE4: MASSAS | AF4: 8480 | AG4: 008480 - ROTISSERIA MACARRONADA A BOLONHESA BENDITO KG | AH4: 0 | AJ4: 002353 - COGUMELO FATIADO KG | AK4: KG/0001 | AL4: 2353 | AM4: 0
B5: 0 | C5: NÃO ENCONTRADO | D5: 0 | G5: 7305 | H5: NÃO ENCONTRADO | I5: 1 | L5: 0 | M5: NÃO ENCONTRADO | N5: 1 | Q5: 0 | R5: NÃO ENCONTRADO | S5: 1 | V5: 0 | W5: NÃO ENCONTRADO | X5: 1 | AA5: 7305 | AB5: NÃO ENCONTRADO | AC5: 1 | AF5: 8321 | AG5: 008321 - ROT.ESPAGUETE A BOLONHESA + POLPETONE RECHEADO BENDITO | AH5: 0 | AJ5: 005877 - COGUMELO INTEIRO KG | AK5: KG/0001 | AL5: 5877 | AM5: 0
AF6: 8400 | AG6: 008400 - ROTISSERIA LASANHA A BOLONHESA BENDITO KG | AH6: 0 | AJ6: 002028 - ERVILHA CONGELADA KG | AK6: KG/0001 | AL6: 2028 | AM6: 0
A7: MACARRÃO | B7: 8480 | C7: 008480 - ROTISSERIA MACARRONADA A BOLONHESA BENDITO KG | D7: 0.35 | F7: MACARRÃO | G7: 8480 | H7: 008480 - ROTISSERIA MACARRONADA A BOLONHESA BENDITO KG | I7: 0.35 | K7: MACARRÃO | L7: 8480 | M7: 008480 - ROTISSERIA MACARRONADA A BOLONHESA BENDITO KG | N7: 0.35 | P7: MACARRÃO | Q7: 8480 | R7: 008480 - ROTISSERIA MACARRONADA A BOLONHESA BENDITO KG | S7: 0.35 | U7: MACARRÃO | V7: 8480 | W7: 008480 - ROTISSERIA MACARRONADA A BOLONHESA BENDITO KG | X7: 0.35 | Z7: MACARRÃO | AA7: 8900 | AB7: 008900 - ROTISSERIA YAKISSOBA BENDITO KG | AC7: 0.35 | AF7: 9020 | AG7: NÃO ENCONTRADO | AH7: 0 | AJ7: 035607 - ERVILHA LATA 1,7KG | AK7: UN/0001 | AL7: 356077 | AM7: 10
B8: 93626 | C8: 093626 - ROTISSERIA MACARRAO C/BROCOLIS E BACON KG | D8: 0.35 | G8: 8442 | H8: 008442 - ROTISSERIA MACARRAO C/CALABRESA MOLHO ROSE BENDITO KG | I8: 0.35 | L8: 8321 | M8: 008321 - ROT.ESPAGUETE A BOLONHESA + POLPETONE RECHEADO BENDITO | N8: 1 | Q8: 8321 | R8: 008321 - ROT.ESPAGUETE A BOLONHESA + POLPETONE RECHEADO BENDITO | S8: 1 | V8: 8321 | W8: 008321 - ROT.ESPAGUETE A BOLONHESA + POLPETONE RECHEADO BENDITO | X8: 1 | AA8: 8480 | AB8: 008480 - ROTISSERIA MACARRONADA A BOLONHESA BENDITO KG | AC8: 0.35 | AJ8: 007337 - F. PROPRIA ISCA DE FRANGO A MILANESA KG | AK8: KG/0001 | AL8: 7337 | AM8: 69.9
B9: 0 | C9: NÃO ENCONTRADO | D9: 0.35 | G9: 9019 | H9: NÃO ENCONTRADO | I9: 0 | L9: 9019 | M9: NÃO ENCONTRADO | N9: 0 | Q9: 0 | R9: NÃO ENCONTRADO | S9: 1 | V9: 0 | W9: NÃO ENCONTRADO | X9: 0.35 | AA9: 8321 | AB9: 008321 - ROT.ESPAGUETE A BOLONHESA + POLPETONE RECHEADO BENDITO | AC9: 1 | AE9: MONO ARROZ | AF9: 8037 | AG9: 008037 - ROTISSERIA ARROZ CARRETEIRO BENDITO KG | AH9: 0 | AJ9: 006911 - GORDURA VEGETAL PARA FRITADEIRA KG | AK9: KG/0001 | AL9: 6911 | AM9: 10
AF10: 8023 | AG10: 008023 - ROTISSERIA ARROZ A GREGA BENDITO KG | AH10: 0 | AJ10: 006270 - HMP SAL KG | AK10: KG/0012 | AL10: 6270 | AM10: 2.45
A11: MONO ARROZ | B11: 8028 | C11: 008028 - ROTISSERIA ARROZ BRANCO BENDITO KG | D11: 0.12 | F11: MONO ARROZ | G11: 8028 | H11: 008028 - ROTISSERIA ARROZ BRANCO BENDITO KG | I11: 0.12 | K11: MONO ARROZ | L11: 8028 | M11: 008028 - ROTISSERIA ARROZ BRANCO BENDITO KG | N11: 0.12 | P11: MONO ARROZ | Q11: 8028 | R11: 008028 - ROTISSERIA ARROZ BRANCO BENDITO KG | S11: 0.15 | U11: MONO ARROZ | V11: 8028 | W11: 008028 - ROTISSERIA ARROZ BRANCO BENDITO KG | X11: 0.12 | Z11: MONO ARROZ | AA11: 8028 | AB11: 008028 - ROTISSERIA ARROZ BRANCO BENDITO KG | AC11: 0.12 | AF11: 0 | AG11: NÃO ENCONTRADO | AH11: 0 | AJ11: 006272 - HMP SALSA KG | AK11: KG/0001 | AL11: 6272 | AM11: 37.95
B12: 0 | C12: NÃO ENCONTRADO | D12: 0 | G12: 346 | H12: NÃO ENCONTRADO | I12: 0 | L12: 346 | M12: NÃO ENCONTRADO | N12: 0 | Q12: 0 | R12: NÃO ENCONTRADO | S12: 1 | V12: 0 | W12: NÃO ENCONTRADO | X12: 1 | AA12: 346 | AB12: NÃO ENCONTRADO | AC12: 0 | AJ12: 006268 - HMP VINAGRE KG | AK12: KG/0012 | AL12: 6268 | AM12: 5
AE13: SALADAS COZIDAS | AF13: 6857 | AG13: 006857 - ROTISSERIA MAIONESE DE LEGUMES COM FRANGO | AH13: 0 | AJ13: 007581 - MEDALHAO QUIABO COM BACON BENDITO KG | AK13: KG/0001 | AL13: 7581 | AM13: 59.9
A14: MONO FEIJÃO | B14: 8328 | C14: 008328 - ROTISSERIA FEIJAO BENDITO KG | D14: 0.18 | F14: MONO FEIJÃO | G14: 8328 | H14: 008328 - ROTISSERIA FEIJAO BENDITO KG | I14: 0.18 | K14: MONO FEIJÃO | L14: 8328 | M14: 008328 - ROTISSERIA FEIJAO BENDITO KG | N14: 0.18 | P14: MONO FEIJÃO | Q14: 8328 | R14: 008328 - ROTISSERIA FEIJAO BENDITO KG | S14: 0.15 | U14: MONO FEIJÃO | V14: 8328 | W14: 008328 - ROTISSERIA FEIJAO BENDITO KG | X14: 0.18 | Z14: MONO FEIJÃO | AA14: 8328 | AB14: 008328 - ROTISSERIA FEIJAO BENDITO KG | AC14: 0.18 | AF14: 8482 | AG14: 008482 - ROTISSERIA MAIONESE DE LEGUMES COM FRANGO BENDITO KG | AH14: 0 | AJ14: 003361 - MILHO VERDE EM CONSERVA LATA 1,7KG (COLOCAR PRECO KG) | AK14: KG/0001 | AL14: 3361 | AM14: 0
B15: 10 | C15: NÃO ENCONTRADO | D15: 0 | G15: 0 | H15: NÃO ENCONTRADO | I15: 0 | L15: 0 | M15: NÃO ENCONTRADO | N15: 0 | Q15: 0 | R15: NÃO ENCONTRADO | S15: 0 | V15: 0 | W15: NÃO ENCONTRADO | X15: 0 | AA15: 8336 | AB15: 008336 - ROTISSERIA FEIJOADA BENDITO KG | AC15: 0.35 | AF15: 1 | AG15: NÃO ENCONTRADO | AH15: 0 | AJ15: 007570 - MOLHO PESTO BENDITO KG | AK15: KG/0001 | AL15: 7570 | AM15: 149.9
I16: 0 | AJ16: 009177 - MP ALGA P/SUSHI KG | AK16: KG/0001 | AL16: 9177 | AM16: 1.69
A17: MONO GUARNIÇÃO | B17: 8089 | C17: 008089 - ROTISSERIA BATATA ASSADA BENDITO KG | D17: 0.15 | F17: MONO GUARNIÇÃO | G17: 8080 | H17: 008080 - ROTISSERIA BANANA BENDITO KG | I17: 0.12 | K17: MONO GUARNIÇÃO | L17: 8292 | M17: 008292 - ROTISSERIA CREME DE MILHO BENDITO KG | N17: 0.15 | P17: MONO GUARNIÇÃO | Q17: 8598 | R17: 008598 - ROTISSERIA PURE DE BATATA BENDITO KG | S17: 0.15 | U17: MONO GUARNIÇÃO | V17: 8279 | W17: 008279 - ROTISSERIA COUVE FLOR EMPANADA BENDITO KG | X17: 0.15 | Z17: MONO GUARNIÇÃO | AA17: 8292 | AB17: 008292 - ROTISSERIA CREME DE MILHO BENDITO KG | AC17: 0.15 | AE17: MONO GUARNIÇÃO | AF17: 6873 | AG17: 006873 - ROT REFRIGERADO FAROFA KG | AH17: 0 | AJ17: 009167 - MP ARROZ JAPONES KG | AK17: KG/0001 | AL17: 9167 | AM17: 8.1
B18: 8598 | C18: 008598 - ROTISSERIA PURE DE BATATA BENDITO KG | D18: 0.15 | G18: 8089 | H18: 008089 - ROTISSERIA BATATA ASSADA BENDITO KG | I18: 0.12 | L18: 8391 | M18: 008391 - ROTISSERIA JILO FRITO BENDITO KG | N18: 0.08 | Q18: 8080 | R18: 008080 - ROTISSERIA BANANA BENDITO KG | S18: 0.12 | V18: 8089 | W18: 008089 - ROTISSERIA BATATA ASSADA BENDITO KG | X18: 0.15 | AA18: 8391 | AB18: 008391 - ROTISSERIA JILO FRITO BENDITO KG | AC18: 0.08 | AF18: 0 | AG18: NÃO ENCONTRADO | AH18: 0 | AJ18: 009196 - MP FARINHA PANKO KG | AK18: KG/0001 | AL18: 9196 | AM18: 14.12
B19: 8403 | C19: 008403 - ROTISSERIA LEGUMES BENDITO KG | D19: 0.15 | G19: 8598 | H19: 008598 - ROTISSERIA PURE DE BATATA BENDITO KG | I19: 0.12 | L19: 8153 | M19: 008153 - ROTISSERIA BERINJELA PIZZAOLA BENDITO KG | N19: 0.08 | Q19: 8323 | R19: 008323 - ROTISSERIA FAROFA BENDITO KG | S19: 0.12 | V19: 8292 | W19: 008292 - ROTISSERIA CREME DE MILHO BENDITO KG | X19: 0 | AA19: 8153 | AB19: 008153 - ROTISSERIA BERINJELA PIZZAOLA BENDITO KG | AC19: 0.1 | AF19: 0 | AG19: NÃO ENCONTRADO | AH19: 0 | AJ19: 009197 - MP MOLHO AGRIDOCE KG | AK19: KG/0001 | AL19: 9197 | AM19: 4.82
AJ20: 009199 - MP MOLHO SHOYU KG | AK20: KG/0001 | AL20: 9199 | AM20: 0.17
A21: MONO PROTEINAS | B21: 8409 | C21: 008409 - ROTISSERIA LINGUICA ASSADA BENDITO KG | D21: 0.15 | F21: MONO PROTEINAS | G21: 8491 | H21: 008491 - ROTISSERIA MEDALHAO FRANGO BENDITO KG | I21: 0.15 | K21: MONO PROTEINAS | L21: 8349 | M21: 008349 - ROTISSERIA FILE FRANGO PARMEGIANA BENDITO KG | N21: 0.15 | P21: MONO PROTEINAS | Q21: 8804 | R21: 008804 - ROTISSERIA SOBRECOXA RECHEADA BENDITO KG | S21: 0.2 | U21: MONO PROTEINAS | V21: 8381 | W21: 008381 - ROTISSERIA FRANGO XADREZ BENDITO KG | X21: 0.15 | Z21: MONO PROTEINAS | AA21: 8361 | AB21: 008361 - ROTISSERIA FILE SOBRECOXA ASSADA BENDITO KG | AC21: 1 | AE21: CARNES ASSADAS | AF21: COD | AG21: PRODUTO | AH21: PESO P/PCT | AJ21: 009178 - MP MOLHO TARE KG | AK21: KG/0001 | AL21: 9178 | AM21: 20.75
B22: 8945 | C22: 008945 - ROT.ISCA DE FRANGO A MILANESA BENDITO KG | D22: 0.15 | G22: 8602 | H22: 008602 - ROTISSERIA QUIBE ASSADO BENDITO KG | I22: 0.15 | L22: 8158 | M22: 008158 - ROTISSERIA BIFE A ROLE BENDITO KG | N22: 0.15 | Q22: 8006 | R22: 008006 - ROTISSERIA ALMONDEGAS AO MOLHO BENDITO KG | V22: 8834 | W22: 008834 - ROTISSERIA STROGONOFF DE CARNE BENDITO KG | X22: 0.15 | AA22: 8409 | AB22: 008409 - ROTISSERIA LINGUICA ASSADA BENDITO KG | AC22: 0.12 | AE22: CARNES ASSADAS | AF22: 93583 | AG22: 093583 - ASS.FRANGO BENDITO INTEIRO | AH22: 0
B23: 8396 | C23: 008396 - ROTISSERIA LAGARTO AO MOLHO MADEIRA BENDITO KG | D23: 0 | G23: 8231 | H23: 008231 - ROTISSERIA CHARUTO BENDITO KG
B24: 8945 | C24: 008945 - ROT.ISCA DE FRANGO A MILANESA BENDITO KG | D24: 0 | G24: 8837 | H24: 008837 - ROTISSERIA STROGONOFF DE FRANGO BENDITO KG | I24: 0.15 | L24: 8284 | M24: 008284 - ROTISSERIA COXA SOBRECOXA ASSADA BENDITO KG | N24: 0.15 | Q24: 8519 | R24: 008519 - ROTISSERIA COXINHA BUFALO WINGS KG | S24: 0 | V24: 8231 | W24: 008231 - ROTISSERIA CHARUTO BENDITO KG | X24: 0 | AA24: 8298 | AB24: 008298 - ROTISSERIA DOBRADINHA BENDITO KG | AC24: 0.35 | AF24: 2893 | AG24: 002893 - ASS.FRANGO METADE BENDITO UNIDADE | AH24: 0 | AJ24: 002753 - OLEO COMP.SOJA/AZEITE GALAO (COLOCAR PRECO POR LITRO) | AK24: KG/0005 | AL24: 2753 | AM24: 0
AF25: 93964 | AG25: 093964 - ROTISSERIA CUPIM ASSADO MOLHO ALHO KG | AH25: 0 | AJ25: 006671 - OLEO DE ALGODAO GALAO (PRECO POR LITRO) | AK25: KG/0001 | AL25: 6671 | AM25: 99.99
A26: SALADAS COZIDAS | B26: 8221 | C26: 008221 - ROTISSERIA CAPONATA BERINJELA BENDITO KG | D26: 0.35 | F26: SALADAS COZIDAS | G26: 8695 | H26: 008695 - ROTISSERIA SALADA DE BETERRABA BENDITO KG | I26: 0.35 | K26: SALADAS COZIDAS | L26: 8690 | M26: 008690 - ROTISSERIA SALADA DE BATATA CURTINHA BENDITO KG | N26: 0.35 | P26: SALADAS COZIDAS | Q26: 8671 | R26: 008671 - ROTISSERIA SALADA BATATONESE BENDITO KG | S26: 0.35 | U26: SALADAS COZIDAS | V26: 0 | W26: NÃO ENCONTRADO | X26: 0 | Z26: SALADAS COZIDAS | AA26: 0 | AB26: NÃO ENCONTRADO | AC26: 0 | AF26: 8484 | AG26: 008484 - ROTISSERIA MAMINHA ASSADA BENDITO KG | AH26: 0 | AJ26: 035544 - OLEO SOJA GALAO (COLOCAR PRECO POR LITRO) | AK26: UN/0001 | AL26: 355445 | AM26: 30
B27: 8789 | C27: 008789 - ROTISSERIA SALADA SUNOMONO BENDITOKG | D27: 0.35 | G27: 8713 | H27: 008713 - ROTISSERIA SALADA DE GRAO DE BICO BENDITO KG | I27: 0.35 | L27: 8687 | M27: 008687 - ROTISSERIA SALADA CENOURA C/VAGEM BENDITO KG | N27: 0.35 | Q27: 8839 | R27: 008839 - ROTISSERIA TABULE BENDITO KG | S27: 0.35 | V27: 0 | W27: NÃO ENCONTRADO | X27: 0 | AA27: 0 | AB27: NÃO ENCONTRADO | AC27: -1 | AF27: 8274 | AG27: 008274 - ROTISSERIA COSTELINHA PORCO MOLHO BARBECUE BENDITO KG | AH27: 0 | AJ27: 001895 - OLEO SOJA LT (GALAO) | AK27: KG/0001 | AL27: 1895 | AM27: 0
A28: SALDAS PROTEICAS/C.JAPONESA | B28: COD | C28: PRODUTO | D28: PESO P/PCT | F28: SALDAS PROTEICAS/C.JAPONESA | G28: COD | H28: PRODUTO | I28: PESO P/PCT | K28: SALDAS PROTEICAS/C.JAPONESA | L28: COD | M28: PRODUTO | N28: PESO P/PCT | P28: SALDAS PROTEICAS/C.JAPONESA | Q28: COD | R28: PRODUTO | S28: PESO P/PCT | U28: SALDAS PROTEICAS/C.JAPONESA | V28: COD | W28: PRODUTO | X28: PESO P/PCT | Z28: CARNES ASSADAS | AA28: COD | AB28: PRODUTO | AC28: PESO P/PCT | AF28: 8393 | AG28: 008393 - ROTISSERIA JOELHO PORCO ASSADO BENDITO KG | AH28: 0 | AJ28: 102365 - PADARIA TABUA DE FRIOS KG | AK28: KG/0001 | AL28: 102365 | AM28: 35.9
A29: SALADAS PRÓTEICAS | B29: 8963 | C29: 008963 - ROTISSERIA SALADA CEASER C/FRANGO BENDITO | D29: 1 | F29: SALADAS PRÓTEICAS | G29: 8963 | H29: 008963 - ROTISSERIA SALADA CEASER C/FRANGO BENDITO | I29: 1 | K29: SALADAS PRÓTEICAS | L29: 8963 | M29: 008963 - ROTISSERIA SALADA CEASER C/FRANGO BENDITO | N29: 1 | P29: SALADAS PRÓTEICAS | Q29: 8963 | R29: 008963 - ROTISSERIA SALADA CEASER C/FRANGO BENDITO | S29: 1 | U29: SALADAS PRÓTEICAS | V29: 8963 | W29: 008963 - ROTISSERIA SALADA CEASER C/FRANGO BENDITO | X29: 1 | Z29: CARNES ASSADAS | AA29: 2893 | AB29: 002893 - ASS.FRANGO METADE BENDITO UNIDADE | AC29: 1 | AF29: 7652 | AG29: 007652 - REFEICAO COXA SOBRECOXA ASSADA BENDITO UN | AH29: 0 | AJ29: 002173 - PALMITO PUPUNHA PICADO KG | AK29: KG/0001 | AL29: 2173 | AM29: 0
B30: 8962 | C30: 008962 - ROTISSERIA SALADA MIX DE FOLHA E LEGUMES C/PROTEINAS BENDITO | D30: 0 | G30: 8962 | H30: 008962 - ROTISSERIA SALADA MIX DE FOLHA E LEGUMES C/PROTEINAS BENDITO | I30: 0 | L30: 8962 | M30: 008962 - ROTISSERIA SALADA MIX DE FOLHA E LEGUMES C/PROTEINAS BENDITO | N30: 1 | Q30: 0 | R30: NÃO ENCONTRADO | S30: 0 | V30: 0 | W30: NÃO ENCONTRADO | X30: 0 | AA30: 8484 | AB30: 008484 - ROTISSERIA MAMINHA ASSADA BENDITO KG | AC30: 0.65 | AF30: 8523 | AG30: 008523 - ROTISSERIA TULIPA BUFALO WINGS KG | AH30: 0 | AJ30: 007573 - PATE DE ATUM BENDITO KG | AK30: KG/0001 | AL30: 7573 | AM30: 59.9
B31: 30 | C31: NÃO ENCONTRADO | D31: 0 | G31: 0 | H31: NÃO ENCONTRADO | I31: 0 | L31: 0 | M31: NÃO ENCONTRADO | N31: 0 | Q31: 0 | R31: NÃO ENCONTRADO | S31: 0 | V31: 0 | W31: NÃO ENCONTRADO | X31: 0 | AA31: 8523 | AB31: 008523 - ROTISSERIA TULIPA BUFALO WINGS KG | AC31: 0.35 | AF31: 8396 | AG31: 008396 - ROTISSERIA LAGARTO AO MOLHO MADEIRA BENDITO KG | AH31: 0 | AJ31: 007574 - PATE DE AZEITONA PRETA BENDITO KG | AK31: KG/0001 | AL31: 7574 | AM31: 99.9
AA32: 0 | AB32: NÃO ENCONTRADO | AC32: 0 | AJ32: 007575 - PATE DE AZEITONA VERDE BENDITO KG | AK32: KG/0001 | AL32: 7575 | AM32: 79.9
A33: SUSHI | B33: 9124 | C33: 009124 - ROTISSERIA HOT HOLL BENDITO UN | D33: 1 | F33: SUSHI | G33: 9123 | H33: 009123 - ROTISSERIA SUSHI KANI C/CREAM CHEESE BENDITO UN | I33: 1 | K33: SUSHI | L33: 9124 | M33: 009124 - ROTISSERIA HOT HOLL BENDITO UN | N33: 1 | P33: SUSHI | Q33: 9123 | R33: 009123 - ROTISSERIA SUSHI KANI C/CREAM CHEESE BENDITO UN | S33: 1 | U33: SUSHI | V33: 9119 | W33: 009119 - ROTISSERIA CALIFORNIA BENDITO UN | X33: 1 | AA33: 0 | AB33: NÃO ENCONTRADO | AC33: 0 | AJ33: 007576 - PATE DE GORGONZOLA BENDITO KG | AK33: KG/0001 | AL33: 7576 | AM33: 79.9
B34: 9119 | C34: 009119 - ROTISSERIA CALIFORNIA BENDITO UN | D34: 1 | G34: 0 | H34: NÃO ENCONTRADO | I34: 0 | L34: 9119 | M34: 009119 - ROTISSERIA CALIFORNIA BENDITO UN | N34: 1 | Q34: 0 | R34: NÃO ENCONTRADO | S34: 1 | V34: 9124 | W34: 009124 - ROTISSERIA HOT HOLL BENDITO UN | X34: 1 | AA34: 0 | AB34: NÃO ENCONTRADO | AC34: 0 | AJ34: 008079 - PATE DE NOZES BENDITO KG | AK34: KG/0001 | AL34: 8079 | AM34: 99.9
B35: 0 | C35: NÃO ENCONTRADO | D35: 0 | G35: 0 | H35: NÃO ENCONTRADO | I35: 0 | L35: 0 | M35: NÃO ENCONTRADO | N35: 0 | Q35: 0 | R35: NÃO ENCONTRADO | S35: 0 | V35: 0 | W35: NÃO ENCONTRADO | X35: 0 | AA35: 0 | AB35: NÃO ENCONTRADO | AC35: 0 | AJ35: 007580 - PATE DE TOMATE SECO BENDITO KG | AK35: KG/0001 | AL35: 7580 | AM35: 79.9
AA36: 0 | AB36: NÃO ENCONTRADO | AC36: 0 | AJ36: 007582 - PRATO EXECUTIVO FIT BENDITO UND | AK36: UN/0001 | AL36: 7582 | AM36: 19.9
A37: POKE/TEMAKI | B37: 9129 | C37: 009129 - ROTISSERIA SALADA POKE DE SHIMEJI BENDITO UN | D37: 1 | F37: POKE/TEMAKI | G37: 9289 | H37: 009289 - ROTISSERIA TEMAKI HOT SALMAO GRELAHADO | I37: 1 | K37: POKE/TEMAKI | L37: 0 | M37: NÃO ENCONTRADO | N37: 0 | P37: POKE/TEMAKI | Q37: 9289 | R37: 009289 - ROTISSERIA TEMAKI HOT SALMAO GRELAHADO | S37: 0 | U37: POKE/TEMAKI | V37: 9129 | W37: 009129 - ROTISSERIA SALADA POKE DE SHIMEJI BENDITO UN | X37: 0 | AA37: 0 | AB37: NÃO ENCONTRADO | AC37: 0 | AJ37: 007930 - REF COPA LOMBO ACEBOLADA BENDITO | AK37: UN/0001 | AL37: 7930 | AM37: 23.9
B38: 0 | C38: NÃO ENCONTRADO | D38: 1 | G38: 0 | H38: NÃO ENCONTRADO | I38: 0 | L38: 0 | M38: NÃO ENCONTRADO | N38: 0 | Q38: 0 | R38: NÃO ENCONTRADO | S38: 0 | V38: 0 | W38: NÃO ENCONTRADO | X38: 0 | Z38: SALDAS PROTEICAS/C.JAPONESA | AA38: COD | AB38: PRODUTO | AC38: PESO P/PCT | AJ38: 008948 - REF COPA LOMBO SUINA MILANESA BENDITO | AK38: UN/0001 | AL38: 8948 | AM38: 23.9
B39: 90 | C39: NÃO ENCONTRADO | D39: 0 | G39: 0 | H39: NÃO ENCONTRADO | I39: 0 | L39: 0 | M39: NÃO ENCONTRADO | N39: 0 | Q39: 0 | R39: NÃO ENCONTRADO | S39: 0 | V39: 0 | W39: NÃO ENCONTRADO | X39: 0 | Z39: SALADAS PRÓTEICAS | AA39: 8963 | AB39: 008963 - ROTISSERIA SALADA CEASER C/FRANGO BENDITO | AC39: 1 | AJ39: 007590 - REFEICAO ALMONDEGA BENDITO UN | AK39: UN/0001 | AL39: 7590 | AM39: 19.9
A40: MASSAS/PATES/MOLHOS/ETC | B40: COD | C40: PRODUTO | D40: PESO P/PCT | E40: MASSAS/PATES/MOLHOS/ETC | F40: MASSAS/PATES/MOLHOS/ETC | G40: COD | H40: PRODUTO | I40: PESO P/PCT | K40: MASSAS/PATES/MOLHOS/ETC | L40: COD | M40: PRODUTO | N40: PESO P/PCT | P40: MASSAS/PATES/MOLHOS/ETC | Q40: COD | R40: PRODUTO | S40: PESO P/PCT | U40: MASSAS/PATES/MOLHOS/ETC | V40: COD | W40: PRODUTO | X40: PESO P/PCT | AA40: 0 | AB40: NÃO ENCONTRADO | AC40: 0 | AJ40: 007602 - REFEICAO ARROZ E FILE FRANGO MILANESA BENDITO UN | AK40: UN/0001 | AL40: 7602 | AM40: 19.9
...

Sheet SEGUNDA
A1: SEGUNDA (LOJA 1 BENDITO-ROTISSERIA) | I1: SUJESTÃO DE PEDIDO | P1: SEGUNDA (LOJA 1 BENDITO-ROTISSERIA) | R1: DATA | S1: 46048
A2: ALMOÇO | C2: INFORMAÇÕES DO PEDIDO | D2: INFORMAÇÕES DO PEDIDO | I2: INFORMAÇÕES SUGESTÃO DE PEDIDO | P2: ALMOÇO | R2: INFORMAÇÕES DO PEDIDO
A3: COD | B3: MARMITA 3 DIVISORIAS | C3: QTD | D3: KG/UN | E3: P.PADRÃO | F3: Q.PCT | G3: PREÇO | H3: TOTAL | I3: VENDA QTD | J3: EM PCT | K3: EM VALORES | L3: PERIODO BASE | M3: STATUS | P3: COD | Q3: MARMITA 3 DIVISORIAS | R3: QTD | S3: Q.PCT
A4: =('[1]ESCALA DE PRODUÇÃO'!B3) -> #REF! | B4: =XLOOKUP(A4,'[1]ESCALA DE PRODUÇÃO'!$AL$1:$AL$1048566,'[1]ESCALA DE PRODUÇÃO'!$AJ$1:$AJ$1048566,"NÃO ENCOTRADO") -> #REF! | C4: 10 | D4: =XLOOKUP(A4,'[1]ESCALA DE PRODUÇÃO'!$AL$1:$AL$1048566,'[1]ESCALA DE PRODUÇÃO'!$AK$1:$AK$1048566,"0") -> #REF! | E4: ='[2]ESCALA DE PRODUÇÃO'!D3 -> #REF! | F4: =IFERROR(C4/E4,"0") -> 0 | G4: =XLOOKUP(A4,'[1]ESCALA DE PRODUÇÃO'!$AL$1:$AL$1048566,'[1]ESCALA DE PRODUÇÃO'!$AM$1:$AM$1048566,"SEM PREÇO") -> #REF! | H4: =IFERROR(C4*G4,"0") -> 0 | I4: {=XLOOKUP(A4,'DADOS DE VENDA'!A:A,'DADOS DE VENDA'!D:D,"SEM VENDA")} -> #REF! | J4: =IFERROR(I4/E4,"0") -> 0 | K4: =IFERROR(I4*G4,"0") -> 0 | L4: {=XLOOKUP(A4,'DADOS DE VENDA'!A:A,'DADOS DE VENDA'!E:E,"RUPTURA NO PERIODO")} -> #REF! | M4: {=IFS(C4<I4,"ABAIXO",C4>I4,"ACIMA",C4=I4,"OK")} -> #REF! | P4: =A4 -> #REF! | Q4: =XLOOKUP(P4,'[1]ESCALA DE PRODUÇÃO'!$AL$1:$AL$1048566,'[1]ESCALA DE PRODUÇÃO'!$AJ$1:$AJ$1048566,"NÃO ENCOTRADO") -> #REF! | R4: =C4 -> 10 | S4: =(F4) -> 0
A5: =('[1]ESCALA DE PRODUÇÃO'!B4) -> #REF! | B5: =XLOOKUP(A5,'[1]ESCALA DE PRODUÇÃO'!$AL$1:$AL$1048566,'[1]ESCALA DE PRODUÇÃO'!$AJ$1:$AJ$1048566,"NÃO ENCOTRADO") -> #REF! | C5: 12 | D5: =XLOOKUP(A5,'[1]ESCALA DE PRODUÇÃO'!$AL$1:$AL$1048566,'[1]ESCALA DE PRODUÇÃO'!$AK$1:$AK$1048566,"0") -> #REF! | E5: ='[2]ESCALA DE PRODUÇÃO'!D4 -> #REF! | F5: =IFERROR(C5/E5,"0") -> 0 | G5: =XLOOKUP(A5,'[1]ESCALA DE PRODUÇÃO'!$AL$1:$AL$1048566,'[1]ESCALA DE PRODUÇÃO'!$AM$1:$AM$1048566,"SEM PREÇO") -> #REF! | H5: =IFERROR(C5*G5,"0") -> 0 | I5: {=XLOOKUP(A5,'DADOS DE VENDA'!A:A,'DADOS DE VENDA'!D:D,"SEM VENDA")} -> #REF! | J5: =IFERROR(I5/E5,"0") -> 0 | K5: =IFERROR(I5*G5,"0") -> 0 | L5: {=XLOOKUP(A5,'DADOS DE VENDA'!A:A,'DADOS DE VENDA'!E:E,"RUPTURA NO PERIODO")} -> #REF! | M5: {=IFS(C5<I5,"ABAIXO",C5>I5,"ACIMA",C5=I5,"OK")} -> #REF! | P5: =A5 -> #REF! | Q5: =XLOOKUP(P5,'[1]ESCALA DE PRODUÇÃO'!$AL$1:$AL$1048566,'[1]ESCALA DE PRODUÇÃO'!$AJ$1:$AJ$1048566,"NÃO ENCOTRADO") -> #REF! | R5: =C5 -> 12 | S5: =(F5) -> 0
A6: =('[1]ESCALA DE PRODUÇÃO'!B5) -> #REF! | B6: =XLOOKUP(A6,'[1]ESCALA DE PRODUÇÃO'!$AL$1:$AL$1048566,'[1]ESCALA DE PRODUÇÃO'!$AJ$1:$AJ$1048566,"NÃO ENCOTRADO") -> #REF! | C6: 0 | D6: =XLOOKUP(A6,'[1]ESCALA DE PRODUÇÃO'!$AL$1:$AL$1048566,'[1]ESCALA DE PRODUÇÃO'!$AK$1:$AK$1048566,"0") -> #REF! | E6: ='[2]ESCALA DE PRODUÇÃO'!D5 -> #REF! | F6: =IFERROR(C6/E6,"0") -> 0 | G6: =XLOOKUP(A6,'[1]ESCALA DE PRODUÇÃO'!$AL$1:$AL$1048566,'[1]ESCALA DE PRODUÇÃO'!$AM$1:$AM$1048566,"SEM PREÇO") -> #REF! | H6: =IFERROR(C6*G6,"0") -> 0 | I6: {=XLOOKUP(A6,'DADOS DE VENDA'!A:A,'DADOS DE VENDA'!D:D,"SEM VENDA")} -> #REF! | J6: =IFERROR(I6/E6,"0") -> 0 | K6: =IFERROR(I6*G6,"0") -> 0 | L6: {=XLOOKUP(A6,'DADOS DE VENDA'!A:A,'DADOS DE VENDA'!E:E,"RUPTURA NO PERIODO")} -> #REF! | M6: {=IFS(C6<I6,"ABAIXO",C6>I6,"ACIMA",C6=I6,"OK")} -> #REF! | P6: =A6 -> #REF! | Q6: =XLOOKUP(P6,'[1]ESCALA DE PRODUÇÃO'!$AL$1:$AL$1048566,'[1]ESCALA DE PRODUÇÃO'!$AJ$1:$AJ$1048566,"NÃO ENCOTRADO") -> #REF! | R6: =C6 -> 0 | S6: =(F6) -> 0
A7: COD | B7: MACARRÃO | C7: QTD | D7: KG/UN | E7: P.PADRÃO | F7: Q.PCT | G7: PREÇO | H7: TOTAL | I7: VENDA QTD | J7: EM PCT | K7: EM VALORES | L7: PERIODO BASE | M7: STATUS | P7: COD | Q7: MACARRÃO | R7: QTD | S7: Q.PCT
A8: =('[1]ESCALA DE PRODUÇÃO'!B7) -> #REF! | B8: =XLOOKUP(A8,'[1]ESCALA DE PRODUÇÃO'!$AL$1:$AL$1048566,'[1]ESCALA DE PRODUÇÃO'!$AJ$1:$AJ$1048566,"NÃO ENCOTRADO") -> #REF! | C8: 1 | D8: =XLOOKUP(A8,'[1]ESCALA DE PRODUÇÃO'!$AL$1:$AL$1048566,'[1]ESCALA DE PRODUÇÃO'!$AK$1:$AK$1048566,"0") -> #REF! | E8: ='[2]ESCALA DE PRODUÇÃO'!D7 -> #REF! | F8: =IFERROR(C8/E8,"0") -> 0 | G8: =XLOOKUP(A8,'[1]ESCALA DE PRODUÇÃO'!$AL$1:$AL$1048566,'[1]ESCALA DE PRODUÇÃO'!$AM$1:$AM$1048566,"SEM PREÇO") -> #REF! | H8: =IFERROR(C8*G8,"0") -> 0 | I8: {=XLOOKUP(A8,'DADOS DE VENDA'!A:A,'DADOS DE VENDA'!D:D,"SEM VENDA")} -> #REF! | J8: =IFERROR(I8/E8,"0") -> 0 | K8: =IFERROR(I8*G8,"0") -> 0 | L8: {=XLOOKUP(A8,'DADOS DE VENDA'!A:A,'DADOS DE VENDA'!E:E,"RUPTURA NO PERIODO")} -> #REF! | M8: {=IFS(C8<I8,"ABAIXO",C8>I8,"ACIMA",C8=I8,"OK")} -> #REF! | P8: =A8 -> #REF! | Q8: =XLOOKUP(P8,'[1]ESCALA DE PRODUÇÃO'!$AL$1:$AL$1048566,'[1]ESCALA DE PRODUÇÃO'!$AJ$1:$AJ$1048566,"NÃO ENCOTRADO") -> #REF! | R8: =C8 -> 1 | S8: =(F8) -> 0
A9: =('[1]ESCALA DE PRODUÇÃO'!B8) -> #REF! | B9: =XLOOKUP(A9,'[1]ESCALA DE PRODUÇÃO'!$AL$1:$AL$1048566,'[1]ESCALA DE PRODUÇÃO'!$AJ$1:$AJ$1048566,"NÃO ENCOTRADO") -> #REF! | C9: 1 | D9: =XLOOKUP(A9,'[1]ESCALA DE PRODUÇÃO'!$AL$1:$AL$1048566,'[1]ESCALA DE PRODUÇÃO'!$AK$1:$AK$1048566,"0") -> #REF! | E9: ='[2]ESCALA DE PRODUÇÃO'!D8 -> #REF! | F9: =IFERROR(C9/E9,"0") -> 0 | G9: =XLOOKUP(A9,'[1]ESCALA DE PRODUÇÃO'!$AL$1:$AL$1048566,'[1]ESCALA DE PRODUÇÃO'!$AM$1:$AM$1048566,"SEM PREÇO") -> #REF! | H9: =IFERROR(C9*G9,"0") -> 0 | I9: {=XLOOKUP(A9,'DADOS DE VENDA'!A:A,'DADOS DE VENDA'!D:D,"SEM VENDA")} -> #REF! | J9: =IFERROR(I9/E9,"0") -> 0 | K9: =IFERROR(I9*G9,"0") -> 0 | L9: {=XLOOKUP(A9,'DADOS DE VENDA'!A:A,'DADOS DE VENDA'!E:E,"RUPTURA NO PERIODO")} -> #REF! | M9: {=IFS(C9<I9,"ABAIXO",C9>I9,"ACIMA",C9=I9,"OK")} -> #REF! | P9: =A9 -> #REF! | Q9: =XLOOKUP(P9,'[1]ESCALA DE PRODUÇÃO'!$AL$1:$AL$1048566,'[1]ESCALA DE PRODUÇÃO'!$AJ$1:$AJ$1048566,"NÃO ENCOTRADO") -> #REF! | R9: =C9 -> 1 | S9: =(F9) -> 0
A10: =('[1]ESCALA DE PRODUÇÃO'!B9) -> #REF! | B10: =XLOOKUP(A10,'[1]ESCALA DE PRODUÇÃO'!$AL$1:$AL$1048566,'[1]ESCALA DE PRODUÇÃO'!$AJ$1:$AJ$1048566,"NÃO ENCOTRADO") -> #REF! | C10: 0 | D10: =XLOOKUP(A10,'[1]ESCALA DE PRODUÇÃO'!$AL$1:$AL$1048566,'[1]ESCALA DE PRODUÇÃO'!$AK$1:$AK$1048566,"0") -> #REF! | E10: ='[2]ESCALA DE PRODUÇÃO'!D9 -> #REF! | F10: =IFERROR(C10/E10,"0") -> 0 | G10: =XLOOKUP(A10,'[1]ESCALA DE PRODUÇÃO'!$AL$1:$AL$1048566,'[1]ESCALA DE PRODUÇÃO'!$AM$1:$AM$1048566,"SEM PREÇO") -> #REF! | H10: =IFERROR(C10*G10,"0") -> 0 | I10: {=XLOOKUP(A10,'DADOS DE VENDA'!A:A,'DADOS DE VENDA'!D:D,"SEM VENDA")} -> #REF! | J10: =IFERROR(I10/E10,"0") -> 0 | K10: =IFERROR(I10*G10,"0") -> 0 | L10: {=XLOOKUP(A10,'DADOS DE VENDA'!A:A,'DADOS DE VENDA'!E:E,"RUPTURA NO PERIODO")} -> #REF! | M10: {=IFS(C10<I10,"ABAIXO",C10>I10,"ACIMA",C10=I10,"OK")} -> #REF! | P10: =A10 -> #REF! | Q10: =XLOOKUP(P10,'[1]ESCALA DE PRODUÇÃO'!$AL$1:$AL$1048566,'[1]ESCALA DE PRODUÇÃO'!$AJ$1:$AJ$1048566,"NÃO ENCOTRADO") -> #REF! | R10: =C10 -> 0 | S10: =(F10) -> 0
A11: COD | B11: MONO ARROZ | C11: QTD | D11: KG/UN | E11: P.PADRÃO | F11: Q.PCT | G11: PREÇO | H11: TOTAL | I11: VENDA QTD | J11: EM PCT | K11: EM VALORES | L11: PERIODO BASE | M11: STATUS | P11: COD | Q11: MONO ARROZ | R11: QTD | S11: Q.PCT
A12: =('[1]ESCALA DE PRODUÇÃO'!B11) -> #REF! | B12: =XLOOKUP(A12,'[1]ESCALA DE PRODUÇÃO'!$AL$1:$AL$1048566,'[1]ESCALA DE PRODUÇÃO'!$AJ$1:$AJ$1048566,"NÃO ENCOTRADO") -> #REF! | C12: 1 | D12: =XLOOKUP(A12,'[1]ESCALA DE PRODUÇÃO'!$AL$1:$AL$1048566,'[1]ESCALA DE PRODUÇÃO'!$AK$1:$AK$1048566,"0") -> #REF! | E12: ='[2]ESCALA DE PRODUÇÃO'!D11 -> #REF! | F12: =IFERROR(C12/E12,"0") -> 0 | G12: =XLOOKUP(A12,'[1]ESCALA DE PRODUÇÃO'!$AL$1:$AL$1048566,'[1]ESCALA DE PRODUÇÃO'!$AM$1:$AM$1048566,"SEM PREÇO") -> #REF! | H12: =IFERROR(C12*G12,"0") -> 0 | I12: {=XLOOKUP(A12,'DADOS DE VENDA'!A:A,'DADOS DE VENDA'!D:D,"SEM VENDA")} -> #REF! | J12: =IFERROR(I12/E12,"0") -> 0 | K12: =IFERROR(I12*G12,"0") -> 0 | L12: {=XLOOKUP(A12,'DADOS DE VENDA'!A:A,'DADOS DE VENDA'!E:E,"RUPTURA NO PERIODO")} -> #REF! | M12: {=IFS(C12<I12,"ABAIXO",C12>I12,"ACIMA",C12=I12,"OK")} -> #REF! | P12: =A12 -> #REF! | Q12: =XLOOKUP(P12,'[1]ESCALA DE PRODUÇÃO'!$AL$1:$AL$1048566,'[1]ESCALA DE PRODUÇÃO'!$AJ$1:$AJ$1048566,"NÃO ENCOTRADO") -> #REF! | R12: =C12 -> 1 | S12: =(F12) -> 0
A13: =('[1]ESCALA DE PRODUÇÃO'!B12) -> #REF! | B13: =XLOOKUP(A13,'[1]ESCALA DE PRODUÇÃO'!$AL$1:$AL$1048566,'[1]ESCALA DE PRODUÇÃO'!$AJ$1:$AJ$1048566,"NÃO ENCOTRADO") -> #REF! | C13: 0 | D13: =XLOOKUP(A13,'[1]ESCALA DE PRODUÇÃO'!$AL$1:$AL$1048566,'[1]ESCALA DE PRODUÇÃO'!$AK$1:$AK$1048566,"0") -> #REF! | E13: ='[2]ESCALA DE PRODUÇÃO'!D12 -> #REF! | F13: =IFERROR(C13/E13,"0") -> 0 | G13: =XLOOKUP(A13,'[1]ESCALA DE PRODUÇÃO'!$AL$1:$AL$1048566,'[1]ESCALA DE PRODUÇÃO'!$AM$1:$AM$1048566,"SEM PREÇO") -> #REF! | H13: =IFERROR(C13*G13,"0") -> 0 | I13: {=XLOOKUP(A13,'DADOS DE VENDA'!A:A,'DADOS DE VENDA'!D:D,"SEM VENDA")} -> #REF! | J13: =IFERROR(I13/E13,"0") -> 0 | K13: =IFERROR(I13*G13,"0") -> 0 | L13: {=XLOOKUP(A13,'DADOS DE VENDA'!A:A,'DADOS DE VENDA'!E:E,"RUPTURA NO PERIODO")} -> #REF! | M13: {=IFS(C13<I13,"ABAIXO",C13>I13,"ACIMA",C13=I13,"OK")} -> #REF! | P13: =A13 -> #REF! | Q13: =XLOOKUP(P13,'[1]ESCALA DE PRODUÇÃO'!$AL$1:$AL$1048566,'[1]ESCALA DE PRODUÇÃO'!$AJ$1:$AJ$1048566,"NÃO ENCOTRADO") -> #REF! | R13: =C13 -> 0 | S13: =(F13) -> 0
A14: COD | B14: MONO FEIJÃO | C14: QTD | D14: KG/UN | E14: P.PADRÃO | F14: Q.PCT | G14: PREÇO | H14: TOTAL | I14: VENDA QTD | J14: EM PCT | K14: EM VALORES | L14: PERIODO BASE | M14: STATUS | P14: COD | Q14: MONO FEIJÃO | R14: QTD | S14: Q.PCT
A15: =('[1]ESCALA DE PRODUÇÃO'!B14) -> #REF! | B15: =XLOOKUP(A15,'[1]ESCALA DE PRODUÇÃO'!$AL$1:$AL$1048566,'[1]ESCALA DE PRODUÇÃO'!$AJ$1:$AJ$1048566,"NÃO ENCOTRADO") -> #REF! | C15: 1 | D15: =XLOOKUP(A15,'[1]ESCALA DE PRODUÇÃO'!$AL$1:$AL$1048566,'[1]ESCALA DE PRODUÇÃO'!$AK$1:$AK$1048566,"0") -> #REF! | E15: ='[2]ESCALA DE PRODUÇÃO'!D14 -> #REF! | F15: =IFERROR(C15/E15,"0") -> 0 | G15: =XLOOKUP(A15,'[1]ESCALA DE PRODUÇÃO'!$AL$1:$AL$1048566,'[1]ESCALA DE PRODUÇÃO'!$AM$1:$AM$1048566,"SEM PREÇO") -> #REF! | H15: =IFERROR(C15*G15,"0") -> 0 | I15: {=XLOOKUP(A15,'DADOS DE VENDA'!A:A,'DADOS DE VENDA'!D:D,"SEM VENDA")} -> #REF! | J15: =IFERROR(I15/E15,"0") -> 0 | K15: =IFERROR(I15*G15,"0") -> 0 | L15: {=XLOOKUP(A15,'DADOS DE VENDA'!A:A,'DADOS DE VENDA'!E:E,"RUPTURA NO PERIODO")} -> #REF! | M15: {=IFS(C15<I15,"ABAIXO",C15>I15,"ACIMA",C15=I15,"OK")} -> #REF! | P15: =A15 -> #REF! | Q15: =XLOOKUP(P15,'[1]ESCALA DE PRODUÇÃO'!$AL$1:$AL$1048566,'[1]ESCALA DE PRODUÇÃO'!$AJ$1:$AJ$1048566,"NÃO ENCOTRADO") -> #REF! | R15: =C15 -> 1 | S15: =(F15) -> 0
